Workbook

Sheet Instances
B1: alpha-qh-1.0/alpha | T1: alpha-qh-1.0/alpha_dom | AL1: alpha-qh-1.0/alpha_noheur | BD1: clingo-native-1.0/ga | BV1: clingo-native-1.0/ga_co | CN1: clingo-native-1.0/ga_weak | DF1: clingo-native-1.0/ga_weak_co | DX1: clingo-native-1.0/gc | EP1: clingo-native-1.0/gc_co | FH1: clingo-native-1.0/gc_noheur | FZ1: clingo-native-1.0/gc_noheur_co | GR1: clingo-native-1.0/la | HJ1: clingo-native-1.0/la_aux | IB1: clingo-native-1.0/la_co | IT1: clingo-native-1.0/lc | JL1: clingo-native-1.0/lc_co | KD1: clingo-prolog-1.0/ga | KV1: clingo-prolog-1.0/ga_co | LN1: clingo-prolog-1.0/ga_weak | MF1: clingo-prolog-1.0/ga_weak_co | MX1: clingo-prolog-1.0/gc | NP1: clingo-prolog-1.0/gc_co | OH1: clingo-prolog-1.0/gc_noheur | OZ1: clingo-prolog-1.0/gc_noheur_co | PR1: clingo-prolog-1.0/la | QJ1: clingo-prolog-1.0/la_aux | RB1: clingo-prolog-1.0/la_co | RT1: clingo-prolog-1.0/lc | SL1: clingo-prolog-1.0/lc_co | TD1: min | TU1: median | UL1: max
B2: atoms | C2: choices | D2: clingo_total | E2: conflicts | F2: constraints | G2: error | H2: grounding | I2: mem | J2: memout | K2: models | L2: par2 | M2: restarts | N2: rules | O2: solving | P2: status | Q2: time | R2: timeout | S2: variables | T2: atoms | U2: choices | V2: clingo_total | W2: conflicts | X2: constraints | Y2: error | Z2: grounding | AA2: mem | AB2: memout | AC2: models | AD2: par2 | AE2: restarts | AF2: rules | AG2: solving | AH2: status | AI2: time | AJ2: timeout | AK2: variables | AL2: atoms | AM2: choices | AN2: clingo_total | AO2: conflicts | AP2: constraints | AQ2: error | AR2: grounding | AS2: mem | AT2: memout | AU2: models | AV2: par2 | AW2: restarts | AX2: rules | AY2: solving | AZ2: status | BA2: time | BB2: timeout | BC2: variables | BD2: atoms | BE2: choices | BF2: clingo_total | BG2: conflicts | BH2: constraints | BI2: error | BJ2: grounding | BK2: mem | BL2: memout | BM2: models | BN2: par2 | BO2: restarts | BP2: rules | BQ2: solving | BR2: status | BS2: time | BT2: timeout | BU2: variables | BV2: atoms | BW2: choices | BX2: clingo_total | BY2: conflicts | BZ2: constraints | CA2: error | CB2: grounding | CC2: mem | CD2: memout | CE2: models | CF2: par2 | CG2: restarts | CH2: rules | CI2: solving | CJ2: status | CK2: time | CL2: timeout | CM2: variables | CN2: atoms | CO2: choices | CP2: clingo_total | CQ2: conflicts | CR2: constraints | CS2: error | CT2: grounding | CU2: mem | CV2: memout | CW2: models | CX2: par2 | CY2: restarts | CZ2: rules | DA2: solving | DB2: status | DC2: time | DD2: timeout | DE2: variables | DF2: atoms | DG2: choices | DH2: clingo_total | DI2: conflicts | DJ2: constraints | DK2: error | DL2: grounding | DM2: mem | DN2: memout | DO2: models | DP2: par2 | DQ2: restarts | DR2: rules | DS2: solving | DT2: status | DU2: time | DV2: timeout | DW2: variables | DX2: atoms | DY2: choices | DZ2: clingo_total | EA2: conflicts | EB2: constraints | EC2: error | ED2: grounding | EE2: mem | EF2: memout | EG2: models | EH2: par2 | EI2: restarts | EJ2: rules | EK2: solving | EL2: status | EM2: time | EN2: timeout | EO2: variables | EP2: atoms | EQ2: choices | ER2: clingo_total | ES2: conflicts | ET2: constraints | EU2: error | EV2: grounding | EW2: mem | EX2: memout | EY2: models | EZ2: par2 | FA2: restarts | FB2: rules | FC2: solving | FD2: status | FE2: time | FF2: timeout | FG2: variables | FH2: atoms | FI2: choices | FJ2: clingo_total | FK2: conflicts | FL2: constraints | FM2: error | FN2: grounding | FO2: mem | FP2: memout | FQ2: models | FR2: par2 | FS2: restarts | FT2: rules | FU2: solving | FV2: status | FW2: time | FX2: timeout | FY2: variables | FZ2: atoms | GA2: choices | GB2: clingo_total | GC2: conflicts | GD2: constraints | GE2: error | GF2: grounding | GG2: mem | GH2: memout | GI2: models | GJ2: par2 | GK2: restarts | GL2: rules | GM2: solving | GN2: status | GO2: time | GP2: timeout | GQ2: variables | GR2: atoms | GS2: choices | GT2: clingo_total | GU2: conflicts | GV2: constraints | GW2: error | GX2: grounding | GY2: mem | GZ2: memout | HA2: models | HB2: par2 | HC2: restarts | HD2: rules | HE2: solving | HF2: status | HG2: time | HH2: timeout | HI2: variables | HJ2: atoms | HK2: choices | HL2: clingo_total | HM2: conflicts | HN2: constraints | HO2: error | HP2: grounding | HQ2: mem | HR2: memout | HS2: models | HT2: par2 | HU2: restarts | HV2: rules | HW2: solving | HX2: status | HY2: time | HZ2: timeout | IA2: variables | IB2: atoms | IC2: choices | ID2: clingo_total | IE2: conflicts | IF2: constraints | IG2: error | IH2: grounding | II2: mem | IJ2: memout | IK2: models | IL2: par2 | IM2: restarts | IN2: rules | IO2: solving | IP2: status | IQ2: time | IR2: timeout | IS2: variables | IT2: atoms | IU2: choices | IV2: clingo_total | IW2: conflicts | IX2: constraints | IY2: error | IZ2: grounding | JA2: mem | JB2: memout | JC2: models | JD2: par2 | JE2: restarts | JF2: rules | JG2: solving | JH2: status | JI2: time | JJ2: timeout | JK2: variables | JL2: atoms | JM2: choices | JN2: clingo_total | JO2: conflicts | JP2: constraints | JQ2: error | JR2: grounding | JS2: mem | JT2: memout | JU2: models | JV2: par2 | JW2: restarts | JX2: rules | JY2: solving | JZ2: status | KA2: time | KB2: timeout | KC2: variables | KD2: atoms | KE2: choices | KF2: clingo_total | KG2: conflicts | KH2: constraints | KI2: error | KJ2: grounding | KK2: mem | KL2: memout | KM2: models | KN2: par2 | KO2: restarts | KP2: rules | KQ2: solving | KR2: status | KS2: time | KT2: timeout | KU2: variables | KV2: atoms | KW2: choices | KX2: clingo_total | KY2: conflicts | KZ2: constraints | LA2: error | LB2: grounding | LC2: mem | LD2: memout | LE2: models | LF2: par2 | LG2: restarts | LH2: rules | LI2: solving | LJ2: status | LK2: time | LL2: timeout | LM2: variables | LN2: atoms | LO2: choices | LP2: clingo_total | LQ2: conflicts | LR2: constraints | LS2: error | LT2: grounding | LU2: mem | LV2: memout | LW2: models | LX2: par2 | LY2: restarts | LZ2: rules | MA2: solving | MB2: status | MC2: time | MD2: timeout | ME2: variables | MF2: atoms | MG2: choices | MH2: clingo_total | MI2: conflicts | MJ2: constraints | MK2: error | ML2: grounding | MM2: mem | MN2: memout | MO2: models | MP2: par2 | MQ2: restarts | MR2: rules | MS2: solving | MT2: status | MU2: time | MV2: timeout | MW2: variables | MX2: atoms | MY2: choices | MZ2: clingo_total | NA2: conflicts | NB2: constraints | NC2: error | ND2: grounding | NE2: mem | NF2: memout | NG2: models | NH2: par2 | NI2: restarts | NJ2: rules | NK2: solving | NL2: status | NM2: time | NN2: timeout | NO2: variables | NP2: atoms | NQ2: choices | NR2: clingo_total | NS2: conflicts | NT2: constraints | NU2: error | NV2: grounding | NW2: mem | NX2: memout | NY2: models | NZ2: par2 | OA2: restarts | OB2: rules | OC2: solving | OD2: status | OE2: time | OF2: timeout | OG2: variables | OH2: atoms | OI2: choices | OJ2: clingo_total | OK2: conflicts | OL2: constraints | OM2: error | ON2: grounding | OO2: mem | OP2: memout | OQ2: models | OR2: par2 | OS2: restarts | OT2: rules | OU2: solving | OV2: status | OW2: time | OX2: timeout | OY2: variables | OZ2: atoms | PA2: choices | PB2: clingo_total | PC2: conflicts | PD2: constraints | PE2: error | PF2: grounding | PG2: mem | PH2: memout | PI2: models | PJ2: par2 | PK2: restarts | PL2: rules | PM2: solving | PN2: status | PO2: time | PP2: timeout | PQ2: variables | PR2: atoms | PS2: choices | PT2: clingo_total | PU2: conflicts | PV2: constraints | PW2: error | PX2: grounding | PY2: mem | PZ2: memout | QA2: models | QB2: par2 | QC2: restarts | QD2: rules | QE2: solving | QF2: status | QG2: time | QH2: timeout | QI2: variables | QJ2: atoms | QK2: choices | QL2: clingo_total | QM2: conflicts | QN2: constraints | QO2: error | QP2: grounding | QQ2: mem | QR2: memout | QS2: models | QT2: par2 | QU2: restarts | QV2: rules | QW2: solving | QX2: status | QY2: time | QZ2: timeout | RA2: variables | RB2: atoms | RC2: choices | RD2: clingo_total | RE2: conflicts | RF2: constraints | RG2: error | RH2: grounding | RI2: mem | RJ2: memout | RK2: models | RL2: par2 | RM2: restarts | RN2: rules | RO2: solving | RP2: status | RQ2: time | RR2: timeout | RS2: variables | RT2: atoms | RU2: choices | RV2: clingo_total | RW2: conflicts | RX2: constraints | RY2: error | RZ2: grounding | SA2: mem | SB2: memout | SC2: models | SD2: par2 | SE2: restarts | SF2: rules | SG2: solving | SH2: status | SI2: time | SJ2: timeout | SK2: variables | SL2: atoms | SM2: choices | SN2: clingo_total | SO2: conflicts | SP2: constraints | SQ2: error | SR2: grounding | SS2: mem | ST2: memout | SU2: models | SV2: par2 | SW2: restarts | SX2: rules | SY2: solving | SZ2: status | TA2: time | TB2: timeout | TC2: variables | TD2: atoms | TE2: choices | TF2: clingo_total | TG2: conflicts | TH2: constraints | TI2: error | TJ2: grounding | TK2: mem | TL2: memout | TM2: models | TN2: par2 | TO2: restarts | TP2: rules | TQ2: solving | TR2: time | TS2: timeout | TT2: variables | TU2: atoms | TV2: choices | TW2: clingo_total | TX2: conflicts | TY2: constraints | TZ2: error | UA2: grounding | UB2: mem | UC2: memout | UD2: models | UE2: par2 | UF2: restarts | UG2: rules | UH2: solving | UI2: time | UJ2: timeout | UK2: variables | UL2: atoms | UM2: choices | UN2: clingo_total | UO2: conflicts | UP2: constraints | UQ2: error | UR2: grounding | US2: mem | UT2: memout | UU2: models | UV2: par2 | UW2: restarts | UX2: rules | UY2: solving | UZ2: time | VA2: timeout | VB2: variables
A3: ./bsp-0010 | G3: 0 | I3: 128 | J3: 0 | L3: 0.88 | P3: SATISFIABLE | Q3: 0.88 | R3: 0 | AQ3: 0 | AS3: 132 | AT3: 0 | AV3: 1.32 | AZ3: SATISFIABLE | BA3: 1.32 | BB3: 0 | BD3: 636 | BE3: 10 | BF3: 0.007 | BG3: 0 | BH3: 3508 | BI3: 0 | BJ3: 0.007 | BK3: 0 | BL3: 0 | BM3: 1 | BN3: 0.03 | BO3: 0 | BP3: 4780 | BQ3: 0 | BR3: SATISFIABLE | BS3: 0.03 | BT3: 0 | BU3: 242 | BV3: 199 | BW3: 4 | BX3: 0.003 | BY3: 0 | BZ3: 170 | CA3: 0 | CB3: 0.003 | CC3: 0 | CD3: 0 | CE3: 1 | CF3: 0.02 | CG3: 0 | CH3: 1328 | CI3: 0 | CJ3: SATISFIABLE | CK3: 0.02 | CL3: 0 | CM3: 129 | CN3: 798 | CO3: 52 | CP3: 0.008 | CQ3: 46 | CR3: 3536 | CS3: 0 | CT3: 0.008 | CU3: 0 | CV3: 0 | CW3: 1 | CX3: 0.03 | CY3: 0 | CZ3: 4960 | DA3: 0 | DB3: SATISFIABLE | DC3: 0.03 | DD3: 0 | DE3: 246 | DF3: 361 | DG3: 5 | DH3: 0.003 | DI3: 0 | DJ3: 508 | DK3: 0 | DL3: 0.003 | DM3: 0 | DN3: 0 | DO3: 1 | DP3: 0.03 | DQ3: 0 | DR3: 1498 | DS3: 0 | DT3: SATISFIABLE | DU3: 0.03 | DV3: 0 | DW3: 237 | DX3: 798 | DY3: 60 | DZ3: 0.008 | EA3: 55 | EB3: 6896 | EC3: 0 | ED3: 0.008 | EE3: 0 | EF3: 0 | EG3: 1 | EH3: 0.03 | EI3: 0 | EJ3: 4960 | EK3: 0 | EL3: SATISFIABLE | EM3: 0.03 | EN3: 0 | EO3: 1366 | EP3: 361 | EQ3: 6 | ER3: 0.004 | ES3: 0 | ET3: 3808 | EU3: 0 | EV3: 0.004 | EW3: 0 | EX3: 0 | EY3: 1 | EZ3: 0.03 | FA3: 0 | FB3: 1498 | FC3: 0 | FD3: SATISFIABLE | FE3: 0.03 | FF3: 0 | FG3: 1337 | FH3: 470 | FI3: 21 | FJ3: 0.005 | FK3: 15 | FL3: 3466 | FM3: 0 | FN3: 0.005 | FO3: 0 | FP3: 0 | FQ3: 1 | FR3: 0.03 | FS3: 0 | FT3: 3476 | FU3: 0 | FV3: SATISFIABLE | FW3: 0.03 | FX3: 0 | FY3: 230 | FZ3: 33 | GA3: 4 | GB3: 0.001 | GC3: 0 | GD3: 2 | GE3: 0 | GF3: 0.001 | GG3: 0 | GH3: 0 | GI3: 1 | GJ3: 0.04 | GK3: 0 | GL3: 34 | GM3: 0 | GN3: SATISFIABLE | GO3: 0.04 | GP3: 0 | GQ3: 11 | GR3: 472 | GS3: 10 | GT3: 0.005 | GU3: 0 | GV3: 3466 | GW3: 0 | GX3: 0.005 | GY3: 0 | GZ3: 0 | HA3: 1 | HB3: 0.03 | HC3: 0 | HD3: 3478 | HE3: 0 | HF3: SATISFIABLE | HG3: 0.03 | HH3: 0 | HI3: 230 | HJ3: 1920 | HK3: 60 | HL3: 0.026 | HM3: 55 | HN3: 6876 | HO3: 0 | HP3: 0.026 | HQ3: 8 | HR3: 0 | HS3: 1 | HT3: 0.13 | HU3: 0 | HV3: 4962 | HW3: 0 | HX3: SATISFIABLE | HY3: 0.13 | HZ3: 0 | IA3: 1356 | IB3: 35 | IC3: 8 | ID3: 0.001 | IE3: 0 | IF3: 2 | IG3: 0 | IH3: 0.001 | II3: 0 | IJ3: 0 | IK3: 1 | IL3: 0.03 | IM3: 0 | IN3: 36 | IO3: 0 | IP3: SATISFIABLE | IQ3: 0.03 | IR3: 0 | IS3: 11 | IT3: 472 | IU3: 21 | IV3: 0.005 | IW3: 15 | IX3: 3466 | IY3: 0 | IZ3: 0.005 | JA3: 0 | JB3: 0 | JC3: 1 | JD3: 0.03 | JE3: 0 | JF3: 3478 | JG3: 0 | JH3: SATISFIABLE | JI3: 0.03 | JJ3: 0 | JK3: 230 | JL3: 35 | JM3: 4 | JN3: 0.002 | JO3: 0 | JP3: 2 | JQ3: 0 | JR3: 0.002 | JS3: 0 | JT3: 0 | JU3: 1 | JV3: 0.04 | JW3: 0 | JX3: 36 | JY3: 0 | JZ3: SATISFIABLE | KA3: 0.04 | KB3: 0 | KC3: 11 | KD3: 636 | KE3: 10 | KF3: 0.008 | KG3: 0 | KH3: 3508 | KI3: 0 | KJ3: 0.008 | KK3: 0 | KL3: 0 | KM3: 1 | KN3: 0.04 | KO3: 0 | KP3: 4780 | KQ3: 0 | KR3: SATISFIABLE | KS3: 0.04 | KT3: 0 | KU3: 242 | KV3: 199 | KW3: 4 | KX3: 0.003 | KY3: 0 | KZ3: 170 | LA3: 0 | LB3: 0.003 | LC3: 0 | LD3: 0 | LE3: 1 | LF3: 0.03 | LG3: 0 | LH3: 1328 | LI3: 0 | LJ3: SATISFIABLE | LK3: 0.03 | LL3: 0 | LM3: 129 | LN3: 798 | LO3: 52 | LP3: 0.007 | LQ3: 46 | LR3: 3536 | LS3: 0 | LT3: 0.007 | LU3: 0 | LV3: 0 | LW3: 1 | LX3: 0.03 | LY3: 0 | LZ3: 4960 | MA3: 0 | MB3: SATISFIABLE | MC3: 0.03 | MD3: 0 | ME3: 246 | MF3: 361 | MG3: 5 | MH3: 0.003 | MI3: 0 | MJ3: 508 | MK3: 0 | ML3: 0.003 | MM3: 0 | MN3: 0 | MO3: 1 | MP3: 0.03 | MQ3: 0 | MR3: 1498 | MS3: 0 | MT3: SATISFIABLE | MU3: 0.03 | MV3: 0 | MW3: 237 | MX3: 798 | MY3: 60 | MZ3: 0.008 | NA3: 55 | NB3: 6896 | NC3: 0 | ND3: 0.008 | NE3: 0 | NF3: 0 | NG3: 1 | NH3: 0.03 | NI3: 0 | NJ3: 4960 | NK3: 0 | NL3: SATISFIABLE | NM3: 0.03 | NN3: 0 | NO3: 1366 | NP3: 361 | NQ3: 6 | NR3: 0.004 | NS3: 0 | NT3: 3808 | NU3: 0 | NV3: 0.004 | NW3: 0 | NX3: 0 | NY3: 1 | NZ3: 0.03 | OA3: 0 | OB3: 1498 | OC3: 0 | OD3: SATISFIABLE | OE3: 0.03 | OF3: 0 | OG3: 1337 | OH3: 470 | OI3: 21 | OJ3: 0.022 | OK3: 15 | OL3: 3466 | OM3: 0 | ON3: 0.022 | OO3: 4 | OP3: 0 | OQ3: 1 | OR3: 0.17 | OS3: 0 | OT3: 3476 | OU3: 0 | OV3: SATISFIABLE | OW3: 0.17 | OX3: 0 | OY3: 230 | OZ3: 33 | PA3: 4 | PB3: 0.001 | PC3: 0 | PD3: 2 | PE3: 0 | PF3: 0.001 | PG3: 0 | PH3: 0 | PI3: 1 | PJ3: 0.04 | PK3: 0 | PL3: 34 | PM3: 0 | PN3: SATISFIABLE | PO3: 0.04 | PP3: 0 | PQ3: 11 | PR3: 473 | PS3: 10 | PT3: 0.028 | PU3: 0 | PV3: 3466 | PW3: 0 | PX3: 0.028 | PY3: 0 | PZ3: 0 | QA3: 1 | QB3: 0.06 | QC3: 0 | QD3: 3479 | QE3: 0 | QF3: SATISFIABLE | QG3: 0.06 | QH3: 0 | QI3: 230 | QJ3: 1921 | QK3: 60 | QL3: 0.06 | QM3: 55 | QN3: 6876 | QO3: 0 | QP3: 0.06 | QQ3: 0 | QR3: 0 | QS3: 1 | QT3: 0.1 | QU3: 0 | QV3: 4963 | QW3: 0 | QX3: SATISFIABLE | QY3: 0.1 | QZ3: 0 | RA3: 1356 | RB3: 36 | RC3: 8 | RD3: 0.087 | RE3: 0 | RF3: 2 | RG3: 0 | RH3: 0.087 | RI3: 11 | RJ3: 0 | RK3: 1 | RL3: 0.26 | RM3: 0 | RN3: 37 | RO3: 0 | RP3: SATISFIABLE | RQ3: 0.26 | RR3: 0 | RS3: 11 | RT3: 473 | RU3: 21 | RV3: 0.022 | RW3: 15 | RX3: 3466 | RY3: 0 | RZ3: 0.022 | SA3: 0 | SB3: 0 | SC3: 1 | SD3: 0.05 | SE3: 0 | SF3: 3479 | SG3: 0 | SH3: SATISFIABLE | SI3: 0.05 | SJ3: 0 | SK3: 230 | SL3: 36 | SM3: 4 | SN3: 0.021 | SO3: 0 | SP3: 2 | SQ3: 0 | SR3: 0.021 | SS3: 0 | ST3: 0 | SU3: 1 | SV3: 0.05 | SW3: 0 | SX3: 37 | SY3: 0 | SZ3: SATISFIABLE | TA3: 0.05 | TB3: 0 | TC3: 11 | TD3: =MIN($B3,$T3,$AL3,$BD3,$BV3,$CN3,$DF3,$DX3,$EP3,$FH3,$FZ3,$GR3,$HJ3,$IB3,$IT3,$JL3,$KD3,$KV3,$LN3,$MF3,$MX3,$NP3,$OH3,$OZ3,$PR3,$QJ3,$RB3,$RT3,$SL3) -> 0 | TE3: =MIN($C3,$U3,$AM3,$BE3,$BW3,$CO3,$DG3,$DY3,$EQ3,$FI3,$GA3,$GS3,$HK3,$IC3,$IU3,$JM3,$KE3,$KW3,$LO3,$MG3,$MY3,$NQ3,$OI3,$PA3,$PS3,$QK3,$RC3,$RU3,$SM3) -> 0 | TF3: =MIN($D3,$V3,$AN3,$BF3,$BX3,$CP3,$DH3,$DZ3,$ER3,$FJ3,$GB3,$GT3,$HL3,$ID3,$IV3,$JN3,$KF3,$KX3,$LP3,$MH3,$MZ3,$NR3,$OJ3,$PB3,$PT3,$QL3,$RD3,$RV3,$SN3) -> 0 | TG3: =MIN($E3,$W3,$AO3,$BG3,$BY3,$CQ3,$DI3,$EA3,$ES3,$FK3,$GC3,$GU3,$HM3,$IE3,$IW3,$JO3,$KG3,$KY3,$LQ3,$MI3,$NA3,$NS3,$OK3,$PC3,$PU3,$QM3,$RE3,$RW3,$SO3) -> 0 | TH3: =MIN($F3,$X3,$AP3,$BH3,$BZ3,$CR3,$DJ3,$EB3,$ET3,$FL3,$GD3,$GV3,$HN3,$IF3,$IX3,$JP3,$KH3,$KZ3,$LR3,$MJ3,$NB3,$NT3,$OL3,$PD3,$PV3,$QN3,$RF3,$RX3,$SP3) -> 0 | TI3: =MIN($G3,$Y3,$AQ3,$BI3,$CA3,$CS3,$DK3,$EC3,$EU3,$FM3,$GE3,$GW3,$HO3,$IG3,$IY3,$JQ3,$KI3,$LA3,$LS3,$MK3,$NC3,$NU3,$OM3,$PE3,$PW3,$QO3,$RG3,$RY3,$SQ3) -> 0 | TJ3: =MIN($H3,$Z3,$AR3,$BJ3,$CB3,$CT3,$DL3,$ED3,$EV3,$FN3,$GF3,$GX3,$HP3,$IH3,$IZ3,$JR3,$KJ3,$LB3,$LT3,$ML3,$ND3,$NV3,$ON3,$PF3,$PX3,$QP3,$RH3,$RZ3,$SR3) -> 0 | TK3: =MIN($I3,$AA3,$AS3,$BK3,$CC3,$CU3,$DM3,$EE3,$EW3,$FO3,$GG3,$GY3,$HQ3,$II3,$JA3,$JS3,$KK3,$LC3,$LU3,$MM3,$NE3,$NW3,$OO3,$PG3,$PY3,$QQ3,$RI3,$SA3,$SS3) -> 0 | TL3: =MIN($J3,$AB3,$AT3,$BL3,$CD3,$CV3,$DN3,$EF3,$EX3,$FP3,$GH3,$GZ3,$HR3,$IJ3,$JB3,$JT3,$KL3,$LD3,$LV3,$MN3,$NF3,$NX3,$OP3,$PH3,$PZ3,$QR3,$RJ3,$SB3,$ST3) -> 0 | TM3: =MIN($K3,$AC3,$AU3,$BM3,$CE3,$CW3,$DO3,$EG3,$EY3,$FQ3,$GI3,$HA3,$HS3,$IK3,$JC3,$JU3,$KM3,$LE3,$LW3,$MO3,$NG3,$NY3,$OQ3,$PI3,$QA3,$QS3,$RK3,$SC3,$SU3) -> 0 | TN3: =MIN($L3,$AD3,$AV3,$BN3,$CF3,$CX3,$DP3,$EH3,$EZ3,$FR3,$GJ3,$HB3,$HT3,$IL3,$JD3,$JV3,$KN3,$LF3,$LX3,$MP3,$NH3,$NZ3,$OR3,$PJ3,$QB3,$QT3,$RL3,$SD3,$SV3) -> 0 | TO3: =MIN($M3,$AE3,$AW3,$BO3,$CG3,$CY3,$DQ3,$EI3,$FA3,$FS3,$GK3,$HC3,$HU3,$IM3,$JE3,$JW3,$KO3,$LG3,$LY3,$MQ3,$NI3,$OA3,$OS3,$PK3,$QC3,$QU3,$RM3,$SE3,$SW3) -> 0 | TP3: =MIN($N3,$AF3,$AX3,$BP3,$CH3,$CZ3,$DR3,$EJ3,$FB3,$FT3,$GL3,$HD3,$HV3,$IN3,$JF3,$JX3,$KP3,$LH3,$LZ3,$MR3,$NJ3,$OB3,$OT3,$PL3,$QD3,$QV3,$RN3,$SF3,$SX3) -> 0 | TQ3: =MIN($O3,$AG3,$AY3,$BQ3,$CI3,$DA3,$DS3,$EK3,$FC3,$FU3,$GM3,$HE3,$HW3,$IO3,$JG3,$JY3,$KQ3,$LI3,$MA3,$MS3,$NK3,$OC3,$OU3,$PM3,$QE3,$QW3,$RO3,$SG3,$SY3) -> 0 | TR3: =MIN($Q3,$AI3,$BA3,$BS3,$CK3,$DC3,$DU3,$EM3,$FE3,$FW3,$GO3,$HG3,$HY3,$IQ3,$JI3,$KA3,$KS3,$LK3,$MC3,$MU3,$NM3,$OE3,$OW3,$PO3,$QG3,$QY3,$RQ3,$SI3,$TA3) -> 0 | TS3: =MIN($R3,$AJ3,$BB3,$BT3,$CL3,$DD3,$DV3,$EN3,$FF3,$FX3,$GP3,$HH3,$HZ3,$IR3,$JJ3,$KB3,$KT3,$LL3,$MD3,$MV3,$NN3,$OF3,$OX3,$PP3,$QH3,$QZ3,$RR3,$SJ3,$TB3) -> 0 | TT3: =MIN($S3,$AK3,$BC3,$BU3,$CM3,$DE3,$DW3,$EO3,$FG3,$FY3,$GQ3,$HI3,$IA3,$IS3,$JK3,$KC3,$KU3,$LM3,$ME3,$MW3,$NO3,$OG3,$OY3,$PQ3,$QI3,$RA3,$RS3,$SK3,$TC3) -> 0 | TU3: =MEDIAN($B3,$T3,$AL3,$BD3,$BV3,$CN3,$DF3,$DX3,$EP3,$FH3,$FZ3,$GR3,$HJ3,$IB3,$IT3,$JL3,$KD3,$KV3,$LN3,$MF3,$MX3,$NP3,$OH3,$OZ3,$PR3,$QJ3,$RB3,$RT3,$SL3) -> 0 | TV3: =MEDIAN($C3,$U3,$AM3,$BE3,$BW3,$CO3,$DG3,$DY3,$EQ3,$FI3,$GA3,$GS3,$HK3,$IC3,$IU3,$JM3,$KE3,$KW3,$LO3,$MG3,$MY3,$NQ3,$OI3,$PA3,$PS3,$QK3,$RC3,$RU3,$SM3) -> 0 | TW3: =MEDIAN($D3,$V3,$AN3,$BF3,$BX3,$CP3,$DH3,$DZ3,$ER3,$FJ3,$GB3,$GT3,$HL3,$ID3,$IV3,$JN3,$KF3,$KX3,$LP3,$MH3,$MZ3,$NR3,$OJ3,$PB3,$PT3,$QL3,$RD3,$RV3,$SN3) -> 0 | TX3: =MEDIAN($E3,$W3,$AO3,$BG3,$BY3,$CQ3,$DI3,$EA3,$ES3,$FK3,$GC3,$GU3,$HM3,$IE3,$IW3,$JO3,$KG3,$KY3,$LQ3,$MI3,$NA3,$NS3,$OK3,$PC3,$PU3,$QM3,$RE3,$RW3,$SO3) -> 0 | TY3: =MEDIAN($F3,$X3,$AP3,$BH3,$BZ3,$CR3,$DJ3,$EB3,$ET3,$FL3,$GD3,$GV3,$HN3,$IF3,$IX3,$JP3,$KH3,$KZ3,$LR3,$MJ3,$NB3,$NT3,$OL3,$PD3,$PV3,$QN3,$RF3,$RX3,$SP3) -> 0 | TZ3: =MEDIAN($G3,$Y3,$AQ3,$BI3,$CA3,$CS3,$DK3,$EC3,$EU3,$FM3,$GE3,$GW3,$HO3,$IG3,$IY3,$JQ3,$KI3,$LA3,$LS3,$MK3,$NC3,$NU3,$OM3,$PE3,$PW3,$QO3,$RG3,$RY3,$SQ3) -> 0 | UA3: =MEDIAN($H3,$Z3,$AR3,$BJ3,$CB3,$CT3,$DL3,$ED3,$EV3,$FN3,$GF3,$GX3,$HP3,$IH3,$IZ3,$JR3,$KJ3,$LB3,$LT3,$ML3,$ND3,$NV3,$ON3,$PF3,$PX3,$QP3,$RH3,$RZ3,$SR3) -> 0 | UB3: =MEDIAN($I3,$AA3,$AS3,$BK3,$CC3,$CU3,$DM3,$EE3,$EW3,$FO3,$GG3,$GY3,$HQ3,$II3,$JA3,$JS3,$KK3,$LC3,$LU3,$MM3,$NE3,$NW3,$OO3,$PG3,$PY3,$QQ3,$RI3,$SA3,$SS3) -> 0 | UC3: =MEDIAN($J3,$AB3,$AT3,$BL3,$CD3,$CV3,$DN3,$EF3,$EX3,$FP3,$GH3,$GZ3,$HR3,$IJ3,$JB3,$JT3,$KL3,$LD3,$LV3,$MN3,$NF3,$NX3,$OP3,$PH3,$PZ3,$QR3,$RJ3,$SB3,$ST3) -> 0 | UD3: =MEDIAN($K3,$AC3,$AU3,$BM3,$CE3,$CW3,$DO3,$EG3,$EY3,$FQ3,$GI3,$HA3,$HS3,$IK3,$JC3,$JU3,$KM3,$LE3,$LW3,$MO3,$NG3,$NY3,$OQ3,$PI3,$QA3,$QS3,$RK3,$SC3,$SU3) -> 0 | UE3: =MEDIAN($L3,$AD3,$AV3,$BN3,$CF3,$CX3,$DP3,$EH3,$EZ3,$FR3,$GJ3,$HB3,$HT3,$IL3,$JD3,$JV3,$KN3,$LF3,$LX3,$MP3,$NH3,$NZ3,$OR3,$PJ3,$QB3,$QT3,$RL3,$SD3,$SV3) -> 0 | UF3: =MEDIAN($M3,$AE3,$AW3,$BO3,$CG3,$CY3,$DQ3,$EI3,$FA3,$FS3,$GK3,$HC3,$HU3,$IM3,$JE3,$JW3,$KO3,$LG3,$LY3,$MQ3,$NI3,$OA3,$OS3,$PK3,$QC3,$QU3,$RM3,$SE3,$SW3) -> 0 | UG3: =MEDIAN($N3,$AF3,$AX3,$BP3,$CH3,$CZ3,$DR3,$EJ3,$FB3,$FT3,$GL3,$HD3,$HV3,$IN3,$JF3,$JX3,$KP3,$LH3,$LZ3,$MR3,$NJ3,$OB3,$OT3,$PL3,$QD3,$QV3,$RN3,$SF3,$SX3) -> 0 | UH3: =MEDIAN($O3,$AG3,$AY3,$BQ3,$CI3,$DA3,$DS3,$EK3,$FC3,$FU3,$GM3,$HE3,$HW3,$IO3,$JG3,$JY3,$KQ3,$LI3,$MA3,$MS3,$NK3,$OC3,$OU3,$PM3,$QE3,$QW3,$RO3,$SG3,$SY3) -> 0 | UI3: =MEDIAN($Q3,$AI3,$BA3,$BS3,$CK3,$DC3,$DU3,$EM3,$FE3,$FW3,$GO3,$HG3,$HY3,$IQ3,$JI3,$KA3,$KS3,$LK3,$MC3,$MU3,$NM3,$OE3,$OW3,$PO3,$QG3,$QY3,$RQ3,$SI3,$TA3) -> 0 | UJ3: =MEDIAN($R3,$AJ3,$BB3,$BT3,$CL3,$DD3,$DV3,$EN3,$FF3,$FX3,$GP3,$HH3,$HZ3,$IR3,$JJ3,$KB3,$KT3,$LL3,$MD3,$MV3,$NN3,$OF3,$OX3,$PP3,$QH3,$QZ3,$RR3,$SJ3,$TB3) -> 0 | UK3: =MEDIAN($S3,$AK3,$BC3,$BU3,$CM3,$DE3,$DW3,$EO3,$FG3,$FY3,$GQ3,$HI3,$IA3,$IS3,$JK3,$KC3,$KU3,$LM3,$ME3,$MW3,$NO3,$OG3,$OY3,$PQ3,$QI3,$RA3,$RS3,$SK3,$TC3) -> 0 | UL3: =MAX($B3,$T3,$AL3,$BD3,$BV3,$CN3,$DF3,$DX3,$EP3,$FH3,$FZ3,$GR3,$HJ3,$IB3,$IT3,$JL3,$KD3,$KV3,$LN3,$MF3,$MX3,$NP3,$OH3,$OZ3,$PR3,$QJ3,$RB3,$RT3,$SL3) -> 0 | UM3: =MAX($C3,$U3,$AM3,$BE3,$BW3,$CO3,$DG3,$DY3,$EQ3,$FI3,$GA3,$GS3,$HK3,$IC3,$IU3,$JM3,$KE3,$KW3,$LO3,$MG3,$MY3,$NQ3,$OI3,$PA3,$PS3,$QK3,$RC3,$RU3,$SM3) -> 0 | UN3: =MAX($D3,$V3,$AN3,$BF3,$BX3,$CP3,$DH3,$DZ3,$ER3,$FJ3,$GB3,$GT3,$HL3,$ID3,$IV3,$JN3,$KF3,$KX3,$LP3,$MH3,$MZ3,$NR3,$OJ3,$PB3,$PT3,$QL3,$RD3,$RV3,$SN3) -> 0 | UO3: =MAX($E3,$W3,$AO3,$BG3,$BY3,$CQ3,$DI3,$EA3,$ES3,$FK3,$GC3,$GU3,$HM3,$IE3,$IW3,$JO3,$KG3,$KY3,$LQ3,$MI3,$NA3,$NS3,$OK3,$PC3,$PU3,$QM3,$RE3,$RW3,$SO3) -> 0 | UP3: =MAX($F3,$X3,$AP3,$BH3,$BZ3,$CR3,$DJ3,$EB3,$ET3,$FL3,$GD3,$GV3,$HN3,$IF3,$IX3,$JP3,$KH3,$KZ3,$LR3,$MJ3,$NB3,$NT3,$OL3,$PD3,$PV3,$QN3,$RF3,$RX3,$SP3) -> 0 | UQ3: =MAX($G3,$Y3,$AQ3,$BI3,$CA3,$CS3,$DK3,$EC3,$EU3,$FM3,$GE3,$GW3,$HO3,$IG3,$IY3,$JQ3,$KI3,$LA3,$LS3,$MK3,$NC3,$NU3,$OM3,$PE3,$PW3,$QO3,$RG3,$RY3,$SQ3) -> 0 | UR3: =MAX($H3,$Z3,$AR3,$BJ3,$CB3,$CT3,$DL3,$ED3,$EV3,$FN3,$GF3,$GX3,$HP3,$IH3,$IZ3,$JR3,$KJ3,$LB3,$LT3,$ML3,$ND3,$NV3,$ON3,$PF3,$PX3,$QP3,$RH3,$RZ3,$SR3) -> 0 | US3: =MAX($I3,$AA3,$AS3,$BK3,$CC3,$CU3,$DM3,$EE3,$EW3,$FO3,$GG3,$GY3,$HQ3,$II3,$JA3,$JS3,$KK3,$LC3,$LU3,$MM3,$NE3,$NW3,$OO3,$PG3,$PY3,$QQ3,$RI3,$SA3,$SS3) -> 0 | UT3: =MAX($J3,$AB3,$AT3,$BL3,$CD3,$CV3,$DN3,$EF3,$EX3,$FP3,$GH3,$GZ3,$HR3,$IJ3,$JB3,$JT3,$KL3,$LD3,$LV3,$MN3,$NF3,$NX3,$OP3,$PH3,$PZ3,$QR3,$RJ3,$SB3,$ST3) -> 0 | UU3: =MAX($K3,$AC3,$AU3,$BM3,$CE3,$CW3,$DO3,$EG3,$EY3,$FQ3,$GI3,$HA3,$HS3,$IK3,$JC3,$JU3,$KM3,$LE3,$LW3,$MO3,$NG3,$NY3,$OQ3,$PI3,$QA3,$QS3,$RK3,$SC3,$SU3) -> 0 | UV3: =MAX($L3,$AD3,$AV3,$BN3,$CF3,$CX3,$DP3,$EH3,$EZ3,$FR3,$GJ3,$HB3,$HT3,$IL3,$JD3,$JV3,$KN3,$LF3,$LX3,$MP3,$NH3,$NZ3,$OR3,$PJ3,$QB3,$QT3,$RL3,$SD3,$SV3) -> 0 | UW3: =MAX($M3,$AE3,$AW3,$BO3,$CG3,$CY3,$DQ3,$EI3,$FA3,$FS3,$GK3,$HC3,$HU3,$IM3,$JE3,$JW3,$KO3,$LG3,$LY3,$MQ3,$NI3,$OA3,$OS3,$PK3,$QC3,$QU3,$RM3,$SE3,$SW3) -> 0 | UX3: =MAX($N3,$AF3,$AX3,$BP3,$CH3,$CZ3,$DR3,$EJ3,$FB3,$FT3,$GL3,$HD3,$HV3,$IN3,$JF3,$JX3,$KP3,$LH3,$LZ3,$MR3,$NJ3,$OB3,$OT3,$PL3,$QD3,$QV3,$RN3,$SF3,$SX3) -> 0 | UY3: =MAX($O3,$AG3,$AY3,$BQ3,$CI3,$DA3,$DS3,$EK3,$FC3,$FU3,$GM3,$HE3,$HW3,$IO3,$JG3,$JY3,$KQ3,$LI3,$MA3,$MS3,$NK3,$OC3,$OU3,$PM3,$QE3,$QW3,$RO3,$SG3,$SY3) -> 0 | UZ3: =MAX($Q3,$AI3,$BA3,$BS3,$CK3,$DC3,$DU3,$EM3,$FE3,$FW3,$GO3,$HG3,$HY3,$IQ3,$JI3,$KA3,$KS3,$LK3,$MC3,$MU3,$NM3,$OE3,$OW3,$PO3,$QG3,$QY3,$RQ3,$SI3,$TA3) -> 0 | VA3: =MAX($R3,$AJ3,$BB3,$BT3,$CL3,$DD3,$DV3,$EN3,$FF3,$FX3,$GP3,$HH3,$HZ3,$IR3,$JJ3,$KB3,$KT3,$LL3,$MD3,$MV3,$NN3,$OF3,$OX3,$PP3,$QH3,$QZ3,$RR3,$SJ3,$TB3) -> 0 | VB3: =MAX($S3,$AK3,$BC3,$BU3,$CM3,$DE3,$DW3,$EO3,$FG3,$FY3,$GQ3,$HI3,$IA3,$IS3,$JK3,$KC3,$KU3,$LM3,$ME3,$MW3,$NO3,$OG3,$OY3,$PQ3,$QI3,$RA3,$RS3,$SK3,$TC3) -> 0
A4: ./bsp-0020 | G4: 0 | I4: 132 | J4: 0 | L4: 0.88 | P4: SATISFIABLE | Q4: 0.88 | R4: 0 | AQ4: 0 | AS4: 170 | AT4: 0 | AV4: 0.96 | AZ4: SATISFIABLE | BA4: 0.96 | BB4: 0 | BD4: 2371 | BE4: 20 | BF4: 0.063 | BG4: 0 | BH4: 45768 | BI4: 0 | BJ4: 0.063 | BK4: 0 | BL4: 0 | BM4: 1 | BN4: 0.09 | BO4: 0 | BP4: 54815 | BQ4: 0 | BR4: SATISFIABLE | BS4: 0.09 | BT4: 0 | BU4: 882 | BV4: 694 | BW4: 6 | BX4: 0.032 | BY4: 0 | BZ4: 540 | CA4: 0 | CB4: 0.032 | CC4: 9 | CD4: 0 | CE4: 1 | CF4: 0.12 | CG4: 0 | CH4: 9153 | CI4: 0 | CJ4: SATISFIABLE | CK4: 0.12 | CL4: 0 | CM4: 459 | CN4: 2998 | CO4: 606 | CP4: 0.067 | CQ4: 524 | CR4: 45816 | CS4: 0 | CT4: 0.057 | CU4: 0 | CV4: 0 | CW4: 1 | CX4: 0.09 | CY4: 5 | CZ4: 55480 | DA4: 0.01 | DB4: SATISFIABLE | DC4: 0.09 | DD4: 0 | DE4: 886 | DF4: 1321 | DG4: 6 | DH4: 0.011 | DI4: 0 | DJ4: 1827 | DK4: 0 | DL4: 0.011 | DM4: 0 | DN4: 0 | DO4: 1 | DP4: 0.03 | DQ4: 0 | DR4: 9798 | DS4: 0 | DT4: SATISFIABLE | DU4: 0.03 | DV4: 0 | DW4: 876 | DX4: 2998 | DY4: 578 | DZ4: 0.083 | EA4: 498 | EB4: 71136 | EC4: 0 | ED4: 0.073 | EE4: 0 | EF4: 0 | EG4: 1 | EH4: 0.11 | EI4: 5 | EJ4: 55480 | EK4: 0.01 | EL4: SATISFIABLE | EM4: 0.11 | EN4: 0 | EO4: 9326 | EP4: 1321 | EQ4: 13 | ER4: 0.024 | ES4: 1 | ET4: 27007 | EU4: 0 | EV4: 0.024 | EW4: 0 | EX4: 0 | EY4: 1 | EZ4: 0.05 | FA4: 0 | FB4: 9798 | FC4: 0 | FD4: SATISFIABLE | FE4: 0.05 | FF4: 0 | FG4: 9276 | FH4: 1740 | FI4: 1510 | FJ4: 0.065 | FK4: 1338 | FL4: 45686 | FM4: 0 | FN4: 0.045 | FO4: 0 | FP4: 0 | FQ4: 1 | FR4: 0.09 | FS4: 12 | FT4: 45706 | FU4: 0.02 | FV4: SATISFIABLE | FW4: 0.09 | FX4: 0 | FY4: 860 | FZ4: 63 | GA4: 7 | GB4: 0.001 | GC4: 0 | GD4: 2 | GE4: 0 | GF4: 0.001 | GG4: 0 | GH4: 0 | GI4: 1 | GJ4: 0.05 | GK4: 0 | GL4: 64 | GM4: 0 | GN4: SATISFIABLE | GO4: 0.05 | GP4: 0 | GQ4: 21 | GR4: 1742 | GS4: 20 | GT4: 0.077 | GU4: 0 | GV4: 45686 | GW4: 0 | GX4: 0.077 | GY4: 5 | GZ4: 0 | HA4: 1 | HB4: 0.19 | HC4: 0 | HD4: 45708 | HE4: 0 | HF4: SATISFIABLE | HG4: 0.19 | HH4: 0 | HI4: 860 | HJ4: 11440 | HK4: 573 | HL4: 0.215 | HM4: 492 | HN4: 71096 | HO4: 0 | HP4: 0.095 | HQ4: 25 | HR4: 0 | HS4: 1 | HT4: 0.24 | HU4: 5 | HV4: 55482 | HW4: 0.12 | HX4: SATISFIABLE | HY4: 0.24 | HZ4: 0 | IA4: 9306 | IB4: 65 | IC4: 17 | ID4: 0.001 | IE4: 0 | IF4: 2 | IG4: 0 | IH4: 0.001 | II4: 0 | IJ4: 0 | IK4: 1 | IL4: 0.03 | IM4: 0 | IN4: 66 | IO4: 0 | IP4: SATISFIABLE | IQ4: 0.03 | IR4: 0 | IS4: 21 | IT4: 1742 | IU4: 1510 | IV4: 0.078 | IW4: 1338 | IX4: 45686 | IY4: 0 | IZ4: 0.048 | JA4: 0 | JB4: 0 | JC4: 1 | JD4: 0.1 | JE4: 12 | JF4: 45708 | JG4: 0.03 | JH4: SATISFIABLE | JI4: 0.1 | JJ4: 0 | JK4: 860 | JL4: 65 | JM4: 7 | JN4: 0.001 | JO4: 0 | JP4: 2 | JQ4: 0 | JR4: 0.001 | JS4: 0 | JT4: 0 | JU4: 1 | JV4: 0.03 | JW4: 0 | JX4: 66 | JY4: 0 | JZ4: SATISFIABLE | KA4: 0.03 | KB4: 0 | KC4: 21 | KD4: 2371 | KE4: 20 | KF4: 0.073 | KG4: 0 | KH4: 45768 | KI4: 0 | KJ4: 0.073 | KK4: 0 | KL4: 0 | KM4: 1 | KN4: 0.1 | KO4: 0 | KP4: 54815 | KQ4: 0 | KR4: SATISFIABLE | KS4: 0.1 | KT4: 0 | KU4: 882 | KV4: 694 | KW4: 6 | KX4: 0.015 | KY4: 0 | KZ4: 540 | LA4: 0 | LB4: 0.015 | LC4: 0 | LD4: 0 | LE4: 1 | LF4: 0.04 | LG4: 0 | LH4: 9153 | LI4: 0 | LJ4: SATISFIABLE | LK4: 0.04 | LL4: 0 | LM4: 459 | LN4: 2998 | LO4: 606 | LP4: 0.071 | LQ4: 524 | LR4: 45816 | LS4: 0 | LT4: 0.061 | LU4: 0 | LV4: 0 | LW4: 1 | LX4: 0.1 | LY4: 5 | LZ4: 55480 | MA4: 0.01 | MB4: SATISFIABLE | MC4: 0.1 | MD4: 0 | ME4: 886 | MF4: 1321 | MG4: 6 | MH4: 0.029 | MI4: 0 | MJ4: 1827 | MK4: 0 | ML4: 0.029 | MM4: 4 | MN4: 0 | MO4: 1 | MP4: 0.17 | MQ4: 0 | MR4: 9798 | MS4: 0 | MT4: SATISFIABLE | MU4: 0.17 | MV4: 0 | MW4: 876 | MX4: 2998 | MY4: 578 | MZ4: 0.085 | NA4: 498 | NB4: 71136 | NC4: 0 | ND4: 0.075 | NE4: 0 | NF4: 0 | NG4: 1 | NH4: 0.11 | NI4: 5 | NJ4: 55480 | NK4: 0.01 | NL4: SATISFIABLE | NM4: 0.11 | NN4: 0 | NO4: 9326 | NP4: 1321 | NQ4: 13 | NR4: 0.02 | NS4: 1 | NT4: 27007 | NU4: 0 | NV4: 0.02 | NW4: 0 | NX4: 0 | NY4: 1 | NZ4: 0.05 | OA4: 0 | OB4: 9798 | OC4: 0 | OD4: SATISFIABLE | OE4: 0.05 | OF4: 0 | OG4: 9276 | OH4: 1740 | OI4: 1510 | OJ4: 0.068 | OK4: 1338 | OL4: 45686 | OM4: 0 | ON4: 0.048 | OO4: 0 | OP4: 0 | OQ4: 1 | OR4: 0.09 | OS4: 12 | OT4: 45706 | OU4: 0.02 | OV4: SATISFIABLE | OW4: 0.09 | OX4: 0 | OY4: 860 | OZ4: 63 | PA4: 7 | PB4: 0.001 | PC4: 0 | PD4: 2 | PE4: 0 | PF4: 0.001 | PG4: 0 | PH4: 0 | PI4: 1 | PJ4: 0.04 | PK4: 0 | PL4: 64 | PM4: 0 | PN4: SATISFIABLE | PO4: 0.04 | PP4: 0 | PQ4: 21 | PR4: 1743 | PS4: 20 | PT4: 0.077 | PU4: 0 | PV4: 45686 | PW4: 0 | PX4: 0.077 | PY4: 0 | PZ4: 0 | QA4: 1 | QB4: 0.11 | QC4: 0 | QD4: 45709 | QE4: 0 | QF4: SATISFIABLE | QG4: 0.11 | QH4: 0 | QI4: 860 | QJ4: 11441 | QK4: 573 | QL4: 0.446 | QM4: 492 | QN4: 71096 | QO4: 0 | QP4: 0.306 | QQ4: 29 | QR4: 0 | QS4: 1 | QT4: 0.48 | QU4: 5 | QV4: 55483 | QW4: 0.14 | QX4: SATISFIABLE | QY4: 0.48 | QZ4: 0 | RA4: 9306 | RB4: 66 | RC4: 17 | RD4: 0.019 | RE4: 0 | RF4: 2 | RG4: 0 | RH4: 0.019 | RI4: 0 | RJ4: 0 | RK4: 1 | RL4: 0.04 | RM4: 0 | RN4: 67 | RO4: 0 | RP4: SATISFIABLE | RQ4: 0.04 | RR4: 0 | RS4: 21 | RT4: 1743 | RU4: 1510 | RV4: 0.182 | RW4: 1338 | RX4: 45686 | RY4: 0 | RZ4: 0.122 | SA4: 18 | SB4: 0 | SC4: 1 | SD4: 0.31 | SE4: 12 | SF4: 45709 | SG4: 0.06 | SH4: SATISFIABLE | SI4: 0.31 | SJ4: 0 | SK4: 860 | SL4: 66 | SM4: 7 | SN4: 0.017 | SO4: 0 | SP4: 2 | SQ4: 0 | SR4: 0.017 | SS4: 0 | ST4: 0 | SU4: 1 | SV4: 0.04 | SW4: 0 | SX4: 67 | SY4: 0 | SZ4: SATISFIABLE | TA4: 0.04 | TB4: 0 | TC4: 21 | TD4: =MIN($B4,$T4,$AL4,$BD4,$BV4,$CN4,$DF4,$DX4,$EP4,$FH4,$FZ4,$GR4,$HJ4,$IB4,$IT4,$JL4,$KD4,$KV4,$LN4,$MF4,$MX4,$NP4,$OH4,$OZ4,$PR4,$QJ4,$RB4,$RT4,$SL4) -> 0 | TE4: =MIN($C4,$U4,$AM4,$BE4,$BW4,$CO4,$DG4,$DY4,$EQ4,$FI4,$GA4,$GS4,$HK4,$IC4,$IU4,$JM4,$KE4,$KW4,$LO4,$MG4,$MY4,$NQ4,$OI4,$PA4,$PS4,$QK4,$RC4,$RU4,$SM4) -> 0 | TF4: =MIN($D4,$V4,$AN4,$BF4,$BX4,$CP4,$DH4,$DZ4,$ER4,$FJ4,$GB4,$GT4,$HL4,$ID4,$IV4,$JN4,$KF4,$KX4,$LP4,$MH4,$MZ4,$NR4,$OJ4,$PB4,$PT4,$QL4,$RD4,$RV4,$SN4) -> 0 | TG4: =MIN($E4,$W4,$AO4,$BG4,$BY4,$CQ4,$DI4,$EA4,$ES4,$FK4,$GC4,$GU4,$HM4,$IE4,$IW4,$JO4,$KG4,$KY4,$LQ4,$MI4,$NA4,$NS4,$OK4,$PC4,$PU4,$QM4,$RE4,$RW4,$SO4) -> 0 | TH4: =MIN($F4,$X4,$AP4,$BH4,$BZ4,$CR4,$DJ4,$EB4,$ET4,$FL4,$GD4,$GV4,$HN4,$IF4,$IX4,$JP4,$KH4,$KZ4,$LR4,$MJ4,$NB4,$NT4,$OL4,$PD4,$PV4,$QN4,$RF4,$RX4,$SP4) -> 0 | TI4: =MIN($G4,$Y4,$AQ4,$BI4,$CA4,$CS4,$DK4,$EC4,$EU4,$FM4,$GE4,$GW4,$HO4,$IG4,$IY4,$JQ4,$KI4,$LA4,$LS4,$MK4,$NC4,$NU4,$OM4,$PE4,$PW4,$QO4,$RG4,$RY4,$SQ4) -> 0 | TJ4: =MIN($H4,$Z4,$AR4,$BJ4,$CB4,$CT4,$DL4,$ED4,$EV4,$FN4,$GF4,$GX4,$HP4,$IH4,$IZ4,$JR4,$KJ4,$LB4,$LT4,$ML4,$ND4,$NV4,$ON4,$PF4,$PX4,$QP4,$RH4,$RZ4,$SR4) -> 0 | TK4: =MIN($I4,$AA4,$AS4,$BK4,$CC4,$CU4,$DM4,$EE4,$EW4,$FO4,$GG4,$GY4,$HQ4,$II4,$JA4,$JS4,$KK4,$LC4,$LU4,$MM4,$NE4,$NW4,$OO4,$PG4,$PY4,$QQ4,$RI4,$SA4,$SS4) -> 0 | TL4: =MIN($J4,$AB4,$AT4,$BL4,$CD4,$CV4,$DN4,$EF4,$EX4,$FP4,$GH4,$GZ4,$HR4,$IJ4,$JB4,$JT4,$KL4,$LD4,$LV4,$MN4,$NF4,$NX4,$OP4,$PH4,$PZ4,$QR4,$RJ4,$SB4,$ST4) -> 0 | TM4: =MIN($K4,$AC4,$AU4,$BM4,$CE4,$CW4,$DO4,$EG4,$EY4,$FQ4,$GI4,$HA4,$HS4,$IK4,$JC4,$JU4,$KM4,$LE4,$LW4,$MO4,$NG4,$NY4,$OQ4,$PI4,$QA4,$QS4,$RK4,$SC4,$SU4) -> 0 | TN4: =MIN($L4,$AD4,$AV4,$BN4,$CF4,$CX4,$DP4,$EH4,$EZ4,$FR4,$GJ4,$HB4,$HT4,$IL4,$JD4,$JV4,$KN4,$LF4,$LX4,$MP4,$NH4,$NZ4,$OR4,$PJ4,$QB4,$QT4,$RL4,$SD4,$SV4) -> 0 | TO4: =MIN($M4,$AE4,$AW4,$BO4,$CG4,$CY4,$DQ4,$EI4,$FA4,$FS4,$GK4,$HC4,$HU4,$IM4,$JE4,$JW4,$KO4,$LG4,$LY4,$MQ4,$NI4,$OA4,$OS4,$PK4,$QC4,$QU4,$RM4,$SE4,$SW4) -> 0 | TP4: =MIN($N4,$AF4,$AX4,$BP4,$CH4,$CZ4,$DR4,$EJ4,$FB4,$FT4,$GL4,$HD4,$HV4,$IN4,$JF4,$JX4,$KP4,$LH4,$LZ4,$MR4,$NJ4,$OB4,$OT4,$PL4,$QD4,$QV4,$RN4,$SF4,$SX4) -> 0 | TQ4: =MIN($O4,$AG4,$AY4,$BQ4,$CI4,$DA4,$DS4,$EK4,$FC4,$FU4,$GM4,$HE4,$HW4,$IO4,$JG4,$JY4,$KQ4,$LI4,$MA4,$MS4,$NK4,$OC4,$OU4,$PM4,$QE4,$QW4,$RO4,$SG4,$SY4) -> 0 | TR4: =MIN($Q4,$AI4,$BA4,$BS4,$CK4,$DC4,$DU4,$EM4,$FE4,$FW4,$GO4,$HG4,$HY4,$IQ4,$JI4,$KA4,$KS4,$LK4,$MC4,$MU4,$NM4,$OE4,$OW4,$PO4,$QG4,$QY4,$RQ4,$SI4,$TA4) -> 0 | TS4: =MIN($R4,$AJ4,$BB4,$BT4,$CL4,$DD4,$DV4,$EN4,$FF4,$FX4,$GP4,$HH4,$HZ4,$IR4,$JJ4,$KB4,$KT4,$LL4,$MD4,$MV4,$NN4,$OF4,$OX4,$PP4,$QH4,$QZ4,$RR4,$SJ4,$TB4) -> 0 | TT4: =MIN($S4,$AK4,$BC4,$BU4,$CM4,$DE4,$DW4,$EO4,$FG4,$FY4,$GQ4,$HI4,$IA4,$IS4,$JK4,$KC4,$KU4,$LM4,$ME4,$MW4,$NO4,$OG4,$OY4,$PQ4,$QI4,$RA4,$RS4,$SK4,$TC4) -> 0 | TU4: =MEDIAN($B4,$T4,$AL4,$BD4,$BV4,$CN4,$DF4,$DX4,$EP4,$FH4,$FZ4,$GR4,$HJ4,$IB4,$IT4,$JL4,$KD4,$KV4,$LN4,$MF4,$MX4,$NP4,$OH4,$OZ4,$PR4,$QJ4,$RB4,$RT4,$SL4) -> 0 | TV4: =MEDIAN($C4,$U4,$AM4,$BE4,$BW4,$CO4,$DG4,$DY4,$EQ4,$FI4,$GA4,$GS4,$HK4,$IC4,$IU4,$JM4,$KE4,$KW4,$LO4,$MG4,$MY4,$NQ4,$OI4,$PA4,$PS4,$QK4,$RC4,$RU4,$SM4) -> 0 | TW4: =MEDIAN($D4,$V4,$AN4,$BF4,$BX4,$CP4,$DH4,$DZ4,$ER4,$FJ4,$GB4,$GT4,$HL4,$ID4,$IV4,$JN4,$KF4,$KX4,$LP4,$MH4,$MZ4,$NR4,$OJ4,$PB4,$PT4,$QL4,$RD4,$RV4,$SN4) -> 0 | TX4: =MEDIAN($E4,$W4,$AO4,$BG4,$BY4,$CQ4,$DI4,$EA4,$ES4,$FK4,$GC4,$GU4,$HM4,$IE4,$IW4,$JO4,$KG4,$KY4,$LQ4,$MI4,$NA4,$NS4,$OK4,$PC4,$PU4,$QM4,$RE4,$RW4,$SO4) -> 0 | TY4: =MEDIAN($F4,$X4,$AP4,$BH4,$BZ4,$CR4,$DJ4,$EB4,$ET4,$FL4,$GD4,$GV4,$HN4,$IF4,$IX4,$JP4,$KH4,$KZ4,$LR4,$MJ4,$NB4,$NT4,$OL4,$PD4,$PV4,$QN4,$RF4,$RX4,$SP4) -> 0 | TZ4: =MEDIAN($G4,$Y4,$AQ4,$BI4,$CA4,$CS4,$DK4,$EC4,$EU4,$FM4,$GE4,$GW4,$HO4,$IG4,$IY4,$JQ4,$KI4,$LA4,$LS4,$MK4,$NC4,$NU4,$OM4,$PE4,$PW4,$QO4,$RG4,$RY4,$SQ4) -> 0 | UA4: =MEDIAN($H4,$Z4,$AR4,$BJ4,$CB4,$CT4,$DL4,$ED4,$EV4,$FN4,$GF4,$GX4,$HP4,$IH4,$IZ4,$JR4,$KJ4,$LB4,$LT4,$ML4,$ND4,$NV4,$ON4,$PF4,$PX4,$QP4,$RH4,$RZ4,$SR4) -> 0 | UB4: =MEDIAN($I4,$AA4,$AS4,$BK4,$CC4,$CU4,$DM4,$EE4,$EW4,$FO4,$GG4,$GY4,$HQ4,$II4,$JA4,$JS4,$KK4,$LC4,$LU4,$MM4,$NE4,$NW4,$OO4,$PG4,$PY4,$QQ4,$RI4,$SA4,$SS4) -> 0 | UC4: =MEDIAN($J4,$AB4,$AT4,$BL4,$CD4,$CV4,$DN4,$EF4,$EX4,$FP4,$GH4,$GZ4,$HR4,$IJ4,$JB4,$JT4,$KL4,$LD4,$LV4,$MN4,$NF4,$NX4,$OP4,$PH4,$PZ4,$QR4,$RJ4,$SB4,$ST4) -> 0 | UD4: =MEDIAN($K4,$AC4,$AU4,$BM4,$CE4,$CW4,$DO4,$EG4,$EY4,$FQ4,$GI4,$HA4,$HS4,$IK4,$JC4,$JU4,$KM4,$LE4,$LW4,$MO4,$NG4,$NY4,$OQ4,$PI4,$QA4,$QS4,$RK4,$SC4,$SU4) -> 0 | UE4: =MEDIAN($L4,$AD4,$AV4,$BN4,$CF4,$CX4,$DP4,$EH4,$EZ4,$FR4,$GJ4,$HB4,$HT4,$IL4,$JD4,$JV4,$KN4,$LF4,$LX4,$MP4,$NH4,$NZ4,$OR4,$PJ4,$QB4,$QT4,$RL4,$SD4,$SV4) -> 0 | UF4: =MEDIAN($M4,$AE4,$AW4,$BO4,$CG4,$CY4,$DQ4,$EI4,$FA4,$FS4,$GK4,$HC4,$HU4,$IM4,$JE4,$JW4,$KO4,$LG4,$LY4,$MQ4,$NI4,$OA4,$OS4,$PK4,$QC4,$QU4,$RM4,$SE4,$SW4) -> 0 | UG4: =MEDIAN($N4,$AF4,$AX4,$BP4,$CH4,$CZ4,$DR4,$EJ4,$FB4,$FT4,$GL4,$HD4,$HV4,$IN4,$JF4,$JX4,$KP4,$LH4,$LZ4,$MR4,$NJ4,$OB4,$OT4,$PL4,$QD4,$QV4,$RN4,$SF4,$SX4) -> 0 | UH4: =MEDIAN($O4,$AG4,$AY4,$BQ4,$CI4,$DA4,$DS4,$EK4,$FC4,$FU4,$GM4,$HE4,$HW4,$IO4,$JG4,$JY4,$KQ4,$LI4,$MA4,$MS4,$NK4,$OC4,$OU4,$PM4,$QE4,$QW4,$RO4,$SG4,$SY4) -> 0 | UI4: =MEDIAN($Q4,$AI4,$BA4,$BS4,$CK4,$DC4,$DU4,$EM4,$FE4,$FW4,$GO4,$HG4,$HY4,$IQ4,$JI4,$KA4,$KS4,$LK4,$MC4,$MU4,$NM4,$OE4,$OW4,$PO4,$QG4,$QY4,$RQ4,$SI4,$TA4) -> 0 | UJ4: =MEDIAN($R4,$AJ4,$BB4,$BT4,$CL4,$DD4,$DV4,$EN4,$FF4,$FX4,$GP4,$HH4,$HZ4,$IR4,$JJ4,$KB4,$KT4,$LL4,$MD4,$MV4,$NN4,$OF4,$OX4,$PP4,$QH4,$QZ4,$RR4,$SJ4,$TB4) -> 0 | UK4: =MEDIAN($S4,$AK4,$BC4,$BU4,$CM4,$DE4,$DW4,$EO4,$FG4,$FY4,$GQ4,$HI4,$IA4,$IS4,$JK4,$KC4,$KU4,$LM4,$ME4,$MW4,$NO4,$OG4,$OY4,$PQ4,$QI4,$RA4,$RS4,$SK4,$TC4) -> 0 | UL4: =MAX($B4,$T4,$AL4,$BD4,$BV4,$CN4,$DF4,$DX4,$EP4,$FH4,$FZ4,$GR4,$HJ4,$IB4,$IT4,$JL4,$KD4,$KV4,$LN4,$MF4,$MX4,$NP4,$OH4,$OZ4,$PR4,$QJ4,$RB4,$RT4,$SL4) -> 0 | UM4: =MAX($C4,$U4,$AM4,$BE4,$BW4,$CO4,$DG4,$DY4,$EQ4,$FI4,$GA4,$GS4,$HK4,$IC4,$IU4,$JM4,$KE4,$KW4,$LO4,$MG4,$MY4,$NQ4,$OI4,$PA4,$PS4,$QK4,$RC4,$RU4,$SM4) -> 0 | UN4: =MAX($D4,$V4,$AN4,$BF4,$BX4,$CP4,$DH4,$DZ4,$ER4,$FJ4,$GB4,$GT4,$HL4,$ID4,$IV4,$JN4,$KF4,$KX4,$LP4,$MH4,$MZ4,$NR4,$OJ4,$PB4,$PT4,$QL4,$RD4,$RV4,$SN4) -> 0 | UO4: =MAX($E4,$W4,$AO4,$BG4,$BY4,$CQ4,$DI4,$EA4,$ES4,$FK4,$GC4,$GU4,$HM4,$IE4,$IW4,$JO4,$KG4,$KY4,$LQ4,$MI4,$NA4,$NS4,$OK4,$PC4,$PU4,$QM4,$RE4,$RW4,$SO4) -> 0 | UP4: =MAX($F4,$X4,$AP4,$BH4,$BZ4,$CR4,$DJ4,$EB4,$ET4,$FL4,$GD4,$GV4,$HN4,$IF4,$IX4,$JP4,$KH4,$KZ4,$LR4,$MJ4,$NB4,$NT4,$OL4,$PD4,$PV4,$QN4,$RF4,$RX4,$SP4) -> 0 | UQ4: =MAX($G4,$Y4,$AQ4,$BI4,$CA4,$CS4,$DK4,$EC4,$EU4,$FM4,$GE4,$GW4,$HO4,$IG4,$IY4,$JQ4,$KI4,$LA4,$LS4,$MK4,$NC4,$NU4,$OM4,$PE4,$PW4,$QO4,$RG4,$RY4,$SQ4) -> 0 | UR4: =MAX($H4,$Z4,$AR4,$BJ4,$CB4,$CT4,$DL4,$ED4,$EV4,$FN4,$GF4,$GX4,$HP4,$IH4,$IZ4,$JR4,$KJ4,$LB4,$LT4,$ML4,$ND4,$NV4,$ON4,$PF4,$PX4,$QP4,$RH4,$RZ4,$SR4) -> 0 | US4: =MAX($I4,$AA4,$AS4,$BK4,$CC4,$CU4,$DM4,$EE4,$EW4,$FO4,$GG4,$GY4,$HQ4,$II4,$JA4,$JS4,$KK4,$LC4,$LU4,$MM4,$NE4,$NW4,$OO4,$PG4,$PY4,$QQ4,$RI4,$SA4,$SS4) -> 0 | UT4: =MAX($J4,$AB4,$AT4,$BL4,$CD4,$CV4,$DN4,$EF4,$EX4,$FP4,$GH4,$GZ4,$HR4,$IJ4,$JB4,$JT4,$KL4,$LD4,$LV4,$MN4,$NF4,$NX4,$OP4,$PH4,$PZ4,$QR4,$RJ4,$SB4,$ST4) -> 0 | UU4: =MAX($K4,$AC4,$AU4,$BM4,$CE4,$CW4,$DO4,$EG4,$EY4,$FQ4,$GI4,$HA4,$HS4,$IK4,$JC4,$JU4,$KM4,$LE4,$LW4,$MO4,$NG4,$NY4,$OQ4,$PI4,$QA4,$QS4,$RK4,$SC4,$SU4) -> 0 | UV4: =MAX($L4,$AD4,$AV4,$BN4,$CF4,$CX4,$DP4,$EH4,$EZ4,$FR4,$GJ4,$HB4,$HT4,$IL4,$JD4,$JV4,$KN4,$LF4,$LX4,$MP4,$NH4,$NZ4,$OR4,$PJ4,$QB4,$QT4,$RL4,$SD4,$SV4) -> 0 | UW4: =MAX($M4,$AE4,$AW4,$BO4,$CG4,$CY4,$DQ4,$EI4,$FA4,$FS4,$GK4,$HC4,$HU4,$IM4,$JE4,$JW4,$KO4,$LG4,$LY4,$MQ4,$NI4,$OA4,$OS4,$PK4,$QC4,$QU4,$RM4,$SE4,$SW4) -> 0 | UX4: =MAX($N4,$AF4,$AX4,$BP4,$CH4,$CZ4,$DR4,$EJ4,$FB4,$FT4,$GL4,$HD4,$HV4,$IN4,$JF4,$JX4,$KP4,$LH4,$LZ4,$MR4,$NJ4,$OB4,$OT4,$PL4,$QD4,$QV4,$RN4,$SF4,$SX4) -> 0 | UY4: =MAX($O4,$AG4,$AY4,$BQ4,$CI4,$DA4,$DS4,$EK4,$FC4,$FU4,$GM4,$HE4,$HW4,$IO4,$JG4,$JY4,$KQ4,$LI4,$MA4,$MS4,$NK4,$OC4,$OU4,$PM4,$QE4,$QW4,$RO4,$SG4,$SY4) -> 0 | UZ4: =MAX($Q4,$AI4,$BA4,$BS4,$CK4,$DC4,$DU4,$EM4,$FE4,$FW4,$GO4,$HG4,$HY4,$IQ4,$JI4,$KA4,$KS4,$LK4,$MC4,$MU4,$NM4,$OE4,$OW4,$PO4,$QG4,$QY4,$RQ4,$SI4,$TA4) -> 0 | VA4: =MAX($R4,$AJ4,$BB4,$BT4,$CL4,$DD4,$DV4,$EN4,$FF4,$FX4,$GP4,$HH4,$HZ4,$IR4,$JJ4,$KB4,$KT4,$LL4,$MD4,$MV4,$NN4,$OF4,$OX4,$PP4,$QH4,$QZ4,$RR4,$SJ4,$TB4) -> 0 | VB4: =MAX($S4,$AK4,$BC4,$BU4,$CM4,$DE4,$DW4,$EO4,$FG4,$FY4,$GQ4,$HI4,$IA4,$IS4,$JK4,$KC4,$KU4,$LM4,$ME4,$MW4,$NO4,$OG4,$OY4,$PQ4,$QI4,$RA4,$RS4,$SK4,$TC4) -> 0
A5: ./bsp-0030 | G5: 0 | I5: 150 | J5: 0 | L5: 0.95 | P5: SATISFIABLE | Q5: 0.95 | R5: 0 | AQ5: 0 | AS5: 1611 | AT5: 0 | AV5: 24.47 | AZ5: SATISFIABLE | BA5: 24.47 | BB5: 0 | BD5: 5206 | BE5: 30 | BF5: 0.465 | BG5: 0 | BH5: 219778 | BI5: 0 | BJ5: 0.465 | BK5: 39 | BL5: 0 | BM5: 1 | BN5: 0.6 | BO5: 0 | BP5: 249100 | BQ5: 0 | BR5: SATISFIABLE | BS5: 0.6 | BT5: 0 | BU5: 1922 | BV5: 1489 | BW5: 28 | BX5: 0.047 | BY5: 0 | BZ5: 1110 | CA5: 0 | CB5: 0.047 | CC5: 0 | CD5: 0 | CE5: 1 | CF5: 0.07 | CG5: 0 | CH5: 29478 | CI5: 0 | CJ5: SATISFIABLE | CK5: 0.07 | CL5: 0 | CM5: 989 | CN5: 6598 | CO5: 7181 | CP5: 0.588 | CQ5: 6262 | CR5: 219846 | CS5: 0 | CT5: 0.428 | CU5: 38 | CV5: 0 | CW5: 1 | CX5: 0.62 | CY5: 39 | CZ5: 250550 | DA5: 0.16 | DB5: SATISFIABLE | DC5: 0.62 | DD5: 0 | DE5: 1926 | DF5: 2881 | DG5: 19 | DH5: 0.036 | DI5: 3 | DJ5: 3948 | DK5: 0 | DL5: 0.036 | DM5: 0 | DN5: 0 | DO5: 1 | DP5: 0.06 | DQ5: 0 | DR5: 30898 | DS5: 0 | DT5: SATISFIABLE | DU5: 0.06 | DV5: 0 | DW5: 1917 | DX5: 6598 | DY5: 3024 | DZ5: 0.59 | EA5: 2539 | EB5: 303726 | EC5: 0 | ED5: 0.47 | EE5: 47 | EF5: 0 | EG5: 1 | EH5: 0.63 | EI5: 20 | EJ5: 250550 | EK5: 0.12 | EL5: SATISFIABLE | EM5: 0.63 | EN5: 0 | EO5: 29886 | EP5: 2881 | EQ5: 20 | ER5: 0.083 | ES5: 2 | ET5: 87648 | EU5: 0 | EV5: 0.083 | EW5: 10 | EX5: 0 | EY5: 1 | EZ5: 0.17 | FA5: 0 | FB5: 30898 | FC5: 0 | FD5: SATISFIABLE | FE5: 0.17 | FF5: 0 | FG5: 29817 | FH5: 3810 | FI5: 4708 | FJ5: 0.482 | FK5: 4020 | FL5: 219656 | FM5: 0 | FN5: 0.382 | FO5: 36 | FP5: 0 | FQ5: 1 | FR5: 0.51 | FS5: 29 | FT5: 219686 | FU5: 0.1 | FV5: SATISFIABLE | FW5: 0.51 | FX5: 0 | FY5: 1890 | FZ5: 93 | GA5: 10 | GB5: 0.001 | GC5: 0 | GD5: 2 | GE5: 0 | GF5: 0.001 | GG5: 0 | GH5: 0 | GI5: 1 | GJ5: 0.04 | GK5: 0 | GL5: 94 | GM5: 0 | GN5: SATISFIABLE | GO5: 0.04 | GP5: 0 | GQ5: 31 | GR5: 3812 | GS5: 30 | GT5: 0.389 | GU5: 0 | GV5: 219656 | GW5: 0 | GX5: 0.389 | GY5: 36 | GZ5: 0 | HA5: 1 | HB5: 0.42 | HC5: 0 | HD5: 219688 | HE5: 0 | HF5: SATISFIABLE | HG5: 0.42 | HH5: 0 | HI5: 1890 | HJ5: 34560 | HK5: 8452 | HL5: 7.865 | HM5: 7405 | HN5: 303666 | HO5: 0 | HP5: 0.535 | HQ5: 68 | HR5: 0 | HS5: 1 | HT5: 7.92 | HU5: 45 | HV5: 250552 | HW5: 7.33 | HX5: SATISFIABLE | HY5: 7.92 | HZ5: 0 | IA5: 29856 | IB5: 95 | IC5: 28 | ID5: 0.001 | IE5: 0 | IF5: 2 | IG5: 0 | IH5: 0.001 | II5: 0 | IJ5: 0 | IK5: 1 | IL5: 0.03 | IM5: 0 | IN5: 96 | IO5: 0 | IP5: SATISFIABLE | IQ5: 0.03 | IR5: 0 | IS5: 31 | IT5: 3812 | IU5: 4708 | IV5: 0.538 | IW5: 4020 | IX5: 219656 | IY5: 0 | IZ5: 0.388 | JA5: 36 | JB5: 0 | JC5: 1 | JD5: 0.57 | JE5: 29 | JF5: 219688 | JG5: 0.15 | JH5: SATISFIABLE | JI5: 0.57 | JJ5: 0 | JK5: 1890 | JL5: 95 | JM5: 10 | JN5: 0.001 | JO5: 0 | JP5: 2 | JQ5: 0 | JR5: 0.001 | JS5: 0 | JT5: 0 | JU5: 1 | JV5: 0.03 | JW5: 0 | JX5: 96 | JY5: 0 | JZ5: SATISFIABLE | KA5: 0.03 | KB5: 0 | KC5: 31 | KD5: 5206 | KE5: 30 | KF5: 0.446 | KG5: 0 | KH5: 219778 | KI5: 0 | KJ5: 0.446 | KK5: 40 | KL5: 0 | KM5: 1 | KN5: 0.49 | KO5: 0 | KP5: 249100 | KQ5: 0 | KR5: SATISFIABLE | KS5: 0.49 | KT5: 0 | KU5: 1922 | KV5: 1489 | KW5: 28 | KX5: 0.067 | KY5: 0 | KZ5: 1110 | LA5: 0 | LB5: 0.067 | LC5: 6 | LD5: 0 | LE5: 1 | LF5: 0.19 | LG5: 0 | LH5: 29478 | LI5: 0 | LJ5: SATISFIABLE | LK5: 0.19 | LL5: 0 | LM5: 989 | LN5: 6598 | LO5: 7181 | LP5: 0.586 | LQ5: 6262 | LR5: 219846 | LS5: 0 | LT5: 0.436 | LU5: 38 | LV5: 0 | LW5: 1 | LX5: 0.62 | LY5: 39 | LZ5: 250550 | MA5: 0.15 | MB5: SATISFIABLE | MC5: 0.62 | MD5: 0 | ME5: 1926 | MF5: 2881 | MG5: 19 | MH5: 0.038 | MI5: 3 | MJ5: 3948 | MK5: 0 | ML5: 0.038 | MM5: 0 | MN5: 0 | MO5: 1 | MP5: 0.07 | MQ5: 0 | MR5: 30898 | MS5: 0 | MT5: SATISFIABLE | MU5: 0.07 | MV5: 0 | MW5: 1917 | MX5: 6598 | MY5: 3024 | MZ5: 0.578 | NA5: 2539 | NB5: 303726 | NC5: 0 | ND5: 0.458 | NE5: 48 | NF5: 0 | NG5: 1 | NH5: 0.62 | NI5: 20 | NJ5: 250550 | NK5: 0.12 | NL5: SATISFIABLE | NM5: 0.62 | NN5: 0 | NO5: 29886 | NP5: 2881 | NQ5: 20 | NR5: 0.063 | NS5: 2 | NT5: 87648 | NU5: 0 | NV5: 0.063 | NW5: 0 | NX5: 0 | NY5: 1 | NZ5: 0.09 | OA5: 0 | OB5: 30898 | OC5: 0 | OD5: SATISFIABLE | OE5: 0.09 | OF5: 0 | OG5: 29817 | OH5: 3810 | OI5: 4708 | OJ5: 0.476 | OK5: 4020 | OL5: 219656 | OM5: 0 | ON5: 0.376 | OO5: 37 | OP5: 0 | OQ5: 1 | OR5: 0.51 | OS5: 29 | OT5: 219686 | OU5: 0.1 | OV5: SATISFIABLE | OW5: 0.51 | OX5: 0 | OY5: 1890 | OZ5: 93 | PA5: 10 | PB5: 0.001 | PC5: 0 | PD5: 2 | PE5: 0 | PF5: 0.001 | PG5: 0 | PH5: 0 | PI5: 1 | PJ5: 0.04 | PK5: 0 | PL5: 94 | PM5: 0 | PN5: SATISFIABLE | PO5: 0.04 | PP5: 0 | PQ5: 31 | PR5: 3813 | PS5: 30 | PT5: 0.524 | PU5: 0 | PV5: 219656 | PW5: 0 | PX5: 0.514 | PY5: 43 | PZ5: 0 | QA5: 1 | QB5: 0.64 | QC5: 0 | QD5: 219689 | QE5: 0.01 | QF5: SATISFIABLE | QG5: 0.64 | QH5: 0 | QI5: 1890 | QJ5: 34561 | QK5: 8452 | QL5: 5.696 | QM5: 7405 | QN5: 303666 | QO5: 0 | QP5: 1.286 | QQ5: 70 | QR5: 0 | QS5: 1 | QT5: 5.76 | QU5: 45 | QV5: 250553 | QW5: 4.41 | QX5: SATISFIABLE | QY5: 5.76 | QZ5: 0 | RA5: 29856 | RB5: 96 | RC5: 28 | RD5: 0.021 | RE5: 0 | RF5: 2 | RG5: 0 | RH5: 0.021 | RI5: 0 | RJ5: 0 | RK5: 1 | RL5: 0.05 | RM5: 0 | RN5: 97 | RO5: 0 | RP5: SATISFIABLE | RQ5: 0.05 | RR5: 0 | RS5: 31 | RT5: 3813 | RU5: 4708 | RV5: 0.663 | RW5: 4020 | RX5: 219656 | RY5: 0 | RZ5: 0.423 | SA5: 41 | SB5: 0 | SC5: 1 | SD5: 0.71 | SE5: 29 | SF5: 219689 | SG5: 0.24 | SH5: SATISFIABLE | SI5: 0.71 | SJ5: 0 | SK5: 1890 | SL5: 96 | SM5: 10 | SN5: 0.019 | SO5: 0 | SP5: 2 | SQ5: 0 | SR5: 0.019 | SS5: 0 | ST5: 0 | SU5: 1 | SV5: 0.05 | SW5: 0 | SX5: 97 | SY5: 0 | SZ5: SATISFIABLE | TA5: 0.05 | TB5: 0 | TC5: 31 | TD5: =MIN($B5,$T5,$AL5,$BD5,$BV5,$CN5,$DF5,$DX5,$EP5,$FH5,$FZ5,$GR5,$HJ5,$IB5,$IT5,$JL5,$KD5,$KV5,$LN5,$MF5,$MX5,$NP5,$OH5,$OZ5,$PR5,$QJ5,$RB5,$RT5,$SL5) -> 0 | TE5: =MIN($C5,$U5,$AM5,$BE5,$BW5,$CO5,$DG5,$DY5,$EQ5,$FI5,$GA5,$GS5,$HK5,$IC5,$IU5,$JM5,$KE5,$KW5,$LO5,$MG5,$MY5,$NQ5,$OI5,$PA5,$PS5,$QK5,$RC5,$RU5,$SM5) -> 0 | TF5: =MIN($D5,$V5,$AN5,$BF5,$BX5,$CP5,$DH5,$DZ5,$ER5,$FJ5,$GB5,$GT5,$HL5,$ID5,$IV5,$JN5,$KF5,$KX5,$LP5,$MH5,$MZ5,$NR5,$OJ5,$PB5,$PT5,$QL5,$RD5,$RV5,$SN5) -> 0 | TG5: =MIN($E5,$W5,$AO5,$BG5,$BY5,$CQ5,$DI5,$EA5,$ES5,$FK5,$GC5,$GU5,$HM5,$IE5,$IW5,$JO5,$KG5,$KY5,$LQ5,$MI5,$NA5,$NS5,$OK5,$PC5,$PU5,$QM5,$RE5,$RW5,$SO5) -> 0 | TH5: =MIN($F5,$X5,$AP5,$BH5,$BZ5,$CR5,$DJ5,$EB5,$ET5,$FL5,$GD5,$GV5,$HN5,$IF5,$IX5,$JP5,$KH5,$KZ5,$LR5,$MJ5,$NB5,$NT5,$OL5,$PD5,$PV5,$QN5,$RF5,$RX5,$SP5) -> 0 | TI5: =MIN($G5,$Y5,$AQ5,$BI5,$CA5,$CS5,$DK5,$EC5,$EU5,$FM5,$GE5,$GW5,$HO5,$IG5,$IY5,$JQ5,$KI5,$LA5,$LS5,$MK5,$NC5,$NU5,$OM5,$PE5,$PW5,$QO5,$RG5,$RY5,$SQ5) -> 0 | TJ5: =MIN($H5,$Z5,$AR5,$BJ5,$CB5,$CT5,$DL5,$ED5,$EV5,$FN5,$GF5,$GX5,$HP5,$IH5,$IZ5,$JR5,$KJ5,$LB5,$LT5,$ML5,$ND5,$NV5,$ON5,$PF5,$PX5,$QP5,$RH5,$RZ5,$SR5) -> 0 | TK5: =MIN($I5,$AA5,$AS5,$BK5,$CC5,$CU5,$DM5,$EE5,$EW5,$FO5,$GG5,$GY5,$HQ5,$II5,$JA5,$JS5,$KK5,$LC5,$LU5,$MM5,$NE5,$NW5,$OO5,$PG5,$PY5,$QQ5,$RI5,$SA5,$SS5) -> 0 | TL5: =MIN($J5,$AB5,$AT5,$BL5,$CD5,$CV5,$DN5,$EF5,$EX5,$FP5,$GH5,$GZ5,$HR5,$IJ5,$JB5,$JT5,$KL5,$LD5,$LV5,$MN5,$NF5,$NX5,$OP5,$PH5,$PZ5,$QR5,$RJ5,$SB5,$ST5) -> 0 | TM5: =MIN($K5,$AC5,$AU5,$BM5,$CE5,$CW5,$DO5,$EG5,$EY5,$FQ5,$GI5,$HA5,$HS5,$IK5,$JC5,$JU5,$KM5,$LE5,$LW5,$MO5,$NG5,$NY5,$OQ5,$PI5,$QA5,$QS5,$RK5,$SC5,$SU5) -> 0 | TN5: =MIN($L5,$AD5,$AV5,$BN5,$CF5,$CX5,$DP5,$EH5,$EZ5,$FR5,$GJ5,$HB5,$HT5,$IL5,$JD5,$JV5,$KN5,$LF5,$LX5,$MP5,$NH5,$NZ5,$OR5,$PJ5,$QB5,$QT5,$RL5,$SD5,$SV5) -> 0 | TO5: =MIN($M5,$AE5,$AW5,$BO5,$CG5,$CY5,$DQ5,$EI5,$FA5,$FS5,$GK5,$HC5,$HU5,$IM5,$JE5,$JW5,$KO5,$LG5,$LY5,$MQ5,$NI5,$OA5,$OS5,$PK5,$QC5,$QU5,$RM5,$SE5,$SW5) -> 0 | TP5: =MIN($N5,$AF5,$AX5,$BP5,$CH5,$CZ5,$DR5,$EJ5,$FB5,$FT5,$GL5,$HD5,$HV5,$IN5,$JF5,$JX5,$KP5,$LH5,$LZ5,$MR5,$NJ5,$OB5,$OT5,$PL5,$QD5,$QV5,$RN5,$SF5,$SX5) -> 0 | TQ5: =MIN($O5,$AG5,$AY5,$BQ5,$CI5,$DA5,$DS5,$EK5,$FC5,$FU5,$GM5,$HE5,$HW5,$IO5,$JG5,$JY5,$KQ5,$LI5,$MA5,$MS5,$NK5,$OC5,$OU5,$PM5,$QE5,$QW5,$RO5,$SG5,$SY5) -> 0 | TR5: =MIN($Q5,$AI5,$BA5,$BS5,$CK5,$DC5,$DU5,$EM5,$FE5,$FW5,$GO5,$HG5,$HY5,$IQ5,$JI5,$KA5,$KS5,$LK5,$MC5,$MU5,$NM5,$OE5,$OW5,$PO5,$QG5,$QY5,$RQ5,$SI5,$TA5) -> 0 | TS5: =MIN($R5,$AJ5,$BB5,$BT5,$CL5,$DD5,$DV5,$EN5,$FF5,$FX5,$GP5,$HH5,$HZ5,$IR5,$JJ5,$KB5,$KT5,$LL5,$MD5,$MV5,$NN5,$OF5,$OX5,$PP5,$QH5,$QZ5,$RR5,$SJ5,$TB5) -> 0 | TT5: =MIN($S5,$AK5,$BC5,$BU5,$CM5,$DE5,$DW5,$EO5,$FG5,$FY5,$GQ5,$HI5,$IA5,$IS5,$JK5,$KC5,$KU5,$LM5,$ME5,$MW5,$NO5,$OG5,$OY5,$PQ5,$QI5,$RA5,$RS5,$SK5,$TC5) -> 0 | TU5: =MEDIAN($B5,$T5,$AL5,$BD5,$BV5,$CN5,$DF5,$DX5,$EP5,$FH5,$FZ5,$GR5,$HJ5,$IB5,$IT5,$JL5,$KD5,$KV5,$LN5,$MF5,$MX5,$NP5,$OH5,$OZ5,$PR5,$QJ5,$RB5,$RT5,$SL5) -> 0 | TV5: =MEDIAN($C5,$U5,$AM5,$BE5,$BW5,$CO5,$DG5,$DY5,$EQ5,$FI5,$GA5,$GS5,$HK5,$IC5,$IU5,$JM5,$KE5,$KW5,$LO5,$MG5,$MY5,$NQ5,$OI5,$PA5,$PS5,$QK5,$RC5,$RU5,$SM5) -> 0 | TW5: =MEDIAN($D5,$V5,$AN5,$BF5,$BX5,$CP5,$DH5,$DZ5,$ER5,$FJ5,$GB5,$GT5,$HL5,$ID5,$IV5,$JN5,$KF5,$KX5,$LP5,$MH5,$MZ5,$NR5,$OJ5,$PB5,$PT5,$QL5,$RD5,$RV5,$SN5) -> 0 | TX5: =MEDIAN($E5,$W5,$AO5,$BG5,$BY5,$CQ5,$DI5,$EA5,$ES5,$FK5,$GC5,$GU5,$HM5,$IE5,$IW5,$JO5,$KG5,$KY5,$LQ5,$MI5,$NA5,$NS5,$OK5,$PC5,$PU5,$QM5,$RE5,$RW5,$SO5) -> 0 | TY5: =MEDIAN($F5,$X5,$AP5,$BH5,$BZ5,$CR5,$DJ5,$EB5,$ET5,$FL5,$GD5,$GV5,$HN5,$IF5,$IX5,$JP5,$KH5,$KZ5,$LR5,$MJ5,$NB5,$NT5,$OL5,$PD5,$PV5,$QN5,$RF5,$RX5,$SP5) -> 0 | TZ5: =MEDIAN($G5,$Y5,$AQ5,$BI5,$CA5,$CS5,$DK5,$EC5,$EU5,$FM5,$GE5,$GW5,$HO5,$IG5,$IY5,$JQ5,$KI5,$LA5,$LS5,$MK5,$NC5,$NU5,$OM5,$PE5,$PW5,$QO5,$RG5,$RY5,$SQ5) -> 0 | UA5: =MEDIAN($H5,$Z5,$AR5,$BJ5,$CB5,$CT5,$DL5,$ED5,$EV5,$FN5,$GF5,$GX5,$HP5,$IH5,$IZ5,$JR5,$KJ5,$LB5,$LT5,$ML5,$ND5,$NV5,$ON5,$PF5,$PX5,$QP5,$RH5,$RZ5,$SR5) -> 0 | UB5: =MEDIAN($I5,$AA5,$AS5,$BK5,$CC5,$CU5,$DM5,$EE5,$EW5,$FO5,$GG5,$GY5,$HQ5,$II5,$JA5,$JS5,$KK5,$LC5,$LU5,$MM5,$NE5,$NW5,$OO5,$PG5,$PY5,$QQ5,$RI5,$SA5,$SS5) -> 0 | UC5: =MEDIAN($J5,$AB5,$AT5,$BL5,$CD5,$CV5,$DN5,$EF5,$EX5,$FP5,$GH5,$GZ5,$HR5,$IJ5,$JB5,$JT5,$KL5,$LD5,$LV5,$MN5,$NF5,$NX5,$OP5,$PH5,$PZ5,$QR5,$RJ5,$SB5,$ST5) -> 0 | UD5: =MEDIAN($K5,$AC5,$AU5,$BM5,$CE5,$CW5,$DO5,$EG5,$EY5,$FQ5,$GI5,$HA5,$HS5,$IK5,$JC5,$JU5,$KM5,$LE5,$LW5,$MO5,$NG5,$NY5,$OQ5,$PI5,$QA5,$QS5,$RK5,$SC5,$SU5) -> 0 | UE5: =MEDIAN($L5,$AD5,$AV5,$BN5,$CF5,$CX5,$DP5,$EH5,$EZ5,$FR5,$GJ5,$HB5,$HT5,$IL5,$JD5,$JV5,$KN5,$LF5,$LX5,$MP5,$NH5,$NZ5,$OR5,$PJ5,$QB5,$QT5,$RL5,$SD5,$SV5) -> 0 | UF5: =MEDIAN($M5,$AE5,$AW5,$BO5,$CG5,$CY5,$DQ5,$EI5,$FA5,$FS5,$GK5,$HC5,$HU5,$IM5,$JE5,$JW5,$KO5,$LG5,$LY5,$MQ5,$NI5,$OA5,$OS5,$PK5,$QC5,$QU5,$RM5,$SE5,$SW5) -> 0 | UG5: =MEDIAN($N5,$AF5,$AX5,$BP5,$CH5,$CZ5,$DR5,$EJ5,$FB5,$FT5,$GL5,$HD5,$HV5,$IN5,$JF5,$JX5,$KP5,$LH5,$LZ5,$MR5,$NJ5,$OB5,$OT5,$PL5,$QD5,$QV5,$RN5,$SF5,$SX5) -> 0 | UH5: =MEDIAN($O5,$AG5,$AY5,$BQ5,$CI5,$DA5,$DS5,$EK5,$FC5,$FU5,$GM5,$HE5,$HW5,$IO5,$JG5,$JY5,$KQ5,$LI5,$MA5,$MS5,$NK5,$OC5,$OU5,$PM5,$QE5,$QW5,$RO5,$SG5,$SY5) -> 0 | UI5: =MEDIAN($Q5,$AI5,$BA5,$BS5,$CK5,$DC5,$DU5,$EM5,$FE5,$FW5,$GO5,$HG5,$HY5,$IQ5,$JI5,$KA5,$KS5,$LK5,$MC5,$MU5,$NM5,$OE5,$OW5,$PO5,$QG5,$QY5,$RQ5,$SI5,$TA5) -> 0 | UJ5: =MEDIAN($R5,$AJ5,$BB5,$BT5,$CL5,$DD5,$DV5,$EN5,$FF5,$FX5,$GP5,$HH5,$HZ5,$IR5,$JJ5,$KB5,$KT5,$LL5,$MD5,$MV5,$NN5,$OF5,$OX5,$PP5,$QH5,$QZ5,$RR5,$SJ5,$TB5) -> 0 | UK5: =MEDIAN($S5,$AK5,$BC5,$BU5,$CM5,$DE5,$DW5,$EO5,$FG5,$FY5,$GQ5,$HI5,$IA5,$IS5,$JK5,$KC5,$KU5,$LM5,$ME5,$MW5,$NO5,$OG5,$OY5,$PQ5,$QI5,$RA5,$RS5,$SK5,$TC5) -> 0 | UL5: =MAX($B5,$T5,$AL5,$BD5,$BV5,$CN5,$DF5,$DX5,$EP5,$FH5,$FZ5,$GR5,$HJ5,$IB5,$IT5,$JL5,$KD5,$KV5,$LN5,$MF5,$MX5,$NP5,$OH5,$OZ5,$PR5,$QJ5,$RB5,$RT5,$SL5) -> 0 | UM5: =MAX($C5,$U5,$AM5,$BE5,$BW5,$CO5,$DG5,$DY5,$EQ5,$FI5,$GA5,$GS5,$HK5,$IC5,$IU5,$JM5,$KE5,$KW5,$LO5,$MG5,$MY5,$NQ5,$OI5,$PA5,$PS5,$QK5,$RC5,$RU5,$SM5) -> 0 | UN5: =MAX($D5,$V5,$AN5,$BF5,$BX5,$CP5,$DH5,$DZ5,$ER5,$FJ5,$GB5,$GT5,$HL5,$ID5,$IV5,$JN5,$KF5,$KX5,$LP5,$MH5,$MZ5,$NR5,$OJ5,$PB5,$PT5,$QL5,$RD5,$RV5,$SN5) -> 0 | UO5: =MAX($E5,$W5,$AO5,$BG5,$BY5,$CQ5,$DI5,$EA5,$ES5,$FK5,$GC5,$GU5,$HM5,$IE5,$IW5,$JO5,$KG5,$KY5,$LQ5,$MI5,$NA5,$NS5,$OK5,$PC5,$PU5,$QM5,$RE5,$RW5,$SO5) -> 0 | UP5: =MAX($F5,$X5,$AP5,$BH5,$BZ5,$CR5,$DJ5,$EB5,$ET5,$FL5,$GD5,$GV5,$HN5,$IF5,$IX5,$JP5,$KH5,$KZ5,$LR5,$MJ5,$NB5,$NT5,$OL5,$PD5,$PV5,$QN5,$RF5,$RX5,$SP5) -> 0 | UQ5: =MAX($G5,$Y5,$AQ5,$BI5,$CA5,$CS5,$DK5,$EC5,$EU5,$FM5,$GE5,$GW5,$HO5,$IG5,$IY5,$JQ5,$KI5,$LA5,$LS5,$MK5,$NC5,$NU5,$OM5,$PE5,$PW5,$QO5,$RG5,$RY5,$SQ5) -> 0 | UR5: =MAX($H5,$Z5,$AR5,$BJ5,$CB5,$CT5,$DL5,$ED5,$EV5,$FN5,$GF5,$GX5,$HP5,$IH5,$IZ5,$JR5,$KJ5,$LB5,$LT5,$ML5,$ND5,$NV5,$ON5,$PF5,$PX5,$QP5,$RH5,$RZ5,$SR5) -> 0 | US5: =MAX($I5,$AA5,$AS5,$BK5,$CC5,$CU5,$DM5,$EE5,$EW5,$FO5,$GG5,$GY5,$HQ5,$II5,$JA5,$JS5,$KK5,$LC5,$LU5,$MM5,$NE5,$NW5,$OO5,$PG5,$PY5,$QQ5,$RI5,$SA5,$SS5) -> 0 | UT5: =MAX($J5,$AB5,$AT5,$BL5,$CD5,$CV5,$DN5,$EF5,$EX5,$FP5,$GH5,$GZ5,$HR5,$IJ5,$JB5,$JT5,$KL5,$LD5,$LV5,$MN5,$NF5,$NX5,$OP5,$PH5,$PZ5,$QR5,$RJ5,$SB5,$ST5) -> 0 | UU5: =MAX($K5,$AC5,$AU5,$BM5,$CE5,$CW5,$DO5,$EG5,$EY5,$FQ5,$GI5,$HA5,$HS5,$IK5,$JC5,$JU5,$KM5,$LE5,$LW5,$MO5,$NG5,$NY5,$OQ5,$PI5,$QA5,$QS5,$RK5,$SC5,$SU5) -> 0 | UV5: =MAX($L5,$AD5,$AV5,$BN5,$CF5,$CX5,$DP5,$EH5,$EZ5,$FR5,$GJ5,$HB5,$HT5,$IL5,$JD5,$JV5,$KN5,$LF5,$LX5,$MP5,$NH5,$NZ5,$OR5,$PJ5,$QB5,$QT5,$RL5,$SD5,$SV5) -> 0 | UW5: =MAX($M5,$AE5,$AW5,$BO5,$CG5,$CY5,$DQ5,$EI5,$FA5,$FS5,$GK5,$HC5,$HU5,$IM5,$JE5,$JW5,$KO5,$LG5,$LY5,$MQ5,$NI5,$OA5,$OS5,$PK5,$QC5,$QU5,$RM5,$SE5,$SW5) -> 0 | UX5: =MAX($N5,$AF5,$AX5,$BP5,$CH5,$CZ5,$DR5,$EJ5,$FB5,$FT5,$GL5,$HD5,$HV5,$IN5,$JF5,$JX5,$KP5,$LH5,$LZ5,$MR5,$NJ5,$OB5,$OT5,$PL5,$QD5,$QV5,$RN5,$SF5,$SX5) -> 0 | UY5: =MAX($O5,$AG5,$AY5,$BQ5,$CI5,$DA5,$DS5,$EK5,$FC5,$FU5,$GM5,$HE5,$HW5,$IO5,$JG5,$JY5,$KQ5,$LI5,$MA5,$MS5,$NK5,$OC5,$OU5,$PM5,$QE5,$QW5,$RO5,$SG5,$SY5) -> 0 | UZ5: =MAX($Q5,$AI5,$BA5,$BS5,$CK5,$DC5,$DU5,$EM5,$FE5,$FW5,$GO5,$HG5,$HY5,$IQ5,$JI5,$KA5,$KS5,$LK5,$MC5,$MU5,$NM5,$OE5,$OW5,$PO5,$QG5,$QY5,$RQ5,$SI5,$TA5) -> 0 | VA5: =MAX($R5,$AJ5,$BB5,$BT5,$CL5,$DD5,$DV5,$EN5,$FF5,$FX5,$GP5,$HH5,$HZ5,$IR5,$JJ5,$KB5,$KT5,$LL5,$MD5,$MV5,$NN5,$OF5,$OX5,$PP5,$QH5,$QZ5,$RR5,$SJ5,$TB5) -> 0 | VB5: =MAX($S5,$AK5,$BC5,$BU5,$CM5,$DE5,$DW5,$EO5,$FG5,$FY5,$GQ5,$HI5,$IA5,$IS5,$JK5,$KC5,$KU5,$LM5,$ME5,$MW5,$NO5,$OG5,$OY5,$PQ5,$QI5,$RA5,$RS5,$SK5,$TC5) -> 0
