Workbook

Sheet Instances
B1: clingo-native-1.0/ga | T1: clingo-native-1.0/ga_weak | AL1: clingo-native-1.0/gc | BD1: clingo-native-1.0/gc_noheur | BV1: clingo-native-1.0/la | CN1: clingo-native-1.0/la_aux | DF1: clingo-native-1.0/la_co | DX1: clingo-native-1.0/lc | EP1: clingo-prolog-1.0/ga | FH1: clingo-prolog-1.0/ga_weak | FZ1: clingo-prolog-1.0/gc | GR1: clingo-prolog-1.0/gc_noheur | HJ1: clingo-prolog-1.0/la | IB1: clingo-prolog-1.0/la_aux | IT1: clingo-prolog-1.0/la_co | JL1: clingo-prolog-1.0/lc | KD1: min | KU1: median | LL1: max
B2: atoms | C2: choices | D2: clingo_total | E2: conflicts | F2: constraints | G2: error | H2: grounding | I2: mem | J2: memout | K2: models | L2: par2 | M2: restarts | N2: rules | O2: solving | P2: status | Q2: time | R2: timeout | S2: variables | T2: atoms | U2: choices | V2: clingo_total | W2: conflicts | X2: constraints | Y2: error | Z2: grounding | AA2: mem | AB2: memout | AC2: models | AD2: par2 | AE2: restarts | AF2: rules | AG2: solving | AH2: status | AI2: time | AJ2: timeout | AK2: variables | AL2: atoms | AM2: choices | AN2: clingo_total | AO2: conflicts | AP2: constraints | AQ2: error | AR2: grounding | AS2: mem | AT2: memout | AU2: models | AV2: par2 | AW2: restarts | AX2: rules | AY2: solving | AZ2: status | BA2: time | BB2: timeout | BC2: variables | BD2: atoms | BE2: choices | BF2: clingo_total | BG2: conflicts | BH2: constraints | BI2: error | BJ2: grounding | BK2: mem | BL2: memout | BM2: models | BN2: par2 | BO2: restarts | BP2: rules | BQ2: solving | BR2: status | BS2: time | BT2: timeout | BU2: variables | BV2: atoms | BW2: choices | BX2: clingo_total | BY2: conflicts | BZ2: constraints | CA2: error | CB2: grounding | CC2: mem | CD2: memout | CE2: models | CF2: par2 | CG2: restarts | CH2: rules | CI2: solving | CJ2: status | CK2: time | CL2: timeout | CM2: variables | CN2: atoms | CO2: choices | CP2: clingo_total | CQ2: conflicts | CR2: constraints | CS2: error | CT2: grounding | CU2: mem | CV2: memout | CW2: models | CX2: par2 | CY2: restarts | CZ2: rules | DA2: solving | DB2: status | DC2: time | DD2: timeout | DE2: variables | DF2: atoms | DG2: choices | DH2: clingo_total | DI2: conflicts | DJ2: constraints | DK2: error | DL2: grounding | DM2: mem | DN2: memout | DO2: models | DP2: par2 | DQ2: restarts | DR2: rules | DS2: solving | DT2: status | DU2: time | DV2: timeout | DW2: variables | DX2: atoms | DY2: choices | DZ2: clingo_total | EA2: conflicts | EB2: constraints | EC2: error | ED2: grounding | EE2: mem | EF2: memout | EG2: models | EH2: par2 | EI2: restarts | EJ2: rules | EK2: solving | EL2: status | EM2: time | EN2: timeout | EO2: variables | EP2: atoms | EQ2: choices | ER2: clingo_total | ES2: conflicts | ET2: constraints | EU2: error | EV2: grounding | EW2: mem | EX2: memout | EY2: models | EZ2: par2 | FA2: restarts | FB2: rules | FC2: solving | FD2: status | FE2: time | FF2: timeout | FG2: variables | FH2: atoms | FI2: choices | FJ2: clingo_total | FK2: conflicts | FL2: constraints | FM2: error | FN2: grounding | FO2: mem | FP2: memout | FQ2: models | FR2: par2 | FS2: restarts | FT2: rules | FU2: solving | FV2: status | FW2: time | FX2: timeout | FY2: variables | FZ2: atoms | GA2: choices | GB2: clingo_total | GC2: conflicts | GD2: constraints | GE2: error | GF2: grounding | GG2: mem | GH2: memout | GI2: models | GJ2: par2 | GK2: restarts | GL2: rules | GM2: solving | GN2: status | GO2: time | GP2: timeout | GQ2: variables | GR2: atoms | GS2: choices | GT2: clingo_total | GU2: conflicts | GV2: constraints | GW2: error | GX2: grounding | GY2: mem | GZ2: memout | HA2: models | HB2: par2 | HC2: restarts | HD2: rules | HE2: solving | HF2: status | HG2: time | HH2: timeout | HI2: variables | HJ2: atoms | HK2: choices | HL2: clingo_total | HM2: conflicts | HN2: constraints | HO2: error | HP2: grounding | HQ2: mem | HR2: memout | HS2: models | HT2: par2 | HU2: restarts | HV2: rules | HW2: solving | HX2: status | HY2: time | HZ2: timeout | IA2: variables | IB2: atoms | IC2: choices | ID2: clingo_total | IE2: conflicts | IF2: constraints | IG2: error | IH2: grounding | II2: mem | IJ2: memout | IK2: models | IL2: par2 | IM2: restarts | IN2: rules | IO2: solving | IP2: status | IQ2: time | IR2: timeout | IS2: variables | IT2: atoms | IU2: choices | IV2: clingo_total | IW2: conflicts | IX2: constraints | IY2: error | IZ2: grounding | JA2: mem | JB2: memout | JC2: models | JD2: par2 | JE2: restarts | JF2: rules | JG2: solving | JH2: status | JI2: time | JJ2: timeout | JK2: variables | JL2: atoms | JM2: choices | JN2: clingo_total | JO2: conflicts | JP2: constraints | JQ2: error | JR2: grounding | JS2: mem | JT2: memout | JU2: models | JV2: par2 | JW2: restarts | JX2: rules | JY2: solving | JZ2: status | KA2: time | KB2: timeout | KC2: variables | KD2: atoms | KE2: choices | KF2: clingo_total | KG2: conflicts | KH2: constraints | KI2: error | KJ2: grounding | KK2: mem | KL2: memout | KM2: models | KN2: par2 | KO2: restarts | KP2: rules | KQ2: solving | KR2: time | KS2: timeout | KT2: variables | KU2: atoms | KV2: choices | KW2: clingo_total | KX2: conflicts | KY2: constraints | KZ2: error | LA2: grounding | LB2: mem | LC2: memout | LD2: models | LE2: par2 | LF2: restarts | LG2: rules | LH2: solving | LI2: time | LJ2: timeout | LK2: variables | LL2: atoms | LM2: choices | LN2: clingo_total | LO2: conflicts | LP2: constraints | LQ2: error | LR2: grounding | LS2: mem | LT2: memout | LU2: models | LV2: par2 | LW2: restarts | LX2: rules | LY2: solving | LZ2: time | MA2: timeout | MB2: variables
A3: ./bsp-0003 | B3: 76 | C3: 3 | D3: 0.001 | E3: 0 | F3: 170 | G3: 0 | H3: 0.001 | I3: 0 | J3: 0 | K3: 1 | L3: 0.03 | M3: 0 | N3: 178 | O3: 0 | P3: SATISFIABLE | Q3: 0.03 | R3: 0 | S3: 48 | T3: 91 | U3: 4 | V3: 0.001 | W3: 2 | X3: 220 | Y3: 0 | Z3: 0.001 | AA3: 0 | AB3: 0 | AC3: 1 | AD3: 0.03 | AE3: 0 | AF3: 203 | AG3: 0 | AH3: SATISFIABLE | AI3: 0.03 | AJ3: 0 | AK3: 64 | AL3: 91 | AM3: 4 | AN3: 0.001 | AO3: 2 | AP3: 346 | AQ3: 0 | AR3: 0.001 | AS3: 0 | AT3: 0 | AU3: 1 | AV3: 0.03 | AW3: 0 | AX3: 203 | AY3: 0 | AZ3: SATISFIABLE | BA3: 0.03 | BB3: 0 | BC3: 106 | BD3: 57 | BE3: 4 | BF3: 0.001 | BG3: 2 | BH3: 138 | BI3: 0 | BJ3: 0.001 | BK3: 0 | BL3: 0 | BM3: 1 | BN3: 0.03 | BO3: 0 | BP3: 107 | BQ3: 0 | BR3: SATISFIABLE | BS3: 0.03 | BT3: 0 | BU3: 37 | BV3: 59 | BW3: 3 | BX3: 0.001 | BY3: 0 | BZ3: 138 | CA3: 0 | CB3: 0.001 | CC3: 0 | CD3: 0 | CE3: 1 | CF3: 0.03 | CG3: 0 | CH3: 109 | CI3: 0 | CJ3: SATISFIABLE | CK3: 0.03 | CL3: 0 | CM3: 37 | CN3: 135 | CO3: 4 | CP3: 0.002 | CQ3: 2 | CR3: 340 | CS3: 0 | CT3: 0.002 | CU3: 0 | CV3: 0 | CW3: 1 | CX3: 0.03 | CY3: 0 | CZ3: 205 | DA3: 0 | DB3: SATISFIABLE | DC3: 0.03 | DD3: 0 | DE3: 103 | DF3: 14 | DG3: 1 | DH3: 0.001 | DI3: 0 | DJ3: 6 | DK3: 0 | DL3: 0.001 | DM3: 0 | DN3: 0 | DO3: 1 | DP3: 0.03 | DQ3: 0 | DR3: 17 | DS3: 0 | DT3: SATISFIABLE | DU3: 0.03 | DV3: 0 | DW3: 5 | DX3: 59 | DY3: 4 | DZ3: 0.001 | EA3: 2 | EB3: 138 | EC3: 0 | ED3: 0.001 | EE3: 0 | EF3: 0 | EG3: 1 | EH3: 0.03 | EI3: 0 | EJ3: 109 | EK3: 0 | EL3: SATISFIABLE | EM3: 0.03 | EN3: 0 | EO3: 37 | EP3: 76 | EQ3: 3 | ER3: 0.001 | ES3: 0 | ET3: 170 | EU3: 0 | EV3: 0.001 | EW3: 0 | EX3: 0 | EY3: 1 | EZ3: 0.03 | FA3: 0 | FB3: 178 | FC3: 0 | FD3: SATISFIABLE | FE3: 0.03 | FF3: 0 | FG3: 48 | FH3: 91 | FI3: 4 | FJ3: 0.001 | FK3: 2 | FL3: 220 | FM3: 0 | FN3: 0.001 | FO3: 0 | FP3: 0 | FQ3: 1 | FR3: 0.03 | FS3: 0 | FT3: 203 | FU3: 0 | FV3: SATISFIABLE | FW3: 0.03 | FX3: 0 | FY3: 64 | FZ3: 91 | GA3: 4 | GB3: 0.001 | GC3: 2 | GD3: 346 | GE3: 0 | GF3: 0.001 | GG3: 0 | GH3: 0 | GI3: 1 | GJ3: 0.03 | GK3: 0 | GL3: 203 | GM3: 0 | GN3: SATISFIABLE | GO3: 0.03 | GP3: 0 | GQ3: 106 | GR3: 57 | GS3: 4 | GT3: 0.001 | GU3: 2 | GV3: 138 | GW3: 0 | GX3: 0.001 | GY3: 0 | GZ3: 0 | HA3: 1 | HB3: 0.04 | HC3: 0 | HD3: 107 | HE3: 0 | HF3: SATISFIABLE | HG3: 0.04 | HH3: 0 | HI3: 37 | HJ3: 60 | HK3: 3 | HL3: 0.028 | HM3: 0 | HN3: 138 | HO3: 0 | HP3: 0.028 | HQ3: 0 | HR3: 0 | HS3: 1 | HT3: 0.05 | HU3: 0 | HV3: 110 | HW3: 0 | HX3: SATISFIABLE | HY3: 0.05 | HZ3: 0 | IA3: 37 | IB3: 136 | IC3: 4 | ID3: 0.029 | IE3: 2 | IF3: 340 | IG3: 0 | IH3: 0.029 | II3: 0 | IJ3: 0 | IK3: 1 | IL3: 0.06 | IM3: 0 | IN3: 206 | IO3: 0 | IP3: SATISFIABLE | IQ3: 0.06 | IR3: 0 | IS3: 103 | IT3: 15 | IU3: 1 | IV3: 0.027 | IW3: 0 | IX3: 6 | IY3: 0 | IZ3: 0.027 | JA3: 0 | JB3: 0 | JC3: 1 | JD3: 0.05 | JE3: 0 | JF3: 18 | JG3: 0 | JH3: SATISFIABLE | JI3: 0.05 | JJ3: 0 | JK3: 5 | JL3: 60 | JM3: 4 | JN3: 0.027 | JO3: 2 | JP3: 138 | JQ3: 0 | JR3: 0.027 | JS3: 0 | JT3: 0 | JU3: 1 | JV3: 0.05 | JW3: 0 | JX3: 110 | JY3: 0 | JZ3: SATISFIABLE | KA3: 0.05 | KB3: 0 | KC3: 37 | KD3: =MIN($B3,$T3,$AL3,$BD3,$BV3,$CN3,$DF3,$DX3,$EP3,$FH3,$FZ3,$GR3,$HJ3,$IB3,$IT3,$JL3) -> 0 | KE3: =MIN($C3,$U3,$AM3,$BE3,$BW3,$CO3,$DG3,$DY3,$EQ3,$FI3,$GA3,$GS3,$HK3,$IC3,$IU3,$JM3) -> 0 | KF3: =MIN($D3,$V3,$AN3,$BF3,$BX3,$CP3,$DH3,$DZ3,$ER3,$FJ3,$GB3,$GT3,$HL3,$ID3,$IV3,$JN3) -> 0 | KG3: =MIN($E3,$W3,$AO3,$BG3,$BY3,$CQ3,$DI3,$EA3,$ES3,$FK3,$GC3,$GU3,$HM3,$IE3,$IW3,$JO3) -> 0 | KH3: =MIN($F3,$X3,$AP3,$BH3,$BZ3,$CR3,$DJ3,$EB3,$ET3,$FL3,$GD3,$GV3,$HN3,$IF3,$IX3,$JP3) -> 0 | KI3: =MIN($G3,$Y3,$AQ3,$BI3,$CA3,$CS3,$DK3,$EC3,$EU3,$FM3,$GE3,$GW3,$HO3,$IG3,$IY3,$JQ3) -> 0 | KJ3: =MIN($H3,$Z3,$AR3,$BJ3,$CB3,$CT3,$DL3,$ED3,$EV3,$FN3,$GF3,$GX3,$HP3,$IH3,$IZ3,$JR3) -> 0 | KK3: =MIN($I3,$AA3,$AS3,$BK3,$CC3,$CU3,$DM3,$EE3,$EW3,$FO3,$GG3,$GY3,$HQ3,$II3,$JA3,$JS3) -> 0 | KL3: =MIN($J3,$AB3,$AT3,$BL3,$CD3,$CV3,$DN3,$EF3,$EX3,$FP3,$GH3,$GZ3,$HR3,$IJ3,$JB3,$JT3) -> 0 | KM3: =MIN($K3,$AC3,$AU3,$BM3,$CE3,$CW3,$DO3,$EG3,$EY3,$FQ3,$GI3,$HA3,$HS3,$IK3,$JC3,$JU3) -> 0 | KN3: =MIN($L3,$AD3,$AV3,$BN3,$CF3,$CX3,$DP3,$EH3,$EZ3,$FR3,$GJ3,$HB3,$HT3,$IL3,$JD3,$JV3) -> 0 | KO3: =MIN($M3,$AE3,$AW3,$BO3,$CG3,$CY3,$DQ3,$EI3,$FA3,$FS3,$GK3,$HC3,$HU3,$IM3,$JE3,$JW3) -> 0 | KP3: =MIN($N3,$AF3,$AX3,$BP3,$CH3,$CZ3,$DR3,$EJ3,$FB3,$FT3,$GL3,$HD3,$HV3,$IN3,$JF3,$JX3) -> 0 | KQ3: =MIN($O3,$AG3,$AY3,$BQ3,$CI3,$DA3,$DS3,$EK3,$FC3,$FU3,$GM3,$HE3,$HW3,$IO3,$JG3,$JY3) -> 0 | KR3: =MIN($Q3,$AI3,$BA3,$BS3,$CK3,$DC3,$DU3,$EM3,$FE3,$FW3,$GO3,$HG3,$HY3,$IQ3,$JI3,$KA3) -> 0 | KS3: =MIN($R3,$AJ3,$BB3,$BT3,$CL3,$DD3,$DV3,$EN3,$FF3,$FX3,$GP3,$HH3,$HZ3,$IR3,$JJ3,$KB3) -> 0 | KT3: =MIN($S3,$AK3,$BC3,$BU3,$CM3,$DE3,$DW3,$EO3,$FG3,$FY3,$GQ3,$HI3,$IA3,$IS3,$JK3,$KC3) -> 0 | KU3: =MEDIAN($B3,$T3,$AL3,$BD3,$BV3,$CN3,$DF3,$DX3,$EP3,$FH3,$FZ3,$GR3,$HJ3,$IB3,$IT3,$JL3) -> 0 | KV3: =MEDIAN($C3,$U3,$AM3,$BE3,$BW3,$CO3,$DG3,$DY3,$EQ3,$FI3,$GA3,$GS3,$HK3,$IC3,$IU3,$JM3) -> 0 | KW3: =MEDIAN($D3,$V3,$AN3,$BF3,$BX3,$CP3,$DH3,$DZ3,$ER3,$FJ3,$GB3,$GT3,$HL3,$ID3,$IV3,$JN3) -> 0 | KX3: =MEDIAN($E3,$W3,$AO3,$BG3,$BY3,$CQ3,$DI3,$EA3,$ES3,$FK3,$GC3,$GU3,$HM3,$IE3,$IW3,$JO3) -> 0 | KY3: =MEDIAN($F3,$X3,$AP3,$BH3,$BZ3,$CR3,$DJ3,$EB3,$ET3,$FL3,$GD3,$GV3,$HN3,$IF3,$IX3,$JP3) -> 0 | KZ3: =MEDIAN($G3,$Y3,$AQ3,$BI3,$CA3,$CS3,$DK3,$EC3,$EU3,$FM3,$GE3,$GW3,$HO3,$IG3,$IY3,$JQ3) -> 0 | LA3: =MEDIAN($H3,$Z3,$AR3,$BJ3,$CB3,$CT3,$DL3,$ED3,$EV3,$FN3,$GF3,$GX3,$HP3,$IH3,$IZ3,$JR3) -> 0 | LB3: =MEDIAN($I3,$AA3,$AS3,$BK3,$CC3,$CU3,$DM3,$EE3,$EW3,$FO3,$GG3,$GY3,$HQ3,$II3,$JA3,$JS3) -> 0 | LC3: =MEDIAN($J3,$AB3,$AT3,$BL3,$CD3,$CV3,$DN3,$EF3,$EX3,$FP3,$GH3,$GZ3,$HR3,$IJ3,$JB3,$JT3) -> 0 | LD3: =MEDIAN($K3,$AC3,$AU3,$BM3,$CE3,$CW3,$DO3,$EG3,$EY3,$FQ3,$GI3,$HA3,$HS3,$IK3,$JC3,$JU3) -> 0 | LE3: =MEDIAN($L3,$AD3,$AV3,$BN3,$CF3,$CX3,$DP3,$EH3,$EZ3,$FR3,$GJ3,$HB3,$HT3,$IL3,$JD3,$JV3) -> 0 | LF3: =MEDIAN($M3,$AE3,$AW3,$BO3,$CG3,$CY3,$DQ3,$EI3,$FA3,$FS3,$GK3,$HC3,$HU3,$IM3,$JE3,$JW3) -> 0 | LG3: =MEDIAN($N3,$AF3,$AX3,$BP3,$CH3,$CZ3,$DR3,$EJ3,$FB3,$FT3,$GL3,$HD3,$HV3,$IN3,$JF3,$JX3) -> 0 | LH3: =MEDIAN($O3,$AG3,$AY3,$BQ3,$CI3,$DA3,$DS3,$EK3,$FC3,$FU3,$GM3,$HE3,$HW3,$IO3,$JG3,$JY3) -> 0 | LI3: =MEDIAN($Q3,$AI3,$BA3,$BS3,$CK3,$DC3,$DU3,$EM3,$FE3,$FW3,$GO3,$HG3,$HY3,$IQ3,$JI3,$KA3) -> 0 | LJ3: =MEDIAN($R3,$AJ3,$BB3,$BT3,$CL3,$DD3,$DV3,$EN3,$FF3,$FX3,$GP3,$HH3,$HZ3,$IR3,$JJ3,$KB3) -> 0 | LK3: =MEDIAN($S3,$AK3,$BC3,$BU3,$CM3,$DE3,$DW3,$EO3,$FG3,$FY3,$GQ3,$HI3,$IA3,$IS3,$JK3,$KC3) -> 0 | LL3: =MAX($B3,$T3,$AL3,$BD3,$BV3,$CN3,$DF3,$DX3,$EP3,$FH3,$FZ3,$GR3,$HJ3,$IB3,$IT3,$JL3) -> 0 | LM3: =MAX($C3,$U3,$AM3,$BE3,$BW3,$CO3,$DG3,$DY3,$EQ3,$FI3,$GA3,$GS3,$HK3,$IC3,$IU3,$JM3) -> 0 | LN3: =MAX($D3,$V3,$AN3,$BF3,$BX3,$CP3,$DH3,$DZ3,$ER3,$FJ3,$GB3,$GT3,$HL3,$ID3,$IV3,$JN3) -> 0 | LO3: =MAX($E3,$W3,$AO3,$BG3,$BY3,$CQ3,$DI3,$EA3,$ES3,$FK3,$GC3,$GU3,$HM3,$IE3,$IW3,$JO3) -> 0 | LP3: =MAX($F3,$X3,$AP3,$BH3,$BZ3,$CR3,$DJ3,$EB3,$ET3,$FL3,$GD3,$GV3,$HN3,$IF3,$IX3,$JP3) -> 0 | LQ3: =MAX($G3,$Y3,$AQ3,$BI3,$CA3,$CS3,$DK3,$EC3,$EU3,$FM3,$GE3,$GW3,$HO3,$IG3,$IY3,$JQ3) -> 0 | LR3: =MAX($H3,$Z3,$AR3,$BJ3,$CB3,$CT3,$DL3,$ED3,$EV3,$FN3,$GF3,$GX3,$HP3,$IH3,$IZ3,$JR3) -> 0 | LS3: =MAX($I3,$AA3,$AS3,$BK3,$CC3,$CU3,$DM3,$EE3,$EW3,$FO3,$GG3,$GY3,$HQ3,$II3,$JA3,$JS3) -> 0 | LT3: =MAX($J3,$AB3,$AT3,$BL3,$CD3,$CV3,$DN3,$EF3,$EX3,$FP3,$GH3,$GZ3,$HR3,$IJ3,$JB3,$JT3) -> 0 | LU3: =MAX($K3,$AC3,$AU3,$BM3,$CE3,$CW3,$DO3,$EG3,$EY3,$FQ3,$GI3,$HA3,$HS3,$IK3,$JC3,$JU3) -> 0 | LV3: =MAX($L3,$AD3,$AV3,$BN3,$CF3,$CX3,$DP3,$EH3,$EZ3,$FR3,$GJ3,$HB3,$HT3,$IL3,$JD3,$JV3) -> 0 | LW3: =MAX($M3,$AE3,$AW3,$BO3,$CG3,$CY3,$DQ3,$EI3,$FA3,$FS3,$GK3,$HC3,$HU3,$IM3,$JE3,$JW3) -> 0 | LX3: =MAX($N3,$AF3,$AX3,$BP3,$CH3,$CZ3,$DR3,$EJ3,$FB3,$FT3,$GL3,$HD3,$HV3,$IN3,$JF3,$JX3) -> 0 | LY3: =MAX($O3,$AG3,$AY3,$BQ3,$CI3,$DA3,$DS3,$EK3,$FC3,$FU3,$GM3,$HE3,$HW3,$IO3,$JG3,$JY3) -> 0 | LZ3: =MAX($Q3,$AI3,$BA3,$BS3,$CK3,$DC3,$DU3,$EM3,$FE3,$FW3,$GO3,$HG3,$HY3,$IQ3,$JI3,$KA3) -> 0 | MA3: =MAX($R3,$AJ3,$BB3,$BT3,$CL3,$DD3,$DV3,$EN3,$FF3,$FX3,$GP3,$HH3,$HZ3,$IR3,$JJ3,$KB3) -> 0 | MB3: =MAX($S3,$AK3,$BC3,$BU3,$CM3,$DE3,$DW3,$EO3,$FG3,$FY3,$GQ3,$HI3,$IA3,$IS3,$JK3,$KC3) -> 0
A4: ./bsp-0004 | B4: 123 | C4: 4 | D4: 0.002 | E4: 0 | F4: 422 | G4: 0 | H4: 0.002 | I4: 0 | J4: 0 | K4: 1 | L4: 0.03 | M4: 0 | N4: 397 | O4: 0 | P4: SATISFIABLE | Q4: 0.03 | R4: 0 | S4: 96 | T4: 150 | U4: 7 | V4: 0.002 | W4: 4 | X4: 534 | Y4: 0 | Z4: 0.002 | AA4: 0 | AB4: 0 | AC4: 1 | AD4: 0.03 | AE4: 0 | AF4: 456 | AG4: 0 | AH4: SATISFIABLE | AI4: 0.03 | AJ4: 0 | AK4: 128 | AL4: 150 | AM4: 7 | AN4: 0.002 | AO4: 4 | AP4: 798 | AQ4: 0 | AR4: 0.002 | AS4: 0 | AT4: 0 | AU4: 1 | AV4: 0.03 | AW4: 0 | AX4: 456 | AY4: 0 | AZ4: SATISFIABLE | BA4: 0.03 | BB4: 0 | BC4: 216 | BD4: 92 | BE4: 7 | BF4: 0.017 | BG4: 4 | BH4: 350 | BI4: 0 | BJ4: 0.017 | BK4: 5 | BL4: 0 | BM4: 1 | BN4: 0.14 | BO4: 0 | BP4: 246 | BQ4: 0 | BR4: SATISFIABLE | BS4: 0.14 | BT4: 0 | BU4: 76 | BV4: 94 | BW4: 4 | BX4: 0.001 | BY4: 0 | BZ4: 350 | CA4: 0 | CB4: 0.001 | CC4: 0 | CD4: 0 | CE4: 1 | CF4: 0.03 | CG4: 0 | CH4: 248 | CI4: 0 | CJ4: SATISFIABLE | CK4: 0.03 | CL4: 0 | CM4: 76 | CN4: 240 | CO4: 7 | CP4: 0.002 | CQ4: 4 | CR4: 790 | CS4: 0 | CT4: 0.002 | CU4: 0 | CV4: 0 | CW4: 1 | CX4: 0.03 | CY4: 0 | CZ4: 458 | DA4: 0 | DB4: SATISFIABLE | DC4: 0.03 | DD4: 0 | DE4: 212 | DF4: 17 | DG4: 1 | DH4: 0.001 | DI4: 0 | DJ4: 10 | DK4: 0 | DL4: 0.001 | DM4: 0 | DN4: 0 | DO4: 1 | DP4: 0.03 | DQ4: 0 | DR4: 23 | DS4: 0 | DT4: SATISFIABLE | DU4: 0.03 | DV4: 0 | DW4: 7 | DX4: 94 | DY4: 7 | DZ4: 0.001 | EA4: 4 | EB4: 350 | EC4: 0 | ED4: 0.001 | EE4: 0 | EF4: 0 | EG4: 1 | EH4: 0.03 | EI4: 0 | EJ4: 248 | EK4: 0 | EL4: SATISFIABLE | EM4: 0.03 | EN4: 0 | EO4: 76 | EP4: 123 | EQ4: 4 | ER4: 0.002 | ES4: 0 | ET4: 422 | EU4: 0 | EV4: 0.002 | EW4: 0 | EX4: 0 | EY4: 1 | EZ4: 0.03 | FA4: 0 | FB4: 397 | FC4: 0 | FD4: SATISFIABLE | FE4: 0.03 | FF4: 0 | FG4: 96 | FH4: 150 | FI4: 7 | FJ4: 0.002 | FK4: 4 | FL4: 534 | FM4: 0 | FN4: 0.002 | FO4: 0 | FP4: 0 | FQ4: 1 | FR4: 0.03 | FS4: 0 | FT4: 456 | FU4: 0 | FV4: SATISFIABLE | FW4: 0.03 | FX4: 0 | FY4: 128 | FZ4: 150 | GA4: 7 | GB4: 0.003 | GC4: 4 | GD4: 798 | GE4: 0 | GF4: 0.003 | GG4: 0 | GH4: 0 | GI4: 1 | GJ4: 0.03 | GK4: 0 | GL4: 456 | GM4: 0 | GN4: SATISFIABLE | GO4: 0.03 | GP4: 0 | GQ4: 216 | GR4: 92 | GS4: 7 | GT4: 0.016 | GU4: 4 | GV4: 350 | GW4: 0 | GX4: 0.016 | GY4: 0 | GZ4: 0 | HA4: 1 | HB4: 0.09 | HC4: 0 | HD4: 246 | HE4: 0 | HF4: SATISFIABLE | HG4: 0.09 | HH4: 0 | HI4: 76 | HJ4: 95 | HK4: 4 | HL4: 0.084 | HM4: 0 | HN4: 350 | HO4: 0 | HP4: 0.084 | HQ4: 0 | HR4: 0 | HS4: 1 | HT4: 0.11 | HU4: 0 | HV4: 249 | HW4: 0 | HX4: SATISFIABLE | HY4: 0.11 | HZ4: 0 | IA4: 76 | IB4: 241 | IC4: 7 | ID4: 0.031 | IE4: 4 | IF4: 790 | IG4: 0 | IH4: 0.031 | II4: 0 | IJ4: 0 | IK4: 1 | IL4: 0.06 | IM4: 0 | IN4: 459 | IO4: 0 | IP4: SATISFIABLE | IQ4: 0.06 | IR4: 0 | IS4: 212 | IT4: 18 | IU4: 1 | IV4: 0.027 | IW4: 0 | IX4: 10 | IY4: 0 | IZ4: 0.027 | JA4: 0 | JB4: 0 | JC4: 1 | JD4: 0.05 | JE4: 0 | JF4: 24 | JG4: 0 | JH4: SATISFIABLE | JI4: 0.05 | JJ4: 0 | JK4: 7 | JL4: 95 | JM4: 7 | JN4: 0.028 | JO4: 4 | JP4: 350 | JQ4: 0 | JR4: 0.028 | JS4: 0 | JT4: 0 | JU4: 1 | JV4: 0.05 | JW4: 0 | JX4: 249 | JY4: 0 | JZ4: SATISFIABLE | KA4: 0.05 | KB4: 0 | KC4: 76 | KD4: =MIN($B4,$T4,$AL4,$BD4,$BV4,$CN4,$DF4,$DX4,$EP4,$FH4,$FZ4,$GR4,$HJ4,$IB4,$IT4,$JL4) -> 0 | KE4: =MIN($C4,$U4,$AM4,$BE4,$BW4,$CO4,$DG4,$DY4,$EQ4,$FI4,$GA4,$GS4,$HK4,$IC4,$IU4,$JM4) -> 0 | KF4: =MIN($D4,$V4,$AN4,$BF4,$BX4,$CP4,$DH4,$DZ4,$ER4,$FJ4,$GB4,$GT4,$HL4,$ID4,$IV4,$JN4) -> 0 | KG4: =MIN($E4,$W4,$AO4,$BG4,$BY4,$CQ4,$DI4,$EA4,$ES4,$FK4,$GC4,$GU4,$HM4,$IE4,$IW4,$JO4) -> 0 | KH4: =MIN($F4,$X4,$AP4,$BH4,$BZ4,$CR4,$DJ4,$EB4,$ET4,$FL4,$GD4,$GV4,$HN4,$IF4,$IX4,$JP4) -> 0 | KI4: =MIN($G4,$Y4,$AQ4,$BI4,$CA4,$CS4,$DK4,$EC4,$EU4,$FM4,$GE4,$GW4,$HO4,$IG4,$IY4,$JQ4) -> 0 | KJ4: =MIN($H4,$Z4,$AR4,$BJ4,$CB4,$CT4,$DL4,$ED4,$EV4,$FN4,$GF4,$GX4,$HP4,$IH4,$IZ4,$JR4) -> 0 | KK4: =MIN($I4,$AA4,$AS4,$BK4,$CC4,$CU4,$DM4,$EE4,$EW4,$FO4,$GG4,$GY4,$HQ4,$II4,$JA4,$JS4) -> 0 | KL4: =MIN($J4,$AB4,$AT4,$BL4,$CD4,$CV4,$DN4,$EF4,$EX4,$FP4,$GH4,$GZ4,$HR4,$IJ4,$JB4,$JT4) -> 0 | KM4: =MIN($K4,$AC4,$AU4,$BM4,$CE4,$CW4,$DO4,$EG4,$EY4,$FQ4,$GI4,$HA4,$HS4,$IK4,$JC4,$JU4) -> 0 | KN4: =MIN($L4,$AD4,$AV4,$BN4,$CF4,$CX4,$DP4,$EH4,$EZ4,$FR4,$GJ4,$HB4,$HT4,$IL4,$JD4,$JV4) -> 0 | KO4: =MIN($M4,$AE4,$AW4,$BO4,$CG4,$CY4,$DQ4,$EI4,$FA4,$FS4,$GK4,$HC4,$HU4,$IM4,$JE4,$JW4) -> 0 | KP4: =MIN($N4,$AF4,$AX4,$BP4,$CH4,$CZ4,$DR4,$EJ4,$FB4,$FT4,$GL4,$HD4,$HV4,$IN4,$JF4,$JX4) -> 0 | KQ4: =MIN($O4,$AG4,$AY4,$BQ4,$CI4,$DA4,$DS4,$EK4,$FC4,$FU4,$GM4,$HE4,$HW4,$IO4,$JG4,$JY4) -> 0 | KR4: =MIN($Q4,$AI4,$BA4,$BS4,$CK4,$DC4,$DU4,$EM4,$FE4,$FW4,$GO4,$HG4,$HY4,$IQ4,$JI4,$KA4) -> 0 | KS4: =MIN($R4,$AJ4,$BB4,$BT4,$CL4,$DD4,$DV4,$EN4,$FF4,$FX4,$GP4,$HH4,$HZ4,$IR4,$JJ4,$KB4) -> 0 | KT4: =MIN($S4,$AK4,$BC4,$BU4,$CM4,$DE4,$DW4,$EO4,$FG4,$FY4,$GQ4,$HI4,$IA4,$IS4,$JK4,$KC4) -> 0 | KU4: =MEDIAN($B4,$T4,$AL4,$BD4,$BV4,$CN4,$DF4,$DX4,$EP4,$FH4,$FZ4,$GR4,$HJ4,$IB4,$IT4,$JL4) -> 0 | KV4: =MEDIAN($C4,$U4,$AM4,$BE4,$BW4,$CO4,$DG4,$DY4,$EQ4,$FI4,$GA4,$GS4,$HK4,$IC4,$IU4,$JM4) -> 0 | KW4: =MEDIAN($D4,$V4,$AN4,$BF4,$BX4,$CP4,$DH4,$DZ4,$ER4,$FJ4,$GB4,$GT4,$HL4,$ID4,$IV4,$JN4) -> 0 | KX4: =MEDIAN($E4,$W4,$AO4,$BG4,$BY4,$CQ4,$DI4,$EA4,$ES4,$FK4,$GC4,$GU4,$HM4,$IE4,$IW4,$JO4) -> 0 | KY4: =MEDIAN($F4,$X4,$AP4,$BH4,$BZ4,$CR4,$DJ4,$EB4,$ET4,$FL4,$GD4,$GV4,$HN4,$IF4,$IX4,$JP4) -> 0 | KZ4: =MEDIAN($G4,$Y4,$AQ4,$BI4,$CA4,$CS4,$DK4,$EC4,$EU4,$FM4,$GE4,$GW4,$HO4,$IG4,$IY4,$JQ4) -> 0 | LA4: =MEDIAN($H4,$Z4,$AR4,$BJ4,$CB4,$CT4,$DL4,$ED4,$EV4,$FN4,$GF4,$GX4,$HP4,$IH4,$IZ4,$JR4) -> 0 | LB4: =MEDIAN($I4,$AA4,$AS4,$BK4,$CC4,$CU4,$DM4,$EE4,$EW4,$FO4,$GG4,$GY4,$HQ4,$II4,$JA4,$JS4) -> 0 | LC4: =MEDIAN($J4,$AB4,$AT4,$BL4,$CD4,$CV4,$DN4,$EF4,$EX4,$FP4,$GH4,$GZ4,$HR4,$IJ4,$JB4,$JT4) -> 0 | LD4: =MEDIAN($K4,$AC4,$AU4,$BM4,$CE4,$CW4,$DO4,$EG4,$EY4,$FQ4,$GI4,$HA4,$HS4,$IK4,$JC4,$JU4) -> 0 | LE4: =MEDIAN($L4,$AD4,$AV4,$BN4,$CF4,$CX4,$DP4,$EH4,$EZ4,$FR4,$GJ4,$HB4,$HT4,$IL4,$JD4,$JV4) -> 0 | LF4: =MEDIAN($M4,$AE4,$AW4,$BO4,$CG4,$CY4,$DQ4,$EI4,$FA4,$FS4,$GK4,$HC4,$HU4,$IM4,$JE4,$JW4) -> 0 | LG4: =MEDIAN($N4,$AF4,$AX4,$BP4,$CH4,$CZ4,$DR4,$EJ4,$FB4,$FT4,$GL4,$HD4,$HV4,$IN4,$JF4,$JX4) -> 0 | LH4: =MEDIAN($O4,$AG4,$AY4,$BQ4,$CI4,$DA4,$DS4,$EK4,$FC4,$FU4,$GM4,$HE4,$HW4,$IO4,$JG4,$JY4) -> 0 | LI4: =MEDIAN($Q4,$AI4,$BA4,$BS4,$CK4,$DC4,$DU4,$EM4,$FE4,$FW4,$GO4,$HG4,$HY4,$IQ4,$JI4,$KA4) -> 0 | LJ4: =MEDIAN($R4,$AJ4,$BB4,$BT4,$CL4,$DD4,$DV4,$EN4,$FF4,$FX4,$GP4,$HH4,$HZ4,$IR4,$JJ4,$KB4) -> 0 | LK4: =MEDIAN($S4,$AK4,$BC4,$BU4,$CM4,$DE4,$DW4,$EO4,$FG4,$FY4,$GQ4,$HI4,$IA4,$IS4,$JK4,$KC4) -> 0 | LL4: =MAX($B4,$T4,$AL4,$BD4,$BV4,$CN4,$DF4,$DX4,$EP4,$FH4,$FZ4,$GR4,$HJ4,$IB4,$IT4,$JL4) -> 0 | LM4: =MAX($C4,$U4,$AM4,$BE4,$BW4,$CO4,$DG4,$DY4,$EQ4,$FI4,$GA4,$GS4,$HK4,$IC4,$IU4,$JM4) -> 0 | LN4: =MAX($D4,$V4,$AN4,$BF4,$BX4,$CP4,$DH4,$DZ4,$ER4,$FJ4,$GB4,$GT4,$HL4,$ID4,$IV4,$JN4) -> 0 | LO4: =MAX($E4,$W4,$AO4,$BG4,$BY4,$CQ4,$DI4,$EA4,$ES4,$FK4,$GC4,$GU4,$HM4,$IE4,$IW4,$JO4) -> 0 | LP4: =MAX($F4,$X4,$AP4,$BH4,$BZ4,$CR4,$DJ4,$EB4,$ET4,$FL4,$GD4,$GV4,$HN4,$IF4,$IX4,$JP4) -> 0 | LQ4: =MAX($G4,$Y4,$AQ4,$BI4,$CA4,$CS4,$DK4,$EC4,$EU4,$FM4,$GE4,$GW4,$HO4,$IG4,$IY4,$JQ4) -> 0 | LR4: =MAX($H4,$Z4,$AR4,$BJ4,$CB4,$CT4,$DL4,$ED4,$EV4,$FN4,$GF4,$GX4,$HP4,$IH4,$IZ4,$JR4) -> 0 | LS4: =MAX($I4,$AA4,$AS4,$BK4,$CC4,$CU4,$DM4,$EE4,$EW4,$FO4,$GG4,$GY4,$HQ4,$II4,$JA4,$JS4) -> 0 | LT4: =MAX($J4,$AB4,$AT4,$BL4,$CD4,$CV4,$DN4,$EF4,$EX4,$FP4,$GH4,$GZ4,$HR4,$IJ4,$JB4,$JT4) -> 0 | LU4: =MAX($K4,$AC4,$AU4,$BM4,$CE4,$CW4,$DO4,$EG4,$EY4,$FQ4,$GI4,$HA4,$HS4,$IK4,$JC4,$JU4) -> 0 | LV4: =MAX($L4,$AD4,$AV4,$BN4,$CF4,$CX4,$DP4,$EH4,$EZ4,$FR4,$GJ4,$HB4,$HT4,$IL4,$JD4,$JV4) -> 0 | LW4: =MAX($M4,$AE4,$AW4,$BO4,$CG4,$CY4,$DQ4,$EI4,$FA4,$FS4,$GK4,$HC4,$HU4,$IM4,$JE4,$JW4) -> 0 | LX4: =MAX($N4,$AF4,$AX4,$BP4,$CH4,$CZ4,$DR4,$EJ4,$FB4,$FT4,$GL4,$HD4,$HV4,$IN4,$JF4,$JX4) -> 0 | LY4: =MAX($O4,$AG4,$AY4,$BQ4,$CI4,$DA4,$DS4,$EK4,$FC4,$FU4,$GM4,$HE4,$HW4,$IO4,$JG4,$JY4) -> 0 | LZ4: =MAX($Q4,$AI4,$BA4,$BS4,$CK4,$DC4,$DU4,$EM4,$FE4,$FW4,$GO4,$HG4,$HY4,$IQ4,$JI4,$KA4) -> 0 | MA4: =MAX($R4,$AJ4,$BB4,$BT4,$CL4,$DD4,$DV4,$EN4,$FF4,$FX4,$GP4,$HH4,$HZ4,$IR4,$JJ4,$KB4) -> 0 | MB4: =MAX($S4,$AK4,$BC4,$BU4,$CM4,$DE4,$DW4,$EO4,$FG4,$FY4,$GQ4,$HI4,$IA4,$IS4,$JK4,$KC4) -> 0
A5: ./bsp-0005 | B5: 181 | C5: 5 | D5: 0.002 | E5: 0 | F5: 914 | G5: 0 | H5: 0.002 | I5: 0 | J5: 0 | K5: 1 | L5: 0.03 | M5: 0 | N5: 803 | O5: 0 | P5: SATISFIABLE | Q5: 0.03 | R5: 0 | S5: 168 | T5: 223 | U5: 12 | V5: 0.002 | W5: 8 | X5: 1128 | Y5: 0 | Z5: 0.002 | AA5: 0 | AB5: 0 | AC5: 1 | AD5: 0.03 | AE5: 0 | AF5: 929 | AG5: 0 | AH5: SATISFIABLE | AI5: 0.03 | AJ5: 0 | AK5: 220 | AL5: 223 | AM5: 12 | AN5: 0.002 | AO5: 8 | AP5: 1608 | AQ5: 0 | AR5: 0.002 | AS5: 0 | AT5: 0 | AU5: 1 | AV5: 0.03 | AW5: 0 | AX5: 929 | AY5: 0 | AZ5: SATISFIABLE | BA5: 0.03 | BB5: 0 | BC5: 380 | BD5: 135 | BE5: 12 | BF5: 0.002 | BG5: 8 | BH5: 768 | BI5: 0 | BJ5: 0.002 | BK5: 0 | BL5: 0 | BM5: 1 | BN5: 0.05 | BO5: 0 | BP5: 513 | BQ5: 0 | BR5: SATISFIABLE | BS5: 0.05 | BT5: 0 | BU5: 137 | BV5: 137 | BW5: 5 | BX5: 0.002 | BY5: 0 | BZ5: 768 | CA5: 0 | CB5: 0.002 | CC5: 0 | CD5: 0 | CE5: 1 | CF5: 0.03 | CG5: 0 | CH5: 515 | CI5: 0 | CJ5: SATISFIABLE | CK5: 0.03 | CL5: 0 | CM5: 137 | CN5: 385 | CO5: 12 | CP5: 0.003 | CQ5: 8 | CR5: 1598 | CS5: 0 | CT5: 0.003 | CU5: 0 | CV5: 0 | CW5: 1 | CX5: 0.03 | CY5: 0 | CZ5: 931 | DA5: 0 | DB5: SATISFIABLE | DC5: 0.03 | DD5: 0 | DE5: 375 | DF5: 20 | DG5: 4 | DH5: 0.001 | DI5: 0 | DJ5: 18 | DK5: 0 | DL5: 0.001 | DM5: 0 | DN5: 0 | DO5: 1 | DP5: 0.03 | DQ5: 0 | DR5: 28 | DS5: 0 | DT5: SATISFIABLE | DU5: 0.03 | DV5: 0 | DW5: 10 | DX5: 137 | DY5: 12 | DZ5: 0.002 | EA5: 8 | EB5: 768 | EC5: 0 | ED5: 0.002 | EE5: 0 | EF5: 0 | EG5: 1 | EH5: 0.03 | EI5: 0 | EJ5: 515 | EK5: 0 | EL5: SATISFIABLE | EM5: 0.03 | EN5: 0 | EO5: 137 | EP5: 181 | EQ5: 5 | ER5: 0.002 | ES5: 0 | ET5: 914 | EU5: 0 | EV5: 0.002 | EW5: 0 | EX5: 0 | EY5: 1 | EZ5: 0.03 | FA5: 0 | FB5: 803 | FC5: 0 | FD5: SATISFIABLE | FE5: 0.03 | FF5: 0 | FG5: 168 | FH5: 223 | FI5: 12 | FJ5: 0.002 | FK5: 8 | FL5: 1128 | FM5: 0 | FN5: 0.002 | FO5: 0 | FP5: 0 | FQ5: 1 | FR5: 0.03 | FS5: 0 | FT5: 929 | FU5: 0 | FV5: SATISFIABLE | FW5: 0.03 | FX5: 0 | FY5: 220 | FZ5: 223 | GA5: 12 | GB5: 0.002 | GC5: 8 | GD5: 1608 | GE5: 0 | GF5: 0.002 | GG5: 0 | GH5: 0 | GI5: 1 | GJ5: 0.03 | GK5: 0 | GL5: 929 | GM5: 0 | GN5: SATISFIABLE | GO5: 0.03 | GP5: 0 | GQ5: 380 | GR5: 135 | GS5: 12 | GT5: 0.001 | GU5: 8 | GV5: 768 | GW5: 0 | GX5: 0.001 | GY5: 0 | GZ5: 0 | HA5: 1 | HB5: 0.03 | HC5: 0 | HD5: 513 | HE5: 0 | HF5: SATISFIABLE | HG5: 0.03 | HH5: 0 | HI5: 137 | HJ5: 138 | HK5: 5 | HL5: 0.028 | HM5: 0 | HN5: 768 | HO5: 0 | HP5: 0.028 | HQ5: 0 | HR5: 0 | HS5: 1 | HT5: 0.05 | HU5: 0 | HV5: 516 | HW5: 0 | HX5: SATISFIABLE | HY5: 0.05 | HZ5: 0 | IA5: 137 | IB5: 386 | IC5: 12 | ID5: 0.035 | IE5: 8 | IF5: 1598 | IG5: 0 | IH5: 0.035 | II5: 0 | IJ5: 0 | IK5: 1 | IL5: 0.06 | IM5: 0 | IN5: 932 | IO5: 0 | IP5: SATISFIABLE | IQ5: 0.06 | IR5: 0 | IS5: 375 | IT5: 21 | IU5: 3 | IV5: 0.027 | IW5: 0 | IX5: 18 | IY5: 0 | IZ5: 0.027 | JA5: 0 | JB5: 0 | JC5: 1 | JD5: 0.05 | JE5: 0 | JF5: 29 | JG5: 0 | JH5: SATISFIABLE | JI5: 0.05 | JJ5: 0 | JK5: 10 | JL5: 138 | JM5: 12 | JN5: 0.028 | JO5: 8 | JP5: 768 | JQ5: 0 | JR5: 0.028 | JS5: 0 | JT5: 0 | JU5: 1 | JV5: 0.05 | JW5: 0 | JX5: 516 | JY5: 0 | JZ5: SATISFIABLE | KA5: 0.05 | KB5: 0 | KC5: 137 | KD5: =MIN($B5,$T5,$AL5,$BD5,$BV5,$CN5,$DF5,$DX5,$EP5,$FH5,$FZ5,$GR5,$HJ5,$IB5,$IT5,$JL5) -> 0 | KE5: =MIN($C5,$U5,$AM5,$BE5,$BW5,$CO5,$DG5,$DY5,$EQ5,$FI5,$GA5,$GS5,$HK5,$IC5,$IU5,$JM5) -> 0 | KF5: =MIN($D5,$V5,$AN5,$BF5,$BX5,$CP5,$DH5,$DZ5,$ER5,$FJ5,$GB5,$GT5,$HL5,$ID5,$IV5,$JN5) -> 0 | KG5: =MIN($E5,$W5,$AO5,$BG5,$BY5,$CQ5,$DI5,$EA5,$ES5,$FK5,$GC5,$GU5,$HM5,$IE5,$IW5,$JO5) -> 0 | KH5: =MIN($F5,$X5,$AP5,$BH5,$BZ5,$CR5,$DJ5,$EB5,$ET5,$FL5,$GD5,$GV5,$HN5,$IF5,$IX5,$JP5) -> 0 | KI5: =MIN($G5,$Y5,$AQ5,$BI5,$CA5,$CS5,$DK5,$EC5,$EU5,$FM5,$GE5,$GW5,$HO5,$IG5,$IY5,$JQ5) -> 0 | KJ5: =MIN($H5,$Z5,$AR5,$BJ5,$CB5,$CT5,$DL5,$ED5,$EV5,$FN5,$GF5,$GX5,$HP5,$IH5,$IZ5,$JR5) -> 0 | KK5: =MIN($I5,$AA5,$AS5,$BK5,$CC5,$CU5,$DM5,$EE5,$EW5,$FO5,$GG5,$GY5,$HQ5,$II5,$JA5,$JS5) -> 0 | KL5: =MIN($J5,$AB5,$AT5,$BL5,$CD5,$CV5,$DN5,$EF5,$EX5,$FP5,$GH5,$GZ5,$HR5,$IJ5,$JB5,$JT5) -> 0 | KM5: =MIN($K5,$AC5,$AU5,$BM5,$CE5,$CW5,$DO5,$EG5,$EY5,$FQ5,$GI5,$HA5,$HS5,$IK5,$JC5,$JU5) -> 0 | KN5: =MIN($L5,$AD5,$AV5,$BN5,$CF5,$CX5,$DP5,$EH5,$EZ5,$FR5,$GJ5,$HB5,$HT5,$IL5,$JD5,$JV5) -> 0 | KO5: =MIN($M5,$AE5,$AW5,$BO5,$CG5,$CY5,$DQ5,$EI5,$FA5,$FS5,$GK5,$HC5,$HU5,$IM5,$JE5,$JW5) -> 0 | KP5: =MIN($N5,$AF5,$AX5,$BP5,$CH5,$CZ5,$DR5,$EJ5,$FB5,$FT5,$GL5,$HD5,$HV5,$IN5,$JF5,$JX5) -> 0 | KQ5: =MIN($O5,$AG5,$AY5,$BQ5,$CI5,$DA5,$DS5,$EK5,$FC5,$FU5,$GM5,$HE5,$HW5,$IO5,$JG5,$JY5) -> 0 | KR5: =MIN($Q5,$AI5,$BA5,$BS5,$CK5,$DC5,$DU5,$EM5,$FE5,$FW5,$GO5,$HG5,$HY5,$IQ5,$JI5,$KA5) -> 0 | KS5: =MIN($R5,$AJ5,$BB5,$BT5,$CL5,$DD5,$DV5,$EN5,$FF5,$FX5,$GP5,$HH5,$HZ5,$IR5,$JJ5,$KB5) -> 0 | KT5: =MIN($S5,$AK5,$BC5,$BU5,$CM5,$DE5,$DW5,$EO5,$FG5,$FY5,$GQ5,$HI5,$IA5,$IS5,$JK5,$KC5) -> 0 | KU5: =MEDIAN($B5,$T5,$AL5,$BD5,$BV5,$CN5,$DF5,$DX5,$EP5,$FH5,$FZ5,$GR5,$HJ5,$IB5,$IT5,$JL5) -> 0 | KV5: =MEDIAN($C5,$U5,$AM5,$BE5,$BW5,$CO5,$DG5,$DY5,$EQ5,$FI5,$GA5,$GS5,$HK5,$IC5,$IU5,$JM5) -> 0 | KW5: =MEDIAN($D5,$V5,$AN5,$BF5,$BX5,$CP5,$DH5,$DZ5,$ER5,$FJ5,$GB5,$GT5,$HL5,$ID5,$IV5,$JN5) -> 0 | KX5: =MEDIAN($E5,$W5,$AO5,$BG5,$BY5,$CQ5,$DI5,$EA5,$ES5,$FK5,$GC5,$GU5,$HM5,$IE5,$IW5,$JO5) -> 0 | KY5: =MEDIAN($F5,$X5,$AP5,$BH5,$BZ5,$CR5,$DJ5,$EB5,$ET5,$FL5,$GD5,$GV5,$HN5,$IF5,$IX5,$JP5) -> 0 | KZ5: =MEDIAN($G5,$Y5,$AQ5,$BI5,$CA5,$CS5,$DK5,$EC5,$EU5,$FM5,$GE5,$GW5,$HO5,$IG5,$IY5,$JQ5) -> 0 | LA5: =MEDIAN($H5,$Z5,$AR5,$BJ5,$CB5,$CT5,$DL5,$ED5,$EV5,$FN5,$GF5,$GX5,$HP5,$IH5,$IZ5,$JR5) -> 0 | LB5: =MEDIAN($I5,$AA5,$AS5,$BK5,$CC5,$CU5,$DM5,$EE5,$EW5,$FO5,$GG5,$GY5,$HQ5,$II5,$JA5,$JS5) -> 0 | LC5: =MEDIAN($J5,$AB5,$AT5,$BL5,$CD5,$CV5,$DN5,$EF5,$EX5,$FP5,$GH5,$GZ5,$HR5,$IJ5,$JB5,$JT5) -> 0 | LD5: =MEDIAN($K5,$AC5,$AU5,$BM5,$CE5,$CW5,$DO5,$EG5,$EY5,$FQ5,$GI5,$HA5,$HS5,$IK5,$JC5,$JU5) -> 0 | LE5: =MEDIAN($L5,$AD5,$AV5,$BN5,$CF5,$CX5,$DP5,$EH5,$EZ5,$FR5,$GJ5,$HB5,$HT5,$IL5,$JD5,$JV5) -> 0 | LF5: =MEDIAN($M5,$AE5,$AW5,$BO5,$CG5,$CY5,$DQ5,$EI5,$FA5,$FS5,$GK5,$HC5,$HU5,$IM5,$JE5,$JW5) -> 0 | LG5: =MEDIAN($N5,$AF5,$AX5,$BP5,$CH5,$CZ5,$DR5,$EJ5,$FB5,$FT5,$GL5,$HD5,$HV5,$IN5,$JF5,$JX5) -> 0 | LH5: =MEDIAN($O5,$AG5,$AY5,$BQ5,$CI5,$DA5,$DS5,$EK5,$FC5,$FU5,$GM5,$HE5,$HW5,$IO5,$JG5,$JY5) -> 0 | LI5: =MEDIAN($Q5,$AI5,$BA5,$BS5,$CK5,$DC5,$DU5,$EM5,$FE5,$FW5,$GO5,$HG5,$HY5,$IQ5,$JI5,$KA5) -> 0 | LJ5: =MEDIAN($R5,$AJ5,$BB5,$BT5,$CL5,$DD5,$DV5,$EN5,$FF5,$FX5,$GP5,$HH5,$HZ5,$IR5,$JJ5,$KB5) -> 0 | LK5: =MEDIAN($S5,$AK5,$BC5,$BU5,$CM5,$DE5,$DW5,$EO5,$FG5,$FY5,$GQ5,$HI5,$IA5,$IS5,$JK5,$KC5) -> 0 | LL5: =MAX($B5,$T5,$AL5,$BD5,$BV5,$CN5,$DF5,$DX5,$EP5,$FH5,$FZ5,$GR5,$HJ5,$IB5,$IT5,$JL5) -> 0 | LM5: =MAX($C5,$U5,$AM5,$BE5,$BW5,$CO5,$DG5,$DY5,$EQ5,$FI5,$GA5,$GS5,$HK5,$IC5,$IU5,$JM5) -> 0 | LN5: =MAX($D5,$V5,$AN5,$BF5,$BX5,$CP5,$DH5,$DZ5,$ER5,$FJ5,$GB5,$GT5,$HL5,$ID5,$IV5,$JN5) -> 0 | LO5: =MAX($E5,$W5,$AO5,$BG5,$BY5,$CQ5,$DI5,$EA5,$ES5,$FK5,$GC5,$GU5,$HM5,$IE5,$IW5,$JO5) -> 0 | LP5: =MAX($F5,$X5,$AP5,$BH5,$BZ5,$CR5,$DJ5,$EB5,$ET5,$FL5,$GD5,$GV5,$HN5,$IF5,$IX5,$JP5) -> 0 | LQ5: =MAX($G5,$Y5,$AQ5,$BI5,$CA5,$CS5,$DK5,$EC5,$EU5,$FM5,$GE5,$GW5,$HO5,$IG5,$IY5,$JQ5) -> 0 | LR5: =MAX($H5,$Z5,$AR5,$BJ5,$CB5,$CT5,$DL5,$ED5,$EV5,$FN5,$GF5,$GX5,$HP5,$IH5,$IZ5,$JR5) -> 0 | LS5: =MAX($I5,$AA5,$AS5,$BK5,$CC5,$CU5,$DM5,$EE5,$EW5,$FO5,$GG5,$GY5,$HQ5,$II5,$JA5,$JS5) -> 0 | LT5: =MAX($J5,$AB5,$AT5,$BL5,$CD5,$CV5,$DN5,$EF5,$EX5,$FP5,$GH5,$GZ5,$HR5,$IJ5,$JB5,$JT5) -> 0 | LU5: =MAX($K5,$AC5,$AU5,$BM5,$CE5,$CW5,$DO5,$EG5,$EY5,$FQ5,$GI5,$HA5,$HS5,$IK5,$JC5,$JU5) -> 0 | LV5: =MAX($L5,$AD5,$AV5,$BN5,$CF5,$CX5,$DP5,$EH5,$EZ5,$FR5,$GJ5,$HB5,$HT5,$IL5,$JD5,$JV5) -> 0 | LW5: =MAX($M5,$AE5,$AW5,$BO5,$CG5,$CY5,$DQ5,$EI5,$FA5,$FS5,$GK5,$HC5,$HU5,$IM5,$JE5,$JW5) -> 0 | LX5: =MAX($N5,$AF5,$AX5,$BP5,$CH5,$CZ5,$DR5,$EJ5,$FB5,$FT5,$GL5,$HD5,$HV5,$IN5,$JF5,$JX5) -> 0 | LY5: =MAX($O5,$AG5,$AY5,$BQ5,$CI5,$DA5,$DS5,$EK5,$FC5,$FU5,$GM5,$HE5,$HW5,$IO5,$JG5,$JY5) -> 0 | LZ5: =MAX($Q5,$AI5,$BA5,$BS5,$CK5,$DC5,$DU5,$EM5,$FE5,$FW5,$GO5,$HG5,$HY5,$IQ5,$JI5,$KA5) -> 0 | MA5: =MAX($R5,$AJ5,$BB5,$BT5,$CL5,$DD5,$DV5,$EN5,$FF5,$FX5,$GP5,$HH5,$HZ5,$IR5,$JJ5,$KB5) -> 0 | MB5: =MAX($S5,$AK5,$BC5,$BU5,$CM5,$DE5,$DW5,$EO5,$FG5,$FY5,$GQ5,$HI5,$IA5,$IS5,$JK5,$KC5) -> 0
A6: ./house-2 | G6: 0 | J6: 0 | L6: 30 | Q6: 15 | R6: 1 | AQ6: 0 | AT6: 0 | AV6: 30 | BA6: 15 | BB6: 1 | BI6: 0 | BL6: 0 | BN6: 30 | BS6: 15 | BT6: 1 | CA6: 0 | CD6: 0 | CF6: 30 | CK6: 15 | CL6: 1 | EC6: 0 | EF6: 0 | EH6: 30 | EM6: 15 | EN6: 1 | EU6: 0 | EX6: 0 | EZ6: 30 | FE6: 15 | FF6: 1 | GE6: 0 | GH6: 0 | GJ6: 30 | GO6: 15 | GP6: 1 | GW6: 0 | GZ6: 0 | HB6: 30 | HG6: 15 | HH6: 1 | HO6: 0 | HR6: 0 | HT6: 30 | HY6: 15 | HZ6: 1 | JQ6: 0 | JT6: 0 | JV6: 30 | KA6: 15 | KB6: 1 | KI6: =MIN($G6,$Y6,$AQ6,$BI6,$CA6,$CS6,$DK6,$EC6,$EU6,$FM6,$GE6,$GW6,$HO6,$IG6,$IY6,$JQ6) -> 0 | KL6: =MIN($J6,$AB6,$AT6,$BL6,$CD6,$CV6,$DN6,$EF6,$EX6,$FP6,$GH6,$GZ6,$HR6,$IJ6,$JB6,$JT6) -> 0 | KN6: =MIN($L6,$AD6,$AV6,$BN6,$CF6,$CX6,$DP6,$EH6,$EZ6,$FR6,$GJ6,$HB6,$HT6,$IL6,$JD6,$JV6) -> 0 | KR6: =MIN($Q6,$AI6,$BA6,$BS6,$CK6,$DC6,$DU6,$EM6,$FE6,$FW6,$GO6,$HG6,$HY6,$IQ6,$JI6,$KA6) -> 0 | KS6: =MIN($R6,$AJ6,$BB6,$BT6,$CL6,$DD6,$DV6,$EN6,$FF6,$FX6,$GP6,$HH6,$HZ6,$IR6,$JJ6,$KB6) -> 0 | KZ6: =MEDIAN($G6,$Y6,$AQ6,$BI6,$CA6,$CS6,$DK6,$EC6,$EU6,$FM6,$GE6,$GW6,$HO6,$IG6,$IY6,$JQ6) -> 0 | LC6: =MEDIAN($J6,$AB6,$AT6,$BL6,$CD6,$CV6,$DN6,$EF6,$EX6,$FP6,$GH6,$GZ6,$HR6,$IJ6,$JB6,$JT6) -> 0 | LE6: =MEDIAN($L6,$AD6,$AV6,$BN6,$CF6,$CX6,$DP6,$EH6,$EZ6,$FR6,$GJ6,$HB6,$HT6,$IL6,$JD6,$JV6) -> 0 | LI6: =MEDIAN($Q6,$AI6,$BA6,$BS6,$CK6,$DC6,$DU6,$EM6,$FE6,$FW6,$GO6,$HG6,$HY6,$IQ6,$JI6,$KA6) -> 0 | LJ6: =MEDIAN($R6,$AJ6,$BB6,$BT6,$CL6,$DD6,$DV6,$EN6,$FF6,$FX6,$GP6,$HH6,$HZ6,$IR6,$JJ6,$KB6) -> 0 | LQ6: =MAX($G6,$Y6,$AQ6,$BI6,$CA6,$CS6,$DK6,$EC6,$EU6,$FM6,$GE6,$GW6,$HO6,$IG6,$IY6,$JQ6) -> 0 | LT6: =MAX($J6,$AB6,$AT6,$BL6,$CD6,$CV6,$DN6,$EF6,$EX6,$FP6,$GH6,$GZ6,$HR6,$IJ6,$JB6,$JT6) -> 0 | LV6: =MAX($L6,$AD6,$AV6,$BN6,$CF6,$CX6,$DP6,$EH6,$EZ6,$FR6,$GJ6,$HB6,$HT6,$IL6,$JD6,$JV6) -> 0 | LZ6: =MAX($Q6,$AI6,$BA6,$BS6,$CK6,$DC6,$DU6,$EM6,$FE6,$FW6,$GO6,$HG6,$HY6,$IQ6,$JI6,$KA6) -> 0 | MA6: =MAX($R6,$AJ6,$BB6,$BT6,$CL6,$DD6,$DV6,$EN6,$FF6,$FX6,$GP6,$HH6,$HZ6,$IR6,$JJ6,$KB6) -> 0
A7: ./house-4 | G7: 0 | J7: 0 | L7: 30 | Q7: 15 | R7: 1 | AQ7: 0 | AT7: 0 | AV7: 30 | BA7: 15 | BB7: 1 | BI7: 0 | BL7: 0 | BN7: 30 | BS7: 15 | BT7: 1 | CA7: 0 | CD7: 0 | CF7: 30 | CK7: 15 | CL7: 1 | EC7: 0 | EF7: 0 | EH7: 30 | EM7: 15 | EN7: 1 | EU7: 0 | EX7: 0 | EZ7: 30 | FE7: 15 | FF7: 1 | GE7: 0 | GH7: 0 | GJ7: 30 | GO7: 15 | GP7: 1 | GW7: 0 | GZ7: 0 | HB7: 30 | HG7: 15 | HH7: 1 | HO7: 0 | HR7: 0 | HT7: 30 | HY7: 15 | HZ7: 1 | JQ7: 0 | JT7: 0 | JV7: 30 | KA7: 15 | KB7: 1 | KI7: =MIN($G7,$Y7,$AQ7,$BI7,$CA7,$CS7,$DK7,$EC7,$EU7,$FM7,$GE7,$GW7,$HO7,$IG7,$IY7,$JQ7) -> 0 | KL7: =MIN($J7,$AB7,$AT7,$BL7,$CD7,$CV7,$DN7,$EF7,$EX7,$FP7,$GH7,$GZ7,$HR7,$IJ7,$JB7,$JT7) -> 0 | KN7: =MIN($L7,$AD7,$AV7,$BN7,$CF7,$CX7,$DP7,$EH7,$EZ7,$FR7,$GJ7,$HB7,$HT7,$IL7,$JD7,$JV7) -> 0 | KR7: =MIN($Q7,$AI7,$BA7,$BS7,$CK7,$DC7,$DU7,$EM7,$FE7,$FW7,$GO7,$HG7,$HY7,$IQ7,$JI7,$KA7) -> 0 | KS7: =MIN($R7,$AJ7,$BB7,$BT7,$CL7,$DD7,$DV7,$EN7,$FF7,$FX7,$GP7,$HH7,$HZ7,$IR7,$JJ7,$KB7) -> 0 | KZ7: =MEDIAN($G7,$Y7,$AQ7,$BI7,$CA7,$CS7,$DK7,$EC7,$EU7,$FM7,$GE7,$GW7,$HO7,$IG7,$IY7,$JQ7) -> 0 | LC7: =MEDIAN($J7,$AB7,$AT7,$BL7,$CD7,$CV7,$DN7,$EF7,$EX7,$FP7,$GH7,$GZ7,$HR7,$IJ7,$JB7,$JT7) -> 0 | LE7: =MEDIAN($L7,$AD7,$AV7,$BN7,$CF7,$CX7,$DP7,$EH7,$EZ7,$FR7,$GJ7,$HB7,$HT7,$IL7,$JD7,$JV7) -> 0 | LI7: =MEDIAN($Q7,$AI7,$BA7,$BS7,$CK7,$DC7,$DU7,$EM7,$FE7,$FW7,$GO7,$HG7,$HY7,$IQ7,$JI7,$KA7) -> 0 | LJ7: =MEDIAN($R7,$AJ7,$BB7,$BT7,$CL7,$DD7,$DV7,$EN7,$FF7,$FX7,$GP7,$HH7,$HZ7,$IR7,$JJ7,$KB7) -> 0 | LQ7: =MAX($G7,$Y7,$AQ7,$BI7,$CA7,$CS7,$DK7,$EC7,$EU7,$FM7,$GE7,$GW7,$HO7,$IG7,$IY7,$JQ7) -> 0 | LT7: =MAX($J7,$AB7,$AT7,$BL7,$CD7,$CV7,$DN7,$EF7,$EX7,$FP7,$GH7,$GZ7,$HR7,$IJ7,$JB7,$JT7) -> 0 | LV7: =MAX($L7,$AD7,$AV7,$BN7,$CF7,$CX7,$DP7,$EH7,$EZ7,$FR7,$GJ7,$HB7,$HT7,$IL7,$JD7,$JV7) -> 0 | LZ7: =MAX($Q7,$AI7,$BA7,$BS7,$CK7,$DC7,$DU7,$EM7,$FE7,$FW7,$GO7,$HG7,$HY7,$IQ7,$JI7,$KA7) -> 0 | MA7: =MAX($R7,$AJ7,$BB7,$BT7,$CL7,$DD7,$DV7,$EN7,$FF7,$FX7,$GP7,$HH7,$HZ7,$IR7,$JJ7,$KB7) -> 0
A8: ./double-20 | G8: 0 | J8: 0 | L8: 30 | Q8: 15 | R8: 1 | AL8: 8618 | AM8: 1115 | AN8: 2.185 | AO8: 774 | AP8: 1268207 | AQ8: 0 | AR8: 0.955 | AS8: 118 | AT8: 0 | AU8: 1 | AV8: 2.25 | AW8: 6 | AX8: 343253 | AY8: 1.23 | AZ8: SATISFIABLE | BA8: 2.25 | BB8: 0 | BC8: 175566 | BD8: 4886 | BE8: 266 | BF8: 0.145 | BG8: 177 | BH8: 128657 | BI8: 0 | BJ8: 0.125 | BK8: 15 | BL8: 0 | BM8: 1 | BN8: 0.17 | BO8: 1 | BP8: 161018 | BQ8: 0.02 | BR8: SATISFIABLE | BS8: 0.17 | BT8: 0 | BU8: 5298 | CA8: 0 | CD8: 0 | CF8: 30 | CK8: 15 | CL8: 1 | EC8: 0 | EF8: 0 | EH8: 30 | EM8: 15 | EN8: 1 | EU8: 0 | EX8: 0 | EZ8: 30 | FE8: 15 | FF8: 1 | GE8: 0 | GH8: 0 | GJ8: 30 | GO8: 15 | GP8: 1 | GW8: 0 | GZ8: 0 | HB8: 30 | HG8: 15 | HH8: 1 | HO8: 0 | HR8: 0 | HT8: 30 | HY8: 15 | HZ8: 1 | JQ8: 0 | JT8: 0 | JV8: 30 | KA8: 15 | KB8: 1 | KD8: =MIN($B8,$T8,$AL8,$BD8,$BV8,$CN8,$DF8,$DX8,$EP8,$FH8,$FZ8,$GR8,$HJ8,$IB8,$IT8,$JL8) -> 0 | KE8: =MIN($C8,$U8,$AM8,$BE8,$BW8,$CO8,$DG8,$DY8,$EQ8,$FI8,$GA8,$GS8,$HK8,$IC8,$IU8,$JM8) -> 0 | KF8: =MIN($D8,$V8,$AN8,$BF8,$BX8,$CP8,$DH8,$DZ8,$ER8,$FJ8,$GB8,$GT8,$HL8,$ID8,$IV8,$JN8) -> 0 | KG8: =MIN($E8,$W8,$AO8,$BG8,$BY8,$CQ8,$DI8,$EA8,$ES8,$FK8,$GC8,$GU8,$HM8,$IE8,$IW8,$JO8) -> 0 | KH8: =MIN($F8,$X8,$AP8,$BH8,$BZ8,$CR8,$DJ8,$EB8,$ET8,$FL8,$GD8,$GV8,$HN8,$IF8,$IX8,$JP8) -> 0 | KI8: =MIN($G8,$Y8,$AQ8,$BI8,$CA8,$CS8,$DK8,$EC8,$EU8,$FM8,$GE8,$GW8,$HO8,$IG8,$IY8,$JQ8) -> 0 | KJ8: =MIN($H8,$Z8,$AR8,$BJ8,$CB8,$CT8,$DL8,$ED8,$EV8,$FN8,$GF8,$GX8,$HP8,$IH8,$IZ8,$JR8) -> 0 | KK8: =MIN($I8,$AA8,$AS8,$BK8,$CC8,$CU8,$DM8,$EE8,$EW8,$FO8,$GG8,$GY8,$HQ8,$II8,$JA8,$JS8) -> 0 | KL8: =MIN($J8,$AB8,$AT8,$BL8,$CD8,$CV8,$DN8,$EF8,$EX8,$FP8,$GH8,$GZ8,$HR8,$IJ8,$JB8,$JT8) -> 0 | KM8: =MIN($K8,$AC8,$AU8,$BM8,$CE8,$CW8,$DO8,$EG8,$EY8,$FQ8,$GI8,$HA8,$HS8,$IK8,$JC8,$JU8) -> 0 | KN8: =MIN($L8,$AD8,$AV8,$BN8,$CF8,$CX8,$DP8,$EH8,$EZ8,$FR8,$GJ8,$HB8,$HT8,$IL8,$JD8,$JV8) -> 0 | KO8: =MIN($M8,$AE8,$AW8,$BO8,$CG8,$CY8,$DQ8,$EI8,$FA8,$FS8,$GK8,$HC8,$HU8,$IM8,$JE8,$JW8) -> 0 | KP8: =MIN($N8,$AF8,$AX8,$BP8,$CH8,$CZ8,$DR8,$EJ8,$FB8,$FT8,$GL8,$HD8,$HV8,$IN8,$JF8,$JX8) -> 0 | KQ8: =MIN($O8,$AG8,$AY8,$BQ8,$CI8,$DA8,$DS8,$EK8,$FC8,$FU8,$GM8,$HE8,$HW8,$IO8,$JG8,$JY8) -> 0 | KR8: =MIN($Q8,$AI8,$BA8,$BS8,$CK8,$DC8,$DU8,$EM8,$FE8,$FW8,$GO8,$HG8,$HY8,$IQ8,$JI8,$KA8) -> 0 | KS8: =MIN($R8,$AJ8,$BB8,$BT8,$CL8,$DD8,$DV8,$EN8,$FF8,$FX8,$GP8,$HH8,$HZ8,$IR8,$JJ8,$KB8) -> 0 | KT8: =MIN($S8,$AK8,$BC8,$BU8,$CM8,$DE8,$DW8,$EO8,$FG8,$FY8,$GQ8,$HI8,$IA8,$IS8,$JK8,$KC8) -> 0 | KU8: =MEDIAN($B8,$T8,$AL8,$BD8,$BV8,$CN8,$DF8,$DX8,$EP8,$FH8,$FZ8,$GR8,$HJ8,$IB8,$IT8,$JL8) -> 0 | KV8: =MEDIAN($C8,$U8,$AM8,$BE8,$BW8,$CO8,$DG8,$DY8,$EQ8,$FI8,$GA8,$GS8,$HK8,$IC8,$IU8,$JM8) -> 0 | KW8: =MEDIAN($D8,$V8,$AN8,$BF8,$BX8,$CP8,$DH8,$DZ8,$ER8,$FJ8,$GB8,$GT8,$HL8,$ID8,$IV8,$JN8) -> 0 | KX8: =MEDIAN($E8,$W8,$AO8,$BG8,$BY8,$CQ8,$DI8,$EA8,$ES8,$FK8,$GC8,$GU8,$HM8,$IE8,$IW8,$JO8) -> 0 | KY8: =MEDIAN($F8,$X8,$AP8,$BH8,$BZ8,$CR8,$DJ8,$EB8,$ET8,$FL8,$GD8,$GV8,$HN8,$IF8,$IX8,$JP8) -> 0 | KZ8: =MEDIAN($G8,$Y8,$AQ8,$BI8,$CA8,$CS8,$DK8,$EC8,$EU8,$FM8,$GE8,$GW8,$HO8,$IG8,$IY8,$JQ8) -> 0 | LA8: =MEDIAN($H8,$Z8,$AR8,$BJ8,$CB8,$CT8,$DL8,$ED8,$EV8,$FN8,$GF8,$GX8,$HP8,$IH8,$IZ8,$JR8) -> 0 | LB8: =MEDIAN($I8,$AA8,$AS8,$BK8,$CC8,$CU8,$DM8,$EE8,$EW8,$FO8,$GG8,$GY8,$HQ8,$II8,$JA8,$JS8) -> 0 | LC8: =MEDIAN($J8,$AB8,$AT8,$BL8,$CD8,$CV8,$DN8,$EF8,$EX8,$FP8,$GH8,$GZ8,$HR8,$IJ8,$JB8,$JT8) -> 0 | LD8: =MEDIAN($K8,$AC8,$AU8,$BM8,$CE8,$CW8,$DO8,$EG8,$EY8,$FQ8,$GI8,$HA8,$HS8,$IK8,$JC8,$JU8) -> 0 | LE8: =MEDIAN($L8,$AD8,$AV8,$BN8,$CF8,$CX8,$DP8,$EH8,$EZ8,$FR8,$GJ8,$HB8,$HT8,$IL8,$JD8,$JV8) -> 0 | LF8: =MEDIAN($M8,$AE8,$AW8,$BO8,$CG8,$CY8,$DQ8,$EI8,$FA8,$FS8,$GK8,$HC8,$HU8,$IM8,$JE8,$JW8) -> 0 | LG8: =MEDIAN($N8,$AF8,$AX8,$BP8,$CH8,$CZ8,$DR8,$EJ8,$FB8,$FT8,$GL8,$HD8,$HV8,$IN8,$JF8,$JX8) -> 0 | LH8: =MEDIAN($O8,$AG8,$AY8,$BQ8,$CI8,$DA8,$DS8,$EK8,$FC8,$FU8,$GM8,$HE8,$HW8,$IO8,$JG8,$JY8) -> 0 | LI8: =MEDIAN($Q8,$AI8,$BA8,$BS8,$CK8,$DC8,$DU8,$EM8,$FE8,$FW8,$GO8,$HG8,$HY8,$IQ8,$JI8,$KA8) -> 0 | LJ8: =MEDIAN($R8,$AJ8,$BB8,$BT8,$CL8,$DD8,$DV8,$EN8,$FF8,$FX8,$GP8,$HH8,$HZ8,$IR8,$JJ8,$KB8) -> 0 | LK8: =MEDIAN($S8,$AK8,$BC8,$BU8,$CM8,$DE8,$DW8,$EO8,$FG8,$FY8,$GQ8,$HI8,$IA8,$IS8,$JK8,$KC8) -> 0 | LL8: =MAX($B8,$T8,$AL8,$BD8,$BV8,$CN8,$DF8,$DX8,$EP8,$FH8,$FZ8,$GR8,$HJ8,$IB8,$IT8,$JL8) -> 0 | LM8: =MAX($C8,$U8,$AM8,$BE8,$BW8,$CO8,$DG8,$DY8,$EQ8,$FI8,$GA8,$GS8,$HK8,$IC8,$IU8,$JM8) -> 0 | LN8: =MAX($D8,$V8,$AN8,$BF8,$BX8,$CP8,$DH8,$DZ8,$ER8,$FJ8,$GB8,$GT8,$HL8,$ID8,$IV8,$JN8) -> 0 | LO8: =MAX($E8,$W8,$AO8,$BG8,$BY8,$CQ8,$DI8,$EA8,$ES8,$FK8,$GC8,$GU8,$HM8,$IE8,$IW8,$JO8) -> 0 | LP8: =MAX($F8,$X8,$AP8,$BH8,$BZ8,$CR8,$DJ8,$EB8,$ET8,$FL8,$GD8,$GV8,$HN8,$IF8,$IX8,$JP8) -> 0 | LQ8: =MAX($G8,$Y8,$AQ8,$BI8,$CA8,$CS8,$DK8,$EC8,$EU8,$FM8,$GE8,$GW8,$HO8,$IG8,$IY8,$JQ8) -> 0 | LR8: =MAX($H8,$Z8,$AR8,$BJ8,$CB8,$CT8,$DL8,$ED8,$EV8,$FN8,$GF8,$GX8,$HP8,$IH8,$IZ8,$JR8) -> 0 | LS8: =MAX($I8,$AA8,$AS8,$BK8,$CC8,$CU8,$DM8,$EE8,$EW8,$FO8,$GG8,$GY8,$HQ8,$II8,$JA8,$JS8) -> 0 | LT8: =MAX($J8,$AB8,$AT8,$BL8,$CD8,$CV8,$DN8,$EF8,$EX8,$FP8,$GH8,$GZ8,$HR8,$IJ8,$JB8,$JT8) -> 0 | LU8: =MAX($K8,$AC8,$AU8,$BM8,$CE8,$CW8,$DO8,$EG8,$EY8,$FQ8,$GI8,$HA8,$HS8,$IK8,$JC8,$JU8) -> 0 | LV8: =MAX($L8,$AD8,$AV8,$BN8,$CF8,$CX8,$DP8,$EH8,$EZ8,$FR8,$GJ8,$HB8,$HT8,$IL8,$JD8,$JV8) -> 0 | LW8: =MAX($M8,$AE8,$AW8,$BO8,$CG8,$CY8,$DQ8,$EI8,$FA8,$FS8,$GK8,$HC8,$HU8,$IM8,$JE8,$JW8) -> 0 | LX8: =MAX($N8,$AF8,$AX8,$BP8,$CH8,$CZ8,$DR8,$EJ8,$FB8,$FT8,$GL8,$HD8,$HV8,$IN8,$JF8,$JX8) -> 0 | LY8: =MAX($O8,$AG8,$AY8,$BQ8,$CI8,$DA8,$DS8,$EK8,$FC8,$FU8,$GM8,$HE8,$HW8,$IO8,$JG8,$JY8) -> 0 | LZ8: =MAX($Q8,$AI8,$BA8,$BS8,$CK8,$DC8,$DU8,$EM8,$FE8,$FW8,$GO8,$HG8,$HY8,$IQ8,$JI8,$KA8) -> 0 | MA8: =MAX($R8,$AJ8,$BB8,$BT8,$CL8,$DD8,$DV8,$EN8,$FF8,$FX8,$GP8,$HH8,$HZ8,$IR8,$JJ8,$KB8) -> 0 | MB8: =MAX($S8,$AK8,$BC8,$BU8,$CM8,$DE8,$DW8,$EO8,$FG8,$FY8,$GQ8,$HI8,$IA8,$IS8,$JK8,$KC8) -> 0
A9: ./double-40 | G9: 0 | J9: 0 | L9: 30 | Q9: 15 | R9: 1 | AL9: 33278 | AM9: 1346 | AN9: 8.255 | AO9: 643 | AP9: 6227547 | AQ9: 0 | AR9: 6.115 | AS9: 526 | AT9: 0 | AU9: 1 | AV9: 8.47 | AW9: 5 | AX9: 2267383 | AY9: 2.14 | AZ9: SATISFIABLE | BA9: 8.47 | BB9: 0 | BC9: 778946 | BD9: 19766 | BE9: 11659 | BF9: 4.599 | BG9: 7035 | BH9: 1160787 | BI9: 0 | BJ9: 1.169 | BK9: 92 | BL9: 0 | BM9: 1 | BN9: 4.63 | BO9: 30 | BP9: 1475058 | BQ9: 3.43 | BR9: SATISFIABLE | BS9: 4.63 | BT9: 0 | BU9: 22548 | CA9: 0 | CD9: 0 | CF9: 30 | CK9: 15 | CL9: 1 | EC9: 0 | EF9: 0 | EH9: 30 | EM9: 15 | EN9: 1 | EU9: 0 | EX9: 0 | EZ9: 30 | FE9: 15 | FF9: 1 | GE9: 0 | GH9: 0 | GJ9: 30 | GO9: 15 | GP9: 1 | GW9: 0 | GZ9: 0 | HB9: 30 | HG9: 15 | HH9: 1 | HO9: 0 | HR9: 0 | HT9: 30 | HY9: 15 | HZ9: 1 | JQ9: 0 | JT9: 0 | JV9: 30 | KA9: 15 | KB9: 1 | KD9: =MIN($B9,$T9,$AL9,$BD9,$BV9,$CN9,$DF9,$DX9,$EP9,$FH9,$FZ9,$GR9,$HJ9,$IB9,$IT9,$JL9) -> 0 | KE9: =MIN($C9,$U9,$AM9,$BE9,$BW9,$CO9,$DG9,$DY9,$EQ9,$FI9,$GA9,$GS9,$HK9,$IC9,$IU9,$JM9) -> 0 | KF9: =MIN($D9,$V9,$AN9,$BF9,$BX9,$CP9,$DH9,$DZ9,$ER9,$FJ9,$GB9,$GT9,$HL9,$ID9,$IV9,$JN9) -> 0 | KG9: =MIN($E9,$W9,$AO9,$BG9,$BY9,$CQ9,$DI9,$EA9,$ES9,$FK9,$GC9,$GU9,$HM9,$IE9,$IW9,$JO9) -> 0 | KH9: =MIN($F9,$X9,$AP9,$BH9,$BZ9,$CR9,$DJ9,$EB9,$ET9,$FL9,$GD9,$GV9,$HN9,$IF9,$IX9,$JP9) -> 0 | KI9: =MIN($G9,$Y9,$AQ9,$BI9,$CA9,$CS9,$DK9,$EC9,$EU9,$FM9,$GE9,$GW9,$HO9,$IG9,$IY9,$JQ9) -> 0 | KJ9: =MIN($H9,$Z9,$AR9,$BJ9,$CB9,$CT9,$DL9,$ED9,$EV9,$FN9,$GF9,$GX9,$HP9,$IH9,$IZ9,$JR9) -> 0 | KK9: =MIN($I9,$AA9,$AS9,$BK9,$CC9,$CU9,$DM9,$EE9,$EW9,$FO9,$GG9,$GY9,$HQ9,$II9,$JA9,$JS9) -> 0 | KL9: =MIN($J9,$AB9,$AT9,$BL9,$CD9,$CV9,$DN9,$EF9,$EX9,$FP9,$GH9,$GZ9,$HR9,$IJ9,$JB9,$JT9) -> 0 | KM9: =MIN($K9,$AC9,$AU9,$BM9,$CE9,$CW9,$DO9,$EG9,$EY9,$FQ9,$GI9,$HA9,$HS9,$IK9,$JC9,$JU9) -> 0 | KN9: =MIN($L9,$AD9,$AV9,$BN9,$CF9,$CX9,$DP9,$EH9,$EZ9,$FR9,$GJ9,$HB9,$HT9,$IL9,$JD9,$JV9) -> 0 | KO9: =MIN($M9,$AE9,$AW9,$BO9,$CG9,$CY9,$DQ9,$EI9,$FA9,$FS9,$GK9,$HC9,$HU9,$IM9,$JE9,$JW9) -> 0 | KP9: =MIN($N9,$AF9,$AX9,$BP9,$CH9,$CZ9,$DR9,$EJ9,$FB9,$FT9,$GL9,$HD9,$HV9,$IN9,$JF9,$JX9) -> 0 | KQ9: =MIN($O9,$AG9,$AY9,$BQ9,$CI9,$DA9,$DS9,$EK9,$FC9,$FU9,$GM9,$HE9,$HW9,$IO9,$JG9,$JY9) -> 0 | KR9: =MIN($Q9,$AI9,$BA9,$BS9,$CK9,$DC9,$DU9,$EM9,$FE9,$FW9,$GO9,$HG9,$HY9,$IQ9,$JI9,$KA9) -> 0 | KS9: =MIN($R9,$AJ9,$BB9,$BT9,$CL9,$DD9,$DV9,$EN9,$FF9,$FX9,$GP9,$HH9,$HZ9,$IR9,$JJ9,$KB9) -> 0 | KT9: =MIN($S9,$AK9,$BC9,$BU9,$CM9,$DE9,$DW9,$EO9,$FG9,$FY9,$GQ9,$HI9,$IA9,$IS9,$JK9,$KC9) -> 0 | KU9: =MEDIAN($B9,$T9,$AL9,$BD9,$BV9,$CN9,$DF9,$DX9,$EP9,$FH9,$FZ9,$GR9,$HJ9,$IB9,$IT9,$JL9) -> 0 | KV9: =MEDIAN($C9,$U9,$AM9,$BE9,$BW9,$CO9,$DG9,$DY9,$EQ9,$FI9,$GA9,$GS9,$HK9,$IC9,$IU9,$JM9) -> 0 | KW9: =MEDIAN($D9,$V9,$AN9,$BF9,$BX9,$CP9,$DH9,$DZ9,$ER9,$FJ9,$GB9,$GT9,$HL9,$ID9,$IV9,$JN9) -> 0 | KX9: =MEDIAN($E9,$W9,$AO9,$BG9,$BY9,$CQ9,$DI9,$EA9,$ES9,$FK9,$GC9,$GU9,$HM9,$IE9,$IW9,$JO9) -> 0 | KY9: =MEDIAN($F9,$X9,$AP9,$BH9,$BZ9,$CR9,$DJ9,$EB9,$ET9,$FL9,$GD9,$GV9,$HN9,$IF9,$IX9,$JP9) -> 0 | KZ9: =MEDIAN($G9,$Y9,$AQ9,$BI9,$CA9,$CS9,$DK9,$EC9,$EU9,$FM9,$GE9,$GW9,$HO9,$IG9,$IY9,$JQ9) -> 0 | LA9: =MEDIAN($H9,$Z9,$AR9,$BJ9,$CB9,$CT9,$DL9,$ED9,$EV9,$FN9,$GF9,$GX9,$HP9,$IH9,$IZ9,$JR9) -> 0 | LB9: =MEDIAN($I9,$AA9,$AS9,$BK9,$CC9,$CU9,$DM9,$EE9,$EW9,$FO9,$GG9,$GY9,$HQ9,$II9,$JA9,$JS9) -> 0 | LC9: =MEDIAN($J9,$AB9,$AT9,$BL9,$CD9,$CV9,$DN9,$EF9,$EX9,$FP9,$GH9,$GZ9,$HR9,$IJ9,$JB9,$JT9) -> 0 | LD9: =MEDIAN($K9,$AC9,$AU9,$BM9,$CE9,$CW9,$DO9,$EG9,$EY9,$FQ9,$GI9,$HA9,$HS9,$IK9,$JC9,$JU9) -> 0 | LE9: =MEDIAN($L9,$AD9,$AV9,$BN9,$CF9,$CX9,$DP9,$EH9,$EZ9,$FR9,$GJ9,$HB9,$HT9,$IL9,$JD9,$JV9) -> 0 | LF9: =MEDIAN($M9,$AE9,$AW9,$BO9,$CG9,$CY9,$DQ9,$EI9,$FA9,$FS9,$GK9,$HC9,$HU9,$IM9,$JE9,$JW9) -> 0 | LG9: =MEDIAN($N9,$AF9,$AX9,$BP9,$CH9,$CZ9,$DR9,$EJ9,$FB9,$FT9,$GL9,$HD9,$HV9,$IN9,$JF9,$JX9) -> 0 | LH9: =MEDIAN($O9,$AG9,$AY9,$BQ9,$CI9,$DA9,$DS9,$EK9,$FC9,$FU9,$GM9,$HE9,$HW9,$IO9,$JG9,$JY9) -> 0 | LI9: =MEDIAN($Q9,$AI9,$BA9,$BS9,$CK9,$DC9,$DU9,$EM9,$FE9,$FW9,$GO9,$HG9,$HY9,$IQ9,$JI9,$KA9) -> 0 | LJ9: =MEDIAN($R9,$AJ9,$BB9,$BT9,$CL9,$DD9,$DV9,$EN9,$FF9,$FX9,$GP9,$HH9,$HZ9,$IR9,$JJ9,$KB9) -> 0 | LK9: =MEDIAN($S9,$AK9,$BC9,$BU9,$CM9,$DE9,$DW9,$EO9,$FG9,$FY9,$GQ9,$HI9,$IA9,$IS9,$JK9,$KC9) -> 0 | LL9: =MAX($B9,$T9,$AL9,$BD9,$BV9,$CN9,$DF9,$DX9,$EP9,$FH9,$FZ9,$GR9,$HJ9,$IB9,$IT9,$JL9) -> 0 | LM9: =MAX($C9,$U9,$AM9,$BE9,$BW9,$CO9,$DG9,$DY9,$EQ9,$FI9,$GA9,$GS9,$HK9,$IC9,$IU9,$JM9) -> 0 | LN9: =MAX($D9,$V9,$AN9,$BF9,$BX9,$CP9,$DH9,$DZ9,$ER9,$FJ9,$GB9,$GT9,$HL9,$ID9,$IV9,$JN9) -> 0 | LO9: =MAX($E9,$W9,$AO9,$BG9,$BY9,$CQ9,$DI9,$EA9,$ES9,$FK9,$GC9,$GU9,$HM9,$IE9,$IW9,$JO9) -> 0 | LP9: =MAX($F9,$X9,$AP9,$BH9,$BZ9,$CR9,$DJ9,$EB9,$ET9,$FL9,$GD9,$GV9,$HN9,$IF9,$IX9,$JP9) -> 0 | LQ9: =MAX($G9,$Y9,$AQ9,$BI9,$CA9,$CS9,$DK9,$EC9,$EU9,$FM9,$GE9,$GW9,$HO9,$IG9,$IY9,$JQ9) -> 0 | LR9: =MAX($H9,$Z9,$AR9,$BJ9,$CB9,$CT9,$DL9,$ED9,$EV9,$FN9,$GF9,$GX9,$HP9,$IH9,$IZ9,$JR9) -> 0 | LS9: =MAX($I9,$AA9,$AS9,$BK9,$CC9,$CU9,$DM9,$EE9,$EW9,$FO9,$GG9,$GY9,$HQ9,$II9,$JA9,$JS9) -> 0 | LT9: =MAX($J9,$AB9,$AT9,$BL9,$CD9,$CV9,$DN9,$EF9,$EX9,$FP9,$GH9,$GZ9,$HR9,$IJ9,$JB9,$JT9) -> 0 | LU9: =MAX($K9,$AC9,$AU9,$BM9,$CE9,$CW9,$DO9,$EG9,$EY9,$FQ9,$GI9,$HA9,$HS9,$IK9,$JC9,$JU9) -> 0 | LV9: =MAX($L9,$AD9,$AV9,$BN9,$CF9,$CX9,$DP9,$EH9,$EZ9,$FR9,$GJ9,$HB9,$HT9,$IL9,$JD9,$JV9) -> 0 | LW9: =MAX($M9,$AE9,$AW9,$BO9,$CG9,$CY9,$DQ9,$EI9,$FA9,$FS9,$GK9,$HC9,$HU9,$IM9,$JE9,$JW9) -> 0 | LX9: =MAX($N9,$AF9,$AX9,$BP9,$CH9,$CZ9,$DR9,$EJ9,$FB9,$FT9,$GL9,$HD9,$HV9,$IN9,$JF9,$JX9) -> 0 | LY9: =MAX($O9,$AG9,$AY9,$BQ9,$CI9,$DA9,$DS9,$EK9,$FC9,$FU9,$GM9,$HE9,$HW9,$IO9,$JG9,$JY9) -> 0 | LZ9: =MAX($Q9,$AI9,$BA9,$BS9,$CK9,$DC9,$DU9,$EM9,$FE9,$FW9,$GO9,$HG9,$HY9,$IQ9,$JI9,$KA9) -> 0 | MA9: =MAX($R9,$AJ9,$BB9,$BT9,$CL9,$DD9,$DV9,$EN9,$FF9,$FX9,$GP9,$HH9,$HZ9,$IR9,$JJ9,$KB9) -> 0 | MB9: =MAX($S9,$AK9,$BC9,$BU9,$CM9,$DE9,$DW9,$EO9,$FG9,$FY9,$GQ9,$HI9,$IA9,$IS9,$JK9,$KC9) -> 0
A11: SUM | B11: =SUM(B$3:B$9) -> 0 | C11: =SUM(C$3:C$9) -> 0 | D11: =SUM(D$3:D$9) -> 0 | E11: =SUM(E$3:E$9) -> 0 | F11: =SUM(F$3:F$9) -> 0 | G11: =SUM(G$3:G$9) -> 0 | H11: =SUM(H$3:H$9) -> 0 | I11: =SUM(I$3:I$9) -> 0 | ... O11: =SUM(O$3:O$9) -> 0 | Q11: =SUM(Q$3:Q$9) -> 0 | R11: =SUM(R$3:R$9) -> 0 | S11: =SUM(S$3:S$9) -> 0 | T11: =SUM(T$3:T$9) -> 0 | U11: =SUM(U$3:U$9) -> 0 | V11: =SUM(V$3:V$9) -> 0 | W11: =SUM(W$3:W$9) -> 0 | X11: =SUM(X$3:X$9) -> 0 | ... AG11: =SUM(AG$3:AG$9) -> 0 | AI11: =SUM(AI$3:AI$9) -> 0 | AJ11: =SUM(AJ$3:AJ$9) -> 0 | AK11: =SUM(AK$3:AK$9) -> 0 | AL11: =SUM(AL$3:AL$9) -> 0 | AM11: =SUM(AM$3:AM$9) -> 0 | AN11: =SUM(AN$3:AN$9) -> 0 | AO11: =SUM(AO$3:AO$9) -> 0 | AP11: =SUM(AP$3:AP$9) -> 0 | ... AY11: =SUM(AY$3:AY$9) -> 0 | BA11: =SUM(BA$3:BA$9) -> 0 | BB11: =SUM(BB$3:BB$9) -> 0 | BC11: =SUM(BC$3:BC$9) -> 0 | BD11: =SUM(BD$3:BD$9) -> 0 | BE11: =SUM(BE$3:BE$9) -> 0 | BF11: =SUM(BF$3:BF$9) -> 0 | BG11: =SUM(BG$3:BG$9) -> 0 | BH11: =SUM(BH$3:BH$9) -> 0 | ... BQ11: =SUM(BQ$3:BQ$9) -> 0 | BS11: =SUM(BS$3:BS$9) -> 0 | BT11: =SUM(BT$3:BT$9) -> 0 | BU11: =SUM(BU$3:BU$9) -> 0 | BV11: =SUM(BV$3:BV$9) -> 0 | BW11: =SUM(BW$3:BW$9) -> 0 | BX11: =SUM(BX$3:BX$9) -> 0 | BY11: =SUM(BY$3:BY$9) -> 0 | BZ11: =SUM(BZ$3:BZ$9) -> 0 | ... CI11: =SUM(CI$3:CI$9) -> 0 | CK11: =SUM(CK$3:CK$9) -> 0 | CL11: =SUM(CL$3:CL$9) -> 0 | CM11: =SUM(CM$3:CM$9) -> 0 | CN11: =SUM(CN$3:CN$9) -> 0 | CO11: =SUM(CO$3:CO$9) -> 0 | CP11: =SUM(CP$3:CP$9) -> 0 | CQ11: =SUM(CQ$3:CQ$9) -> 0 | CR11: =SUM(CR$3:CR$9) -> 0 | ... DA11: =SUM(DA$3:DA$9) -> 0 | DC11: =SUM(DC$3:DC$9) -> 0 | DD11: =SUM(DD$3:DD$9) -> 0 | DE11: =SUM(DE$3:DE$9) -> 0 | DF11: =SUM(DF$3:DF$9) -> 0 | DG11: =SUM(DG$3:DG$9) -> 0 | DH11: =SUM(DH$3:DH$9) -> 0 | DI11: =SUM(DI$3:DI$9) -> 0 | DJ11: =SUM(DJ$3:DJ$9) -> 0 | ... DS11: =SUM(DS$3:DS$9) -> 0 | DU11: =SUM(DU$3:DU$9) -> 0 | DV11: =SUM(DV$3:DV$9) -> 0 | DW11: =SUM(DW$3:DW$9) -> 0 | DX11: =SUM(DX$3:DX$9) -> 0 | DY11: =SUM(DY$3:DY$9) -> 0 | DZ11: =SUM(DZ$3:DZ$9) -> 0 | EA11: =SUM(EA$3:EA$9) -> 0 | EB11: =SUM(EB$3:EB$9) -> 0 | ... EK11: =SUM(EK$3:EK$9) -> 0 | EM11: =SUM(EM$3:EM$9) -> 0 | EN11: =SUM(EN$3:EN$9) -> 0 | EO11: =SUM(EO$3:EO$9) -> 0 | EP11: =SUM(EP$3:EP$9) -> 0 | EQ11: =SUM(EQ$3:EQ$9) -> 0 | ER11: =SUM(ER$3:ER$9) -> 0 | ES11: =SUM(ES$3:ES$9) -> 0 | ET11: =SUM(ET$3:ET$9) -> 0 | ... FC11: =SUM(FC$3:FC$9) -> 0 | FE11: =SUM(FE$3:FE$9) -> 0 | FF11: =SUM(FF$3:FF$9) -> 0 | FG11: =SUM(FG$3:FG$9) -> 0 | FH11: =SUM(FH$3:FH$9) -> 0 | FI11: =SUM(FI$3:FI$9) -> 0 | FJ11: =SUM(FJ$3:FJ$9) -> 0 | FK11: =SUM(FK$3:FK$9) -> 0 | FL11: =SUM(FL$3:FL$9) -> 0 | ... FU11: =SUM(FU$3:FU$9) -> 0 | FW11: =SUM(FW$3:FW$9) -> 0 | FX11: =SUM(FX$3:FX$9) -> 0 | FY11: =SUM(FY$3:FY$9) -> 0 | FZ11: =SUM(FZ$3:FZ$9) -> 0 | GA11: =SUM(GA$3:GA$9) -> 0 | GB11: =SUM(GB$3:GB$9) -> 0 | GC11: =SUM(GC$3:GC$9) -> 0 | GD11: =SUM(GD$3:GD$9) -> 0 | ... GM11: =SUM(GM$3:GM$9) -> 0 | GO11: =SUM(GO$3:GO$9) -> 0 | GP11: =SUM(GP$3:GP$9) -> 0 | GQ11: =SUM(GQ$3:GQ$9) -> 0 | GR11: =SUM(GR$3:GR$9) -> 0 | GS11: =SUM(GS$3:GS$9) -> 0 | GT11: =SUM(GT$3:GT$9) -> 0 | GU11: =SUM(GU$3:GU$9) -> 0 | GV11: =SUM(GV$3:GV$9) -> 0 | ... HE11: =SUM(HE$3:HE$9) -> 0 | HG11: =SUM(HG$3:HG$9) -> 0 | HH11: =SUM(HH$3:HH$9) -> 0 | HI11: =SUM(HI$3:HI$9) -> 0 | HJ11: =SUM(HJ$3:HJ$9) -> 0 | HK11: =SUM(HK$3:HK$9) -> 0 | HL11: =SUM(HL$3:HL$9) -> 0 | HM11: =SUM(HM$3:HM$9) -> 0 | HN11: =SUM(HN$3:HN$9) -> 0 | ... HW11: =SUM(HW$3:HW$9) -> 0 | HY11: =SUM(HY$3:HY$9) -> 0 | HZ11: =SUM(HZ$3:HZ$9) -> 0 | IA11: =SUM(IA$3:IA$9) -> 0 | IB11: =SUM(IB$3:IB$9) -> 0 | IC11: =SUM(IC$3:IC$9) -> 0 | ID11: =SUM(ID$3:ID$9) -> 0 | IE11: =SUM(IE$3:IE$9) -> 0 | IF11: =SUM(IF$3:IF$9) -> 0 | ... IO11: =SUM(IO$3:IO$9) -> 0 | IQ11: =SUM(IQ$3:IQ$9) -> 0 | IR11: =SUM(IR$3:IR$9) -> 0 | IS11: =SUM(IS$3:IS$9) -> 0 | IT11: =SUM(IT$3:IT$9) -> 0 | IU11: =SUM(IU$3:IU$9) -> 0 | IV11: =SUM(IV$3:IV$9) -> 0 | IW11: =SUM(IW$3:IW$9) -> 0 | IX11: =SUM(IX$3:IX$9) -> 0 | ... JG11: =SUM(JG$3:JG$9) -> 0 | JI11: =SUM(JI$3:JI$9) -> 0 | JJ11: =SUM(JJ$3:JJ$9) -> 0 | JK11: =SUM(JK$3:JK$9) -> 0 | JL11: =SUM(JL$3:JL$9) -> 0 | JM11: =SUM(JM$3:JM$9) -> 0 | JN11: =SUM(JN$3:JN$9) -> 0 | JO11: =SUM(JO$3:JO$9) -> 0 | JP11: =SUM(JP$3:JP$9) -> 0 | ... JY11: =SUM(JY$3:JY$9) -> 0 | KA11: =SUM(KA$3:KA$9) -> 0 | KB11: =SUM(KB$3:KB$9) -> 0 | KC11: =SUM(KC$3:KC$9) -> 0 | KD11: =SUM(KD$3:KD$9) -> 0 | KE11: =SUM(KE$3:KE$9) -> 0 | KF11: =SUM(KF$3:KF$9) -> 0 | KG11: =SUM(KG$3:KG$9) -> 0 | KH11: =SUM(KH$3:KH$9) -> 0 | ... MB11: =SUM(MB$3:MB$9) -> 0
A12: AVG | B12: =AVERAGE(B$3:B$9) -> 0 | C12: =AVERAGE(C$3:C$9) -> 0 | D12: =AVERAGE(D$3:D$9) -> 0 | E12: =AVERAGE(E$3:E$9) -> 0 | F12: =AVERAGE(F$3:F$9) -> 0 | G12: =AVERAGE(G$3:G$9) -> 0 | H12: =AVERAGE(H$3:H$9) -> 0 | I12: =AVERAGE(I$3:I$9) -> 0 | ... O12: =AVERAGE(O$3:O$9) -> 0 | Q12: =AVERAGE(Q$3:Q$9) -> 0 | R12: =AVERAGE(R$3:R$9) -> 0 | S12: =AVERAGE(S$3:S$9) -> 0 | T12: =AVERAGE(T$3:T$9) -> 0 | U12: =AVERAGE(U$3:U$9) -> 0 | V12: =AVERAGE(V$3:V$9) -> 0 | W12: =AVERAGE(W$3:W$9) -> 0 | X12: =AVERAGE(X$3:X$9) -> 0 | ... AG12: =AVERAGE(AG$3:AG$9) -> 0 | AI12: =AVERAGE(AI$3:AI$9) -> 0 | AJ12: =AVERAGE(AJ$3:AJ$9) -> 0 | AK12: =AVERAGE(AK$3:AK$9) -> 0 | AL12: =AVERAGE(AL$3:AL$9) -> 0 | AM12: =AVERAGE(AM$3:AM$9) -> 0 | AN12: =AVERAGE(AN$3:AN$9) -> 0 | AO12: =AVERAGE(AO$3:AO$9) -> 0 | AP12: =AVERAGE(AP$3:AP$9) -> 0 | ... AY12: =AVERAGE(AY$3:AY$9) -> 0 | BA12: =AVERAGE(BA$3:BA$9) -> 0 | BB12: =AVERAGE(BB$3:BB$9) -> 0 | BC12: =AVERAGE(BC$3:BC$9) -> 0 | BD12: =AVERAGE(BD$3:BD$9) -> 0 | BE12: =AVERAGE(BE$3:BE$9) -> 0 | BF12: =AVERAGE(BF$3:BF$9) -> 0 | BG12: =AVERAGE(BG$3:BG$9) -> 0 | BH12: =AVERAGE(BH$3:BH$9) -> 0 | ... BQ12: =AVERAGE(BQ$3:BQ$9) -> 0 | BS12: =AVERAGE(BS$3:BS$9) -> 0 | BT12: =AVERAGE(BT$3:BT$9) -> 0 | BU12: =AVERAGE(BU$3:BU$9) -> 0 | BV12: =AVERAGE(BV$3:BV$9) -> 0 | BW12: =AVERAGE(BW$3:BW$9) -> 0 | BX12: =AVERAGE(BX$3:BX$9) -> 0 | BY12: =AVERAGE(BY$3:BY$9) -> 0 | BZ12: =AVERAGE(BZ$3:BZ$9) -> 0 | ... CI12: =AVERAGE(CI$3:CI$9) -> 0 | CK12: =AVERAGE(CK$3:CK$9) -> 0 | CL12: =AVERAGE(CL$3:CL$9) -> 0 | CM12: =AVERAGE(CM$3:CM$9) -> 0 | CN12: =AVERAGE(CN$3:CN$9) -> 0 | CO12: =AVERAGE(CO$3:CO$9) -> 0 | CP12: =AVERAGE(CP$3:CP$9) -> 0 | CQ12: =AVERAGE(CQ$3:CQ$9) -> 0 | CR12: =AVERAGE(CR$3:CR$9) -> 0 | ... DA12: =AVERAGE(DA$3:DA$9) -> 0 | DC12: =AVERAGE(DC$3:DC$9) -> 0 | DD12: =AVERAGE(DD$3:DD$9) -> 0 | DE12: =AVERAGE(DE$3:DE$9) -> 0 | DF12: =AVERAGE(DF$3:DF$9) -> 0 | DG12: =AVERAGE(DG$3:DG$9) -> 0 | DH12: =AVERAGE(DH$3:DH$9) -> 0 | DI12: =AVERAGE(DI$3:DI$9) -> 0 | DJ12: =AVERAGE(DJ$3:DJ$9) -> 0 | ... DS12: =AVERAGE(DS$3:DS$9) -> 0 | DU12: =AVERAGE(DU$3:DU$9) -> 0 | DV12: =AVERAGE(DV$3:DV$9) -> 0 | DW12: =AVERAGE(DW$3:DW$9) -> 0 | DX12: =AVERAGE(DX$3:DX$9) -> 0 | DY12: =AVERAGE(DY$3:DY$9) -> 0 | DZ12: =AVERAGE(DZ$3:DZ$9) -> 0 | EA12: =AVERAGE(EA$3:EA$9) -> 0 | EB12: =AVERAGE(EB$3:EB$9) -> 0 | ... EK12: =AVERAGE(EK$3:EK$9) -> 0 | EM12: =AVERAGE(EM$3:EM$9) -> 0 | EN12: =AVERAGE(EN$3:EN$9) -> 0 | EO12: =AVERAGE(EO$3:EO$9) -> 0 | EP12: =AVERAGE(EP$3:EP$9) -> 0 | EQ12: =AVERAGE(EQ$3:EQ$9) -> 0 | ER12: =AVERAGE(ER$3:ER$9) -> 0 | ES12: =AVERAGE(ES$3:ES$9) -> 0 | ET12: =AVERAGE(ET$3:ET$9) -> 0 | ... FC12: =AVERAGE(FC$3:FC$9) -> 0 | FE12: =AVERAGE(FE$3:FE$9) -> 0 | FF12: =AVERAGE(FF$3:FF$9) -> 0 | FG12: =AVERAGE(FG$3:FG$9) -> 0 | FH12: =AVERAGE(FH$3:FH$9) -> 0 | FI12: =AVERAGE(FI$3:FI$9) -> 0 | FJ12: =AVERAGE(FJ$3:FJ$9) -> 0 | FK12: =AVERAGE(FK$3:FK$9) -> 0 | FL12: =AVERAGE(FL$3:FL$9) -> 0 | ... FU12: =AVERAGE(FU$3:FU$9) -> 0 | FW12: =AVERAGE(FW$3:FW$9) -> 0 | FX12: =AVERAGE(FX$3:FX$9) -> 0 | FY12: =AVERAGE(FY$3:FY$9) -> 0 | FZ12: =AVERAGE(FZ$3:FZ$9) -> 0 | GA12: =AVERAGE(GA$3:GA$9) -> 0 | GB12: =AVERAGE(GB$3:GB$9) -> 0 | GC12: =AVERAGE(GC$3:GC$9) -> 0 | GD12: =AVERAGE(GD$3:GD$9) -> 0 | ... GM12: =AVERAGE(GM$3:GM$9) -> 0 | GO12: =AVERAGE(GO$3:GO$9) -> 0 | GP12: =AVERAGE(GP$3:GP$9) -> 0 | GQ12: =AVERAGE(GQ$3:GQ$9) -> 0 | GR12: =AVERAGE(GR$3:GR$9) -> 0 | GS12: =AVERAGE(GS$3:GS$9) -> 0 | GT12: =AVERAGE(GT$3:GT$9) -> 0 | GU12: =AVERAGE(GU$3:GU$9) -> 0 | GV12: =AVERAGE(GV$3:GV$9) -> 0 | ... HE12: =AVERAGE(HE$3:HE$9) -> 0 | HG12: =AVERAGE(HG$3:HG$9) -> 0 | HH12: =AVERAGE(HH$3:HH$9) -> 0 | HI12: =AVERAGE(HI$3:HI$9) -> 0 | HJ12: =AVERAGE(HJ$3:HJ$9) -> 0 | HK12: =AVERAGE(HK$3:HK$9) -> 0 | HL12: =AVERAGE(HL$3:HL$9) -> 0 | HM12: =AVERAGE(HM$3:HM$9) -> 0 | HN12: =AVERAGE(HN$3:HN$9) -> 0 | ... HW12: =AVERAGE(HW$3:HW$9) -> 0 | HY12: =AVERAGE(HY$3:HY$9) -> 0 | HZ12: =AVERAGE(HZ$3:HZ$9) -> 0 | IA12: =AVERAGE(IA$3:IA$9) -> 0 | IB12: =AVERAGE(IB$3:IB$9) -> 0 | IC12: =AVERAGE(IC$3:IC$9) -> 0 | ID12: =AVERAGE(ID$3:ID$9) -> 0 | IE12: =AVERAGE(IE$3:IE$9) -> 0 | IF12: =AVERAGE(IF$3:IF$9) -> 0 | ... IO12: =AVERAGE(IO$3:IO$9) -> 0 | IQ12: =AVERAGE(IQ$3:IQ$9) -> 0 | IR12: =AVERAGE(IR$3:IR$9) -> 0 | IS12: =AVERAGE(IS$3:IS$9) -> 0 | IT12: =AVERAGE(IT$3:IT$9) -> 0 | IU12: =AVERAGE(IU$3:IU$9) -> 0 | IV12: =AVERAGE(IV$3:IV$9) -> 0 | IW12: =AVERAGE(IW$3:IW$9) -> 0 | IX12: =AVERAGE(IX$3:IX$9) -> 0 | ... JG12: =AVERAGE(JG$3:JG$9) -> 0 | JI12: =AVERAGE(JI$3:JI$9) -> 0 | JJ12: =AVERAGE(JJ$3:JJ$9) -> 0 | JK12: =AVERAGE(JK$3:JK$9) -> 0 | JL12: =AVERAGE(JL$3:JL$9) -> 0 | JM12: =AVERAGE(JM$3:JM$9) -> 0 | JN12: =AVERAGE(JN$3:JN$9) -> 0 | JO12: =AVERAGE(JO$3:JO$9) -> 0 | JP12: =AVERAGE(JP$3:JP$9) -> 0 | ... JY12: =AVERAGE(JY$3:JY$9) -> 0 | KA12: =AVERAGE(KA$3:KA$9) -> 0 | KB12: =AVERAGE(KB$3:KB$9) -> 0 | KC12: =AVERAGE(KC$3:KC$9) -> 0 | KD12: =AVERAGE(KD$3:KD$9) -> 0 | KE12: =AVERAGE(KE$3:KE$9) -> 0 | KF12: =AVERAGE(KF$3:KF$9) -> 0 | KG12: =AVERAGE(KG$3:KG$9) -> 0 | KH12: =AVERAGE(KH$3:KH$9) -> 0 | ... MB12: =AVERAGE(MB$3:MB$9) -> 0
A13: DEV | B13: =STDEV(B$3:B$9) -> 0 | C13: =STDEV(C$3:C$9) -> 0 | D13: =STDEV(D$3:D$9) -> 0 | E13: =STDEV(E$3:E$9) -> 0 | F13: =STDEV(F$3:F$9) -> 0 | G13: =STDEV(G$3:G$9) -> 0 | H13: =STDEV(H$3:H$9) -> 0 | I13: =STDEV(I$3:I$9) -> 0 | ... O13: =STDEV(O$3:O$9) -> 0 | Q13: =STDEV(Q$3:Q$9) -> 0 | R13: =STDEV(R$3:R$9) -> 0 | S13: =STDEV(S$3:S$9) -> 0 | T13: =STDEV(T$3:T$9) -> 0 | U13: =STDEV(U$3:U$9) -> 0 | V13: =STDEV(V$3:V$9) -> 0 | W13: =STDEV(W$3:W$9) -> 0 | X13: =STDEV(X$3:X$9) -> 0 | ... AG13: =STDEV(AG$3:AG$9) -> 0 | AI13: =STDEV(AI$3:AI$9) -> 0 | AJ13: =STDEV(AJ$3:AJ$9) -> 0 | AK13: =STDEV(AK$3:AK$9) -> 0 | AL13: =STDEV(AL$3:AL$9) -> 0 | AM13: =STDEV(AM$3:AM$9) -> 0 | AN13: =STDEV(AN$3:AN$9) -> 0 | AO13: =STDEV(AO$3:AO$9) -> 0 | AP13: =STDEV(AP$3:AP$9) -> 0 | ... AY13: =STDEV(AY$3:AY$9) -> 0 | BA13: =STDEV(BA$3:BA$9) -> 0 | BB13: =STDEV(BB$3:BB$9) -> 0 | BC13: =STDEV(BC$3:BC$9) -> 0 | BD13: =STDEV(BD$3:BD$9) -> 0 | BE13: =STDEV(BE$3:BE$9) -> 0 | BF13: =STDEV(BF$3:BF$9) -> 0 | BG13: =STDEV(BG$3:BG$9) -> 0 | BH13: =STDEV(BH$3:BH$9) -> 0 | ... BQ13: =STDEV(BQ$3:BQ$9) -> 0 | BS13: =STDEV(BS$3:BS$9) -> 0 | BT13: =STDEV(BT$3:BT$9) -> 0 | BU13: =STDEV(BU$3:BU$9) -> 0 | BV13: =STDEV(BV$3:BV$9) -> 0 | BW13: =STDEV(BW$3:BW$9) -> 0 | BX13: =STDEV(BX$3:BX$9) -> 0 | BY13: =STDEV(BY$3:BY$9) -> 0 | BZ13: =STDEV(BZ$3:BZ$9) -> 0 | ... CI13: =STDEV(CI$3:CI$9) -> 0 | CK13: =STDEV(CK$3:CK$9) -> 0 | CL13: =STDEV(CL$3:CL$9) -> 0 | CM13: =STDEV(CM$3:CM$9) -> 0 | CN13: =STDEV(CN$3:CN$9) -> 0 | CO13: =STDEV(CO$3:CO$9) -> 0 | CP13: =STDEV(CP$3:CP$9) -> 0 | CQ13: =STDEV(CQ$3:CQ$9) -> 0 | CR13: =STDEV(CR$3:CR$9) -> 0 | ... DA13: =STDEV(DA$3:DA$9) -> 0 | DC13: =STDEV(DC$3:DC$9) -> 0 | DD13: =STDEV(DD$3:DD$9) -> 0 | DE13: =STDEV(DE$3:DE$9) -> 0 | DF13: =STDEV(DF$3:DF$9) -> 0 | DG13: =STDEV(DG$3:DG$9) -> 0 | DH13: =STDEV(DH$3:DH$9) -> 0 | DI13: =STDEV(DI$3:DI$9) -> 0 | DJ13: =STDEV(DJ$3:DJ$9) -> 0 | ... DS13: =STDEV(DS$3:DS$9) -> 0 | DU13: =STDEV(DU$3:DU$9) -> 0 | DV13: =STDEV(DV$3:DV$9) -> 0 | DW13: =STDEV(DW$3:DW$9) -> 0 | DX13: =STDEV(DX$3:DX$9) -> 0 | DY13: =STDEV(DY$3:DY$9) -> 0 | DZ13: =STDEV(DZ$3:DZ$9) -> 0 | EA13: =STDEV(EA$3:EA$9) -> 0 | EB13: =STDEV(EB$3:EB$9) -> 0 | ... EK13: =STDEV(EK$3:EK$9) -> 0 | EM13: =STDEV(EM$3:EM$9) -> 0 | EN13: =STDEV(EN$3:EN$9) -> 0 | EO13: =STDEV(EO$3:EO$9) -> 0 | EP13: =STDEV(EP$3:EP$9) -> 0 | EQ13: =STDEV(EQ$3:EQ$9) -> 0 | ER13: =STDEV(ER$3:ER$9) -> 0 | ES13: =STDEV(ES$3:ES$9) -> 0 | ET13: =STDEV(ET$3:ET$9) -> 0 | ... FC13: =STDEV(FC$3:FC$9) -> 0 | FE13: =STDEV(FE$3:FE$9) -> 0 | FF13: =STDEV(FF$3:FF$9) -> 0 | FG13: =STDEV(FG$3:FG$9) -> 0 | FH13: =STDEV(FH$3:FH$9) -> 0 | FI13: =STDEV(FI$3:FI$9) -> 0 | FJ13: =STDEV(FJ$3:FJ$9) -> 0 | FK13: =STDEV(FK$3:FK$9) -> 0 | FL13: =STDEV(FL$3:FL$9) -> 0 | ... FU13: =STDEV(FU$3:FU$9) -> 0 | FW13: =STDEV(FW$3:FW$9) -> 0 | FX13: =STDEV(FX$3:FX$9) -> 0 | FY13: =STDEV(FY$3:FY$9) -> 0 | FZ13: =STDEV(FZ$3:FZ$9) -> 0 | GA13: =STDEV(GA$3:GA$9) -> 0 | GB13: =STDEV(GB$3:GB$9) -> 0 | GC13: =STDEV(GC$3:GC$9) -> 0 | GD13: =STDEV(GD$3:GD$9) -> 0 | ... GM13: =STDEV(GM$3:GM$9) -> 0 | GO13: =STDEV(GO$3:GO$9) -> 0 | GP13: =STDEV(GP$3:GP$9) -> 0 | GQ13: =STDEV(GQ$3:GQ$9) -> 0 | GR13: =STDEV(GR$3:GR$9) -> 0 | GS13: =STDEV(GS$3:GS$9) -> 0 | GT13: =STDEV(GT$3:GT$9) -> 0 | GU13: =STDEV(GU$3:GU$9) -> 0 | GV13: =STDEV(GV$3:GV$9) -> 0 | ... HE13: =STDEV(HE$3:HE$9) -> 0 | HG13: =STDEV(HG$3:HG$9) -> 0 | HH13: =STDEV(HH$3:HH$9) -> 0 | HI13: =STDEV(HI$3:HI$9) -> 0 | HJ13: =STDEV(HJ$3:HJ$9) -> 0 | HK13: =STDEV(HK$3:HK$9) -> 0 | HL13: =STDEV(HL$3:HL$9) -> 0 | HM13: =STDEV(HM$3:HM$9) -> 0 | HN13: =STDEV(HN$3:HN$9) -> 0 | ... HW13: =STDEV(HW$3:HW$9) -> 0 | HY13: =STDEV(HY$3:HY$9) -> 0 | HZ13: =STDEV(HZ$3:HZ$9) -> 0 | IA13: =STDEV(IA$3:IA$9) -> 0 | IB13: =STDEV(IB$3:IB$9) -> 0 | IC13: =STDEV(IC$3:IC$9) -> 0 | ID13: =STDEV(ID$3:ID$9) -> 0 | IE13: =STDEV(IE$3:IE$9) -> 0 | IF13: =STDEV(IF$3:IF$9) -> 0 | ... IO13: =STDEV(IO$3:IO$9) -> 0 | IQ13: =STDEV(IQ$3:IQ$9) -> 0 | IR13: =STDEV(IR$3:IR$9) -> 0 | IS13: =STDEV(IS$3:IS$9) -> 0 | IT13: =STDEV(IT$3:IT$9) -> 0 | IU13: =STDEV(IU$3:IU$9) -> 0 | IV13: =STDEV(IV$3:IV$9) -> 0 | IW13: =STDEV(IW$3:IW$9) -> 0 | IX13: =STDEV(IX$3:IX$9) -> 0 | ... JG13: =STDEV(JG$3:JG$9) -> 0 | JI13: =STDEV(JI$3:JI$9) -> 0 | JJ13: =STDEV(JJ$3:JJ$9) -> 0 | JK13: =STDEV(JK$3:JK$9) -> 0 | JL13: =STDEV(JL$3:JL$9) -> 0 | JM13: =STDEV(JM$3:JM$9) -> 0 | JN13: =STDEV(JN$3:JN$9) -> 0 | JO13: =STDEV(JO$3:JO$9) -> 0 | JP13: =STDEV(JP$3:JP$9) -> 0 | ... JY13: =STDEV(JY$3:JY$9) -> 0 | KA13: =STDEV(KA$3:KA$9) -> 0 | KB13: =STDEV(KB$3:KB$9) -> 0 | KC13: =STDEV(KC$3:KC$9) -> 0 | KD13: =STDEV(KD$3:KD$9) -> 0 | KE13: =STDEV(KE$3:KE$9) -> 0 | KF13: =STDEV(KF$3:KF$9) -> 0 | KG13: =STDEV(KG$3:KG$9) -> 0 | KH13: =STDEV(KH$3:KH$9) -> 0 | ... MB13: =STDEV(MB$3:MB$9) -> 0
